https://www.behance.net/videos/b795c0b0-9820-4806-8365-c86630d45070/Creating-a-black-and-white-duo-portrait-commission-with-Suzanne-Helmigh.mp4
Traceback (most recent call last):
  File "/home/saransh03sharma/.local/lib/python3.10/site-packages/moviepy/video/io/ffmpeg_reader.py", line 285, in ffmpeg_parse_infos
    line = [l for l in lines if keyword in l][index]
IndexError: list index out of range

During handling of the above exception, another exception occurred:

Traceback (most recent call last):
  File "/home/saransh03sharma/Documents/GitHub/VideoIntentDiscovery/scripts/download_videos.py", line 54, in get_slices
    video = VideoFileClip(tmp_name)
  File "/home/saransh03sharma/.local/lib/python3.10/site-packages/moviepy/video/io/VideoFileClip.py", line 88, in __init__
    self.reader = FFMPEG_VideoReader(filename, pix_fmt=pix_fmt,
  File "/home/saransh03sharma/.local/lib/python3.10/site-packages/moviepy/video/io/ffmpeg_reader.py", line 35, in __init__
    infos = ffmpeg_parse_infos(filename, print_infos, check_duration,
  File "/home/saransh03sharma/.local/lib/python3.10/site-packages/moviepy/video/io/ffmpeg_reader.py", line 289, in ffmpeg_parse_infos
    raise IOError(("MoviePy error: failed to read the duration of file %s.\n"
OSError: MoviePy error: failed to read the duration of file ../data/bid/video/https:____www.behance.net__videos__b795c0b0-9820-4806-8365-c86630d45070__Creating-a-black-and-white-duo-portrait-commission-with-Suzanne-Helmigh.mp4.
Here are the file infos returned by ffmpeg:

ffmpeg version 4.2.2-static https://johnvansickle.com/ffmpeg/  Copyright (c) 2000-2019 the FFmpeg developers
  built with gcc 8 (Debian 8.3.0-6)
  configuration: --enable-gpl --enable-version3 --enable-static --disable-debug --disable-ffplay --disable-indev=sndio --disable-outdev=sndio --cc=gcc --enable-fontconfig --enable-frei0r --enable-gnutls --enable-gmp --enable-libgme --enable-gray --enable-libaom --enable-libfribidi --enable-libass --enable-libvmaf --enable-libfreetype --enable-libmp3lame --enable-libopencore-amrnb --enable-libopencore-amrwb --enable-libopenjpeg --enable-librubberband --enable-libsoxr --enable-libspeex --enable-libsrt --enable-libvorbis --enable-libopus --enable-libtheora --enable-libvidstab --enable-libvo-amrwbenc --enable-libvpx --enable-libwebp --enable-libx264 --enable-libx265 --enable-libxml2 --enable-libdav1d --enable-libxvid --enable-libzvbi --enable-libzimg
  libavutil      56. 31.100 / 56. 31.100
  libavcodec     58. 54.100 / 58. 54.100
  libavformat    58. 29.100 / 58. 29.100
  libavdevice    58.  8.100 / 58.  8.100
  libavfilter     7. 57.100 /  7. 57.100
  libswscale      5.  5.100 /  5.  5.100
  libswresample   3.  5.100 /  3.  5.100
  libpostproc    55.  5.100 / 55.  5.100
[mov,mp4,m4a,3gp,3g2,mj2 @ 0x6a65500] Format mov,mp4,m4a,3gp,3g2,mj2 detected only with low score of 1, misdetection possible!
[mov,mp4,m4a,3gp,3g2,mj2 @ 0x6a65500] moov atom not found
../data/bid/video/https:____www.behance.net__videos__b795c0b0-9820-4806-8365-c86630d45070__Creating-a-black-and-white-duo-portrait-commission-with-Suzanne-Helmigh.mp4: Invalid data found when processing input

----------------------------------------------------------
https://www.behance.net/videos/419f9f5f-20d1-459e-954d-18da41d0bf7d/Rejected-Elves-Part-2.mp4
Traceback (most recent call last):
  File "/home/saransh03sharma/.local/lib/python3.10/site-packages/moviepy/video/io/ffmpeg_reader.py", line 285, in ffmpeg_parse_infos
    line = [l for l in lines if keyword in l][index]
IndexError: list index out of range

During handling of the above exception, another exception occurred:

Traceback (most recent call last):
  File "/home/saransh03sharma/Documents/GitHub/VideoIntentDiscovery/scripts/download_videos.py", line 54, in get_slices
    video = VideoFileClip(tmp_name)
  File "/home/saransh03sharma/.local/lib/python3.10/site-packages/moviepy/video/io/VideoFileClip.py", line 88, in __init__
    self.reader = FFMPEG_VideoReader(filename, pix_fmt=pix_fmt,
  File "/home/saransh03sharma/.local/lib/python3.10/site-packages/moviepy/video/io/ffmpeg_reader.py", line 35, in __init__
    infos = ffmpeg_parse_infos(filename, print_infos, check_duration,
  File "/home/saransh03sharma/.local/lib/python3.10/site-packages/moviepy/video/io/ffmpeg_reader.py", line 289, in ffmpeg_parse_infos
    raise IOError(("MoviePy error: failed to read the duration of file %s.\n"
OSError: MoviePy error: failed to read the duration of file ../data/bid/video/https:____www.behance.net__videos__419f9f5f-20d1-459e-954d-18da41d0bf7d__Rejected-Elves-Part-2.mp4.
Here are the file infos returned by ffmpeg:

ffmpeg version 4.2.2-static https://johnvansickle.com/ffmpeg/  Copyright (c) 2000-2019 the FFmpeg developers
  built with gcc 8 (Debian 8.3.0-6)
  configuration: --enable-gpl --enable-version3 --enable-static --disable-debug --disable-ffplay --disable-indev=sndio --disable-outdev=sndio --cc=gcc --enable-fontconfig --enable-frei0r --enable-gnutls --enable-gmp --enable-libgme --enable-gray --enable-libaom --enable-libfribidi --enable-libass --enable-libvmaf --enable-libfreetype --enable-libmp3lame --enable-libopencore-amrnb --enable-libopencore-amrwb --enable-libopenjpeg --enable-librubberband --enable-libsoxr --enable-libspeex --enable-libsrt --enable-libvorbis --enable-libopus --enable-libtheora --enable-libvidstab --enable-libvo-amrwbenc --enable-libvpx --enable-libwebp --enable-libx264 --enable-libx265 --enable-libxml2 --enable-libdav1d --enable-libxvid --enable-libzvbi --enable-libzimg
  libavutil      56. 31.100 / 56. 31.100
  libavcodec     58. 54.100 / 58. 54.100
  libavformat    58. 29.100 / 58. 29.100
  libavdevice    58.  8.100 / 58.  8.100
  libavfilter     7. 57.100 /  7. 57.100
  libswscale      5.  5.100 /  5.  5.100
  libswresample   3.  5.100 /  3.  5.100
  libpostproc    55.  5.100 / 55.  5.100
[mov,mp4,m4a,3gp,3g2,mj2 @ 0x7063500] Format mov,mp4,m4a,3gp,3g2,mj2 detected only with low score of 1, misdetection possible!
[mov,mp4,m4a,3gp,3g2,mj2 @ 0x7063500] moov atom not found
../data/bid/video/https:____www.behance.net__videos__419f9f5f-20d1-459e-954d-18da41d0bf7d__Rejected-Elves-Part-2.mp4: Invalid data found when processing input

----------------------------------------------------------
https://www.behance.net/videos/f83ea5f3-dcc8-47c0-ab75-50b489538348/Autumn-Themed-Digital-Painting-Studies-with-Maddy-Bellwoar.mp4
Traceback (most recent call last):
  File "/home/saransh03sharma/.local/lib/python3.10/site-packages/moviepy/video/io/ffmpeg_reader.py", line 285, in ffmpeg_parse_infos
    line = [l for l in lines if keyword in l][index]
IndexError: list index out of range

During handling of the above exception, another exception occurred:

Traceback (most recent call last):
  File "/home/saransh03sharma/Documents/GitHub/VideoIntentDiscovery/scripts/download_videos.py", line 54, in get_slices
    video = VideoFileClip(tmp_name)
  File "/home/saransh03sharma/.local/lib/python3.10/site-packages/moviepy/video/io/VideoFileClip.py", line 88, in __init__
    self.reader = FFMPEG_VideoReader(filename, pix_fmt=pix_fmt,
  File "/home/saransh03sharma/.local/lib/python3.10/site-packages/moviepy/video/io/ffmpeg_reader.py", line 35, in __init__
    infos = ffmpeg_parse_infos(filename, print_infos, check_duration,
  File "/home/saransh03sharma/.local/lib/python3.10/site-packages/moviepy/video/io/ffmpeg_reader.py", line 289, in ffmpeg_parse_infos
    raise IOError(("MoviePy error: failed to read the duration of file %s.\n"
OSError: MoviePy error: failed to read the duration of file ../data/bid/video/https:____www.behance.net__videos__f83ea5f3-dcc8-47c0-ab75-50b489538348__Autumn-Themed-Digital-Painting-Studies-with-Maddy-Bellwoar.mp4.
Here are the file infos returned by ffmpeg:

ffmpeg version 4.2.2-static https://johnvansickle.com/ffmpeg/  Copyright (c) 2000-2019 the FFmpeg developers
  built with gcc 8 (Debian 8.3.0-6)
  configuration: --enable-gpl --enable-version3 --enable-static --disable-debug --disable-ffplay --disable-indev=sndio --disable-outdev=sndio --cc=gcc --enable-fontconfig --enable-frei0r --enable-gnutls --enable-gmp --enable-libgme --enable-gray --enable-libaom --enable-libfribidi --enable-libass --enable-libvmaf --enable-libfreetype --enable-libmp3lame --enable-libopencore-amrnb --enable-libopencore-amrwb --enable-libopenjpeg --enable-librubberband --enable-libsoxr --enable-libspeex --enable-libsrt --enable-libvorbis --enable-libopus --enable-libtheora --enable-libvidstab --enable-libvo-amrwbenc --enable-libvpx --enable-libwebp --enable-libx264 --enable-libx265 --enable-libxml2 --enable-libdav1d --enable-libxvid --enable-libzvbi --enable-libzimg
  libavutil      56. 31.100 / 56. 31.100
  libavcodec     58. 54.100 / 58. 54.100
  libavformat    58. 29.100 / 58. 29.100
  libavdevice    58.  8.100 / 58.  8.100
  libavfilter     7. 57.100 /  7. 57.100
  libswscale      5.  5.100 /  5.  5.100
  libswresample   3.  5.100 /  3.  5.100
  libpostproc    55.  5.100 / 55.  5.100
[mov,mp4,m4a,3gp,3g2,mj2 @ 0x5881500] Format mov,mp4,m4a,3gp,3g2,mj2 detected only with low score of 1, misdetection possible!
[mov,mp4,m4a,3gp,3g2,mj2 @ 0x5881500] moov atom not found
../data/bid/video/https:____www.behance.net__videos__f83ea5f3-dcc8-47c0-ab75-50b489538348__Autumn-Themed-Digital-Painting-Studies-with-Maddy-Bellwoar.mp4: Invalid data found when processing input

----------------------------------------------------------
https://www.behance.net/videos/8e1173b7-9e84-4f44-a849-243f2271bb2c/Thinking-Doodles-with-Rachel-Ashley-from-Fresco.mp4
Traceback (most recent call last):
  File "/home/saransh03sharma/.local/lib/python3.10/site-packages/moviepy/video/io/ffmpeg_reader.py", line 285, in ffmpeg_parse_infos
    line = [l for l in lines if keyword in l][index]
IndexError: list index out of range

During handling of the above exception, another exception occurred:

Traceback (most recent call last):
  File "/home/saransh03sharma/Documents/GitHub/VideoIntentDiscovery/scripts/download_videos.py", line 54, in get_slices
    video = VideoFileClip(tmp_name)
  File "/home/saransh03sharma/.local/lib/python3.10/site-packages/moviepy/video/io/VideoFileClip.py", line 88, in __init__
    self.reader = FFMPEG_VideoReader(filename, pix_fmt=pix_fmt,
  File "/home/saransh03sharma/.local/lib/python3.10/site-packages/moviepy/video/io/ffmpeg_reader.py", line 35, in __init__
    infos = ffmpeg_parse_infos(filename, print_infos, check_duration,
  File "/home/saransh03sharma/.local/lib/python3.10/site-packages/moviepy/video/io/ffmpeg_reader.py", line 289, in ffmpeg_parse_infos
    raise IOError(("MoviePy error: failed to read the duration of file %s.\n"
OSError: MoviePy error: failed to read the duration of file ../data/bid/video/https:____www.behance.net__videos__8e1173b7-9e84-4f44-a849-243f2271bb2c__Thinking-Doodles-with-Rachel-Ashley-from-Fresco.mp4.
Here are the file infos returned by ffmpeg:

ffmpeg version 4.2.2-static https://johnvansickle.com/ffmpeg/  Copyright (c) 2000-2019 the FFmpeg developers
  built with gcc 8 (Debian 8.3.0-6)
  configuration: --enable-gpl --enable-version3 --enable-static --disable-debug --disable-ffplay --disable-indev=sndio --disable-outdev=sndio --cc=gcc --enable-fontconfig --enable-frei0r --enable-gnutls --enable-gmp --enable-libgme --enable-gray --enable-libaom --enable-libfribidi --enable-libass --enable-libvmaf --enable-libfreetype --enable-libmp3lame --enable-libopencore-amrnb --enable-libopencore-amrwb --enable-libopenjpeg --enable-librubberband --enable-libsoxr --enable-libspeex --enable-libsrt --enable-libvorbis --enable-libopus --enable-libtheora --enable-libvidstab --enable-libvo-amrwbenc --enable-libvpx --enable-libwebp --enable-libx264 --enable-libx265 --enable-libxml2 --enable-libdav1d --enable-libxvid --enable-libzvbi --enable-libzimg
  libavutil      56. 31.100 / 56. 31.100
  libavcodec     58. 54.100 / 58. 54.100
  libavformat    58. 29.100 / 58. 29.100
  libavdevice    58.  8.100 / 58.  8.100
  libavfilter     7. 57.100 /  7. 57.100
  libswscale      5.  5.100 /  5.  5.100
  libswresample   3.  5.100 /  3.  5.100
  libpostproc    55.  5.100 / 55.  5.100
[mov,mp4,m4a,3gp,3g2,mj2 @ 0x6a91500] Format mov,mp4,m4a,3gp,3g2,mj2 detected only with low score of 1, misdetection possible!
[mov,mp4,m4a,3gp,3g2,mj2 @ 0x6a91500] moov atom not found
../data/bid/video/https:____www.behance.net__videos__8e1173b7-9e84-4f44-a849-243f2271bb2c__Thinking-Doodles-with-Rachel-Ashley-from-Fresco.mp4: Invalid data found when processing input

----------------------------------------------------------
https://www.behance.net/videos/37aec988-de9b-4bf9-941e-947c4b7406e2/Virtual-Plein-Air-Sketch-Studies-with-Maddy-Bellwoar.mp4
Traceback (most recent call last):
  File "/home/saransh03sharma/.local/lib/python3.10/site-packages/moviepy/video/io/ffmpeg_reader.py", line 285, in ffmpeg_parse_infos
    line = [l for l in lines if keyword in l][index]
IndexError: list index out of range

During handling of the above exception, another exception occurred:

Traceback (most recent call last):
  File "/home/saransh03sharma/Documents/GitHub/VideoIntentDiscovery/scripts/download_videos.py", line 54, in get_slices
    video = VideoFileClip(tmp_name)
  File "/home/saransh03sharma/.local/lib/python3.10/site-packages/moviepy/video/io/VideoFileClip.py", line 88, in __init__
    self.reader = FFMPEG_VideoReader(filename, pix_fmt=pix_fmt,
  File "/home/saransh03sharma/.local/lib/python3.10/site-packages/moviepy/video/io/ffmpeg_reader.py", line 35, in __init__
    infos = ffmpeg_parse_infos(filename, print_infos, check_duration,
  File "/home/saransh03sharma/.local/lib/python3.10/site-packages/moviepy/video/io/ffmpeg_reader.py", line 289, in ffmpeg_parse_infos
    raise IOError(("MoviePy error: failed to read the duration of file %s.\n"
OSError: MoviePy error: failed to read the duration of file ../data/bid/video/https:____www.behance.net__videos__37aec988-de9b-4bf9-941e-947c4b7406e2__Virtual-Plein-Air-Sketch-Studies-with-Maddy-Bellwoar.mp4.
Here are the file infos returned by ffmpeg:

ffmpeg version 4.2.2-static https://johnvansickle.com/ffmpeg/  Copyright (c) 2000-2019 the FFmpeg developers
  built with gcc 8 (Debian 8.3.0-6)
  configuration: --enable-gpl --enable-version3 --enable-static --disable-debug --disable-ffplay --disable-indev=sndio --disable-outdev=sndio --cc=gcc --enable-fontconfig --enable-frei0r --enable-gnutls --enable-gmp --enable-libgme --enable-gray --enable-libaom --enable-libfribidi --enable-libass --enable-libvmaf --enable-libfreetype --enable-libmp3lame --enable-libopencore-amrnb --enable-libopencore-amrwb --enable-libopenjpeg --enable-librubberband --enable-libsoxr --enable-libspeex --enable-libsrt --enable-libvorbis --enable-libopus --enable-libtheora --enable-libvidstab --enable-libvo-amrwbenc --enable-libvpx --enable-libwebp --enable-libx264 --enable-libx265 --enable-libxml2 --enable-libdav1d --enable-libxvid --enable-libzvbi --enable-libzimg
  libavutil      56. 31.100 / 56. 31.100
  libavcodec     58. 54.100 / 58. 54.100
  libavformat    58. 29.100 / 58. 29.100
  libavdevice    58.  8.100 / 58.  8.100
  libavfilter     7. 57.100 /  7. 57.100
  libswscale      5.  5.100 /  5.  5.100
  libswresample   3.  5.100 /  3.  5.100
  libpostproc    55.  5.100 / 55.  5.100
[mov,mp4,m4a,3gp,3g2,mj2 @ 0x6cff500] Format mov,mp4,m4a,3gp,3g2,mj2 detected only with low score of 1, misdetection possible!
[mov,mp4,m4a,3gp,3g2,mj2 @ 0x6cff500] moov atom not found
../data/bid/video/https:____www.behance.net__videos__37aec988-de9b-4bf9-941e-947c4b7406e2__Virtual-Plein-Air-Sketch-Studies-with-Maddy-Bellwoar.mp4: Invalid data found when processing input

----------------------------------------------------------
https://www.behance.net/videos/419f9f5f-20d1-459e-954d-18da41d0bf7d/Rejected-Elves-Part-2.mp4
Traceback (most recent call last):
  File "/home/saransh03sharma/.local/lib/python3.10/site-packages/moviepy/video/io/ffmpeg_reader.py", line 285, in ffmpeg_parse_infos
    line = [l for l in lines if keyword in l][index]
IndexError: list index out of range

During handling of the above exception, another exception occurred:

Traceback (most recent call last):
  File "/home/saransh03sharma/Documents/GitHub/VideoIntentDiscovery/scripts/download_videos.py", line 49, in get_slices
    video = VideoFileClip(tmp_name)
  File "/home/saransh03sharma/.local/lib/python3.10/site-packages/moviepy/video/io/VideoFileClip.py", line 88, in __init__
    self.reader = FFMPEG_VideoReader(filename, pix_fmt=pix_fmt,
  File "/home/saransh03sharma/.local/lib/python3.10/site-packages/moviepy/video/io/ffmpeg_reader.py", line 35, in __init__
    infos = ffmpeg_parse_infos(filename, print_infos, check_duration,
  File "/home/saransh03sharma/.local/lib/python3.10/site-packages/moviepy/video/io/ffmpeg_reader.py", line 289, in ffmpeg_parse_infos
    raise IOError(("MoviePy error: failed to read the duration of file %s.\n"
OSError: MoviePy error: failed to read the duration of file ../data/bid/video/https:____www.behance.net__videos__419f9f5f-20d1-459e-954d-18da41d0bf7d__Rejected-Elves-Part-2.mp4.
Here are the file infos returned by ffmpeg:

ffmpeg version 4.2.2-static https://johnvansickle.com/ffmpeg/  Copyright (c) 2000-2019 the FFmpeg developers
  built with gcc 8 (Debian 8.3.0-6)
  configuration: --enable-gpl --enable-version3 --enable-static --disable-debug --disable-ffplay --disable-indev=sndio --disable-outdev=sndio --cc=gcc --enable-fontconfig --enable-frei0r --enable-gnutls --enable-gmp --enable-libgme --enable-gray --enable-libaom --enable-libfribidi --enable-libass --enable-libvmaf --enable-libfreetype --enable-libmp3lame --enable-libopencore-amrnb --enable-libopencore-amrwb --enable-libopenjpeg --enable-librubberband --enable-libsoxr --enable-libspeex --enable-libsrt --enable-libvorbis --enable-libopus --enable-libtheora --enable-libvidstab --enable-libvo-amrwbenc --enable-libvpx --enable-libwebp --enable-libx264 --enable-libx265 --enable-libxml2 --enable-libdav1d --enable-libxvid --enable-libzvbi --enable-libzimg
  libavutil      56. 31.100 / 56. 31.100
  libavcodec     58. 54.100 / 58. 54.100
  libavformat    58. 29.100 / 58. 29.100
  libavdevice    58.  8.100 / 58.  8.100
  libavfilter     7. 57.100 /  7. 57.100
  libswscale      5.  5.100 /  5.  5.100
  libswresample   3.  5.100 /  3.  5.100
  libpostproc    55.  5.100 / 55.  5.100
[mov,mp4,m4a,3gp,3g2,mj2 @ 0x6922500] Format mov,mp4,m4a,3gp,3g2,mj2 detected only with low score of 1, misdetection possible!
[mov,mp4,m4a,3gp,3g2,mj2 @ 0x6922500] moov atom not found
../data/bid/video/https:____www.behance.net__videos__419f9f5f-20d1-459e-954d-18da41d0bf7d__Rejected-Elves-Part-2.mp4: Invalid data found when processing input

----------------------------------------------------------
https://www.behance.net/videos/b795c0b0-9820-4806-8365-c86630d45070/Creating-a-black-and-white-duo-portrait-commission-with-Suzanne-Helmigh.mp4
Traceback (most recent call last):
  File "/home/saransh03sharma/.local/lib/python3.10/site-packages/moviepy/video/io/ffmpeg_reader.py", line 285, in ffmpeg_parse_infos
    line = [l for l in lines if keyword in l][index]
IndexError: list index out of range

During handling of the above exception, another exception occurred:

Traceback (most recent call last):
  File "/home/saransh03sharma/Documents/GitHub/VideoIntentDiscovery/scripts/download_videos.py", line 49, in get_slices
    video = VideoFileClip(tmp_name)
  File "/home/saransh03sharma/.local/lib/python3.10/site-packages/moviepy/video/io/VideoFileClip.py", line 88, in __init__
    self.reader = FFMPEG_VideoReader(filename, pix_fmt=pix_fmt,
  File "/home/saransh03sharma/.local/lib/python3.10/site-packages/moviepy/video/io/ffmpeg_reader.py", line 35, in __init__
    infos = ffmpeg_parse_infos(filename, print_infos, check_duration,
  File "/home/saransh03sharma/.local/lib/python3.10/site-packages/moviepy/video/io/ffmpeg_reader.py", line 289, in ffmpeg_parse_infos
    raise IOError(("MoviePy error: failed to read the duration of file %s.\n"
OSError: MoviePy error: failed to read the duration of file ../data/bid/video/https:____www.behance.net__videos__b795c0b0-9820-4806-8365-c86630d45070__Creating-a-black-and-white-duo-portrait-commission-with-Suzanne-Helmigh.mp4.
Here are the file infos returned by ffmpeg:

ffmpeg version 4.2.2-static https://johnvansickle.com/ffmpeg/  Copyright (c) 2000-2019 the FFmpeg developers
  built with gcc 8 (Debian 8.3.0-6)
  configuration: --enable-gpl --enable-version3 --enable-static --disable-debug --disable-ffplay --disable-indev=sndio --disable-outdev=sndio --cc=gcc --enable-fontconfig --enable-frei0r --enable-gnutls --enable-gmp --enable-libgme --enable-gray --enable-libaom --enable-libfribidi --enable-libass --enable-libvmaf --enable-libfreetype --enable-libmp3lame --enable-libopencore-amrnb --enable-libopencore-amrwb --enable-libopenjpeg --enable-librubberband --enable-libsoxr --enable-libspeex --enable-libsrt --enable-libvorbis --enable-libopus --enable-libtheora --enable-libvidstab --enable-libvo-amrwbenc --enable-libvpx --enable-libwebp --enable-libx264 --enable-libx265 --enable-libxml2 --enable-libdav1d --enable-libxvid --enable-libzvbi --enable-libzimg
  libavutil      56. 31.100 / 56. 31.100
  libavcodec     58. 54.100 / 58. 54.100
  libavformat    58. 29.100 / 58. 29.100
  libavdevice    58.  8.100 / 58.  8.100
  libavfilter     7. 57.100 /  7. 57.100
  libswscale      5.  5.100 /  5.  5.100
  libswresample   3.  5.100 /  3.  5.100
  libpostproc    55.  5.100 / 55.  5.100
[mov,mp4,m4a,3gp,3g2,mj2 @ 0x5668500] Format mov,mp4,m4a,3gp,3g2,mj2 detected only with low score of 1, misdetection possible!
[mov,mp4,m4a,3gp,3g2,mj2 @ 0x5668500] moov atom not found
../data/bid/video/https:____www.behance.net__videos__b795c0b0-9820-4806-8365-c86630d45070__Creating-a-black-and-white-duo-portrait-commission-with-Suzanne-Helmigh.mp4: Invalid data found when processing input

----------------------------------------------------------
https://www.behance.net/videos/f83ea5f3-dcc8-47c0-ab75-50b489538348/Autumn-Themed-Digital-Painting-Studies-with-Maddy-Bellwoar.mp4
Traceback (most recent call last):
  File "/home/saransh03sharma/.local/lib/python3.10/site-packages/moviepy/video/io/ffmpeg_reader.py", line 285, in ffmpeg_parse_infos
    line = [l for l in lines if keyword in l][index]
IndexError: list index out of range

During handling of the above exception, another exception occurred:

Traceback (most recent call last):
  File "/home/saransh03sharma/Documents/GitHub/VideoIntentDiscovery/scripts/download_videos.py", line 49, in get_slices
    video = VideoFileClip(tmp_name)
  File "/home/saransh03sharma/.local/lib/python3.10/site-packages/moviepy/video/io/VideoFileClip.py", line 88, in __init__
    self.reader = FFMPEG_VideoReader(filename, pix_fmt=pix_fmt,
  File "/home/saransh03sharma/.local/lib/python3.10/site-packages/moviepy/video/io/ffmpeg_reader.py", line 35, in __init__
    infos = ffmpeg_parse_infos(filename, print_infos, check_duration,
  File "/home/saransh03sharma/.local/lib/python3.10/site-packages/moviepy/video/io/ffmpeg_reader.py", line 289, in ffmpeg_parse_infos
    raise IOError(("MoviePy error: failed to read the duration of file %s.\n"
OSError: MoviePy error: failed to read the duration of file ../data/bid/video/https:____www.behance.net__videos__f83ea5f3-dcc8-47c0-ab75-50b489538348__Autumn-Themed-Digital-Painting-Studies-with-Maddy-Bellwoar.mp4.
Here are the file infos returned by ffmpeg:

ffmpeg version 4.2.2-static https://johnvansickle.com/ffmpeg/  Copyright (c) 2000-2019 the FFmpeg developers
  built with gcc 8 (Debian 8.3.0-6)
  configuration: --enable-gpl --enable-version3 --enable-static --disable-debug --disable-ffplay --disable-indev=sndio --disable-outdev=sndio --cc=gcc --enable-fontconfig --enable-frei0r --enable-gnutls --enable-gmp --enable-libgme --enable-gray --enable-libaom --enable-libfribidi --enable-libass --enable-libvmaf --enable-libfreetype --enable-libmp3lame --enable-libopencore-amrnb --enable-libopencore-amrwb --enable-libopenjpeg --enable-librubberband --enable-libsoxr --enable-libspeex --enable-libsrt --enable-libvorbis --enable-libopus --enable-libtheora --enable-libvidstab --enable-libvo-amrwbenc --enable-libvpx --enable-libwebp --enable-libx264 --enable-libx265 --enable-libxml2 --enable-libdav1d --enable-libxvid --enable-libzvbi --enable-libzimg
  libavutil      56. 31.100 / 56. 31.100
  libavcodec     58. 54.100 / 58. 54.100
  libavformat    58. 29.100 / 58. 29.100
  libavdevice    58.  8.100 / 58.  8.100
  libavfilter     7. 57.100 /  7. 57.100
  libswscale      5.  5.100 /  5.  5.100
  libswresample   3.  5.100 /  3.  5.100
  libpostproc    55.  5.100 / 55.  5.100
[mov,mp4,m4a,3gp,3g2,mj2 @ 0x605a500] Format mov,mp4,m4a,3gp,3g2,mj2 detected only with low score of 1, misdetection possible!
[mov,mp4,m4a,3gp,3g2,mj2 @ 0x605a500] moov atom not found
../data/bid/video/https:____www.behance.net__videos__f83ea5f3-dcc8-47c0-ab75-50b489538348__Autumn-Themed-Digital-Painting-Studies-with-Maddy-Bellwoar.mp4: Invalid data found when processing input

----------------------------------------------------------
https://www.behance.net/videos/8e1173b7-9e84-4f44-a849-243f2271bb2c/Thinking-Doodles-with-Rachel-Ashley-from-Fresco.mp4
Traceback (most recent call last):
  File "/home/saransh03sharma/.local/lib/python3.10/site-packages/moviepy/video/io/ffmpeg_reader.py", line 285, in ffmpeg_parse_infos
    line = [l for l in lines if keyword in l][index]
IndexError: list index out of range

During handling of the above exception, another exception occurred:

Traceback (most recent call last):
  File "/home/saransh03sharma/Documents/GitHub/VideoIntentDiscovery/scripts/download_videos.py", line 49, in get_slices
    video = VideoFileClip(tmp_name)
  File "/home/saransh03sharma/.local/lib/python3.10/site-packages/moviepy/video/io/VideoFileClip.py", line 88, in __init__
    self.reader = FFMPEG_VideoReader(filename, pix_fmt=pix_fmt,
  File "/home/saransh03sharma/.local/lib/python3.10/site-packages/moviepy/video/io/ffmpeg_reader.py", line 35, in __init__
    infos = ffmpeg_parse_infos(filename, print_infos, check_duration,
  File "/home/saransh03sharma/.local/lib/python3.10/site-packages/moviepy/video/io/ffmpeg_reader.py", line 289, in ffmpeg_parse_infos
    raise IOError(("MoviePy error: failed to read the duration of file %s.\n"
OSError: MoviePy error: failed to read the duration of file ../data/bid/video/https:____www.behance.net__videos__8e1173b7-9e84-4f44-a849-243f2271bb2c__Thinking-Doodles-with-Rachel-Ashley-from-Fresco.mp4.
Here are the file infos returned by ffmpeg:

ffmpeg version 4.2.2-static https://johnvansickle.com/ffmpeg/  Copyright (c) 2000-2019 the FFmpeg developers
  built with gcc 8 (Debian 8.3.0-6)
  configuration: --enable-gpl --enable-version3 --enable-static --disable-debug --disable-ffplay --disable-indev=sndio --disable-outdev=sndio --cc=gcc --enable-fontconfig --enable-frei0r --enable-gnutls --enable-gmp --enable-libgme --enable-gray --enable-libaom --enable-libfribidi --enable-libass --enable-libvmaf --enable-libfreetype --enable-libmp3lame --enable-libopencore-amrnb --enable-libopencore-amrwb --enable-libopenjpeg --enable-librubberband --enable-libsoxr --enable-libspeex --enable-libsrt --enable-libvorbis --enable-libopus --enable-libtheora --enable-libvidstab --enable-libvo-amrwbenc --enable-libvpx --enable-libwebp --enable-libx264 --enable-libx265 --enable-libxml2 --enable-libdav1d --enable-libxvid --enable-libzvbi --enable-libzimg
  libavutil      56. 31.100 / 56. 31.100
  libavcodec     58. 54.100 / 58. 54.100
  libavformat    58. 29.100 / 58. 29.100
  libavdevice    58.  8.100 / 58.  8.100
  libavfilter     7. 57.100 /  7. 57.100
  libswscale      5.  5.100 /  5.  5.100
  libswresample   3.  5.100 /  3.  5.100
  libpostproc    55.  5.100 / 55.  5.100
[mov,mp4,m4a,3gp,3g2,mj2 @ 0x6e19500] Format mov,mp4,m4a,3gp,3g2,mj2 detected only with low score of 1, misdetection possible!
[mov,mp4,m4a,3gp,3g2,mj2 @ 0x6e19500] moov atom not found
../data/bid/video/https:____www.behance.net__videos__8e1173b7-9e84-4f44-a849-243f2271bb2c__Thinking-Doodles-with-Rachel-Ashley-from-Fresco.mp4: Invalid data found when processing input

----------------------------------------------------------
https://www.behance.net/videos/37aec988-de9b-4bf9-941e-947c4b7406e2/Virtual-Plein-Air-Sketch-Studies-with-Maddy-Bellwoar.mp4
Traceback (most recent call last):
  File "/home/saransh03sharma/.local/lib/python3.10/site-packages/moviepy/video/io/ffmpeg_reader.py", line 285, in ffmpeg_parse_infos
    line = [l for l in lines if keyword in l][index]
IndexError: list index out of range

During handling of the above exception, another exception occurred:

Traceback (most recent call last):
  File "/home/saransh03sharma/Documents/GitHub/VideoIntentDiscovery/scripts/download_videos.py", line 49, in get_slices
    video = VideoFileClip(tmp_name)
  File "/home/saransh03sharma/.local/lib/python3.10/site-packages/moviepy/video/io/VideoFileClip.py", line 88, in __init__
    self.reader = FFMPEG_VideoReader(filename, pix_fmt=pix_fmt,
  File "/home/saransh03sharma/.local/lib/python3.10/site-packages/moviepy/video/io/ffmpeg_reader.py", line 35, in __init__
    infos = ffmpeg_parse_infos(filename, print_infos, check_duration,
  File "/home/saransh03sharma/.local/lib/python3.10/site-packages/moviepy/video/io/ffmpeg_reader.py", line 289, in ffmpeg_parse_infos
    raise IOError(("MoviePy error: failed to read the duration of file %s.\n"
OSError: MoviePy error: failed to read the duration of file ../data/bid/video/https:____www.behance.net__videos__37aec988-de9b-4bf9-941e-947c4b7406e2__Virtual-Plein-Air-Sketch-Studies-with-Maddy-Bellwoar.mp4.
Here are the file infos returned by ffmpeg:

ffmpeg version 4.2.2-static https://johnvansickle.com/ffmpeg/  Copyright (c) 2000-2019 the FFmpeg developers
  built with gcc 8 (Debian 8.3.0-6)
  configuration: --enable-gpl --enable-version3 --enable-static --disable-debug --disable-ffplay --disable-indev=sndio --disable-outdev=sndio --cc=gcc --enable-fontconfig --enable-frei0r --enable-gnutls --enable-gmp --enable-libgme --enable-gray --enable-libaom --enable-libfribidi --enable-libass --enable-libvmaf --enable-libfreetype --enable-libmp3lame --enable-libopencore-amrnb --enable-libopencore-amrwb --enable-libopenjpeg --enable-librubberband --enable-libsoxr --enable-libspeex --enable-libsrt --enable-libvorbis --enable-libopus --enable-libtheora --enable-libvidstab --enable-libvo-amrwbenc --enable-libvpx --enable-libwebp --enable-libx264 --enable-libx265 --enable-libxml2 --enable-libdav1d --enable-libxvid --enable-libzvbi --enable-libzimg
  libavutil      56. 31.100 / 56. 31.100
  libavcodec     58. 54.100 / 58. 54.100
  libavformat    58. 29.100 / 58. 29.100
  libavdevice    58.  8.100 / 58.  8.100
  libavfilter     7. 57.100 /  7. 57.100
  libswscale      5.  5.100 /  5.  5.100
  libswresample   3.  5.100 /  3.  5.100
  libpostproc    55.  5.100 / 55.  5.100
[mov,mp4,m4a,3gp,3g2,mj2 @ 0x74af500] Format mov,mp4,m4a,3gp,3g2,mj2 detected only with low score of 1, misdetection possible!
[mov,mp4,m4a,3gp,3g2,mj2 @ 0x74af500] moov atom not found
../data/bid/video/https:____www.behance.net__videos__37aec988-de9b-4bf9-941e-947c4b7406e2__Virtual-Plein-Air-Sketch-Studies-with-Maddy-Bellwoar.mp4: Invalid data found when processing input

----------------------------------------------------------
https://www.behance.net/videos/c147bd15-2e4a-4205-9bb3-25133826df6a/Shilin-chipping-away-a-painting.mp4
Traceback (most recent call last):
  File "/home/saransh03sharma/.local/lib/python3.10/site-packages/moviepy/video/io/ffmpeg_reader.py", line 285, in ffmpeg_parse_infos
    line = [l for l in lines if keyword in l][index]
IndexError: list index out of range

During handling of the above exception, another exception occurred:

Traceback (most recent call last):
  File "/home/saransh03sharma/Documents/GitHub/VideoIntentDiscovery/scripts/download_videos.py", line 49, in get_slices
    video = VideoFileClip(tmp_name)
  File "/home/saransh03sharma/.local/lib/python3.10/site-packages/moviepy/video/io/VideoFileClip.py", line 88, in __init__
    self.reader = FFMPEG_VideoReader(filename, pix_fmt=pix_fmt,
  File "/home/saransh03sharma/.local/lib/python3.10/site-packages/moviepy/video/io/ffmpeg_reader.py", line 35, in __init__
    infos = ffmpeg_parse_infos(filename, print_infos, check_duration,
  File "/home/saransh03sharma/.local/lib/python3.10/site-packages/moviepy/video/io/ffmpeg_reader.py", line 289, in ffmpeg_parse_infos
    raise IOError(("MoviePy error: failed to read the duration of file %s.\n"
OSError: MoviePy error: failed to read the duration of file ../data/bid/video/https:____www.behance.net__videos__c147bd15-2e4a-4205-9bb3-25133826df6a__Shilin-chipping-away-a-painting.mp4.
Here are the file infos returned by ffmpeg:

ffmpeg version 4.2.2-static https://johnvansickle.com/ffmpeg/  Copyright (c) 2000-2019 the FFmpeg developers
  built with gcc 8 (Debian 8.3.0-6)
  configuration: --enable-gpl --enable-version3 --enable-static --disable-debug --disable-ffplay --disable-indev=sndio --disable-outdev=sndio --cc=gcc --enable-fontconfig --enable-frei0r --enable-gnutls --enable-gmp --enable-libgme --enable-gray --enable-libaom --enable-libfribidi --enable-libass --enable-libvmaf --enable-libfreetype --enable-libmp3lame --enable-libopencore-amrnb --enable-libopencore-amrwb --enable-libopenjpeg --enable-librubberband --enable-libsoxr --enable-libspeex --enable-libsrt --enable-libvorbis --enable-libopus --enable-libtheora --enable-libvidstab --enable-libvo-amrwbenc --enable-libvpx --enable-libwebp --enable-libx264 --enable-libx265 --enable-libxml2 --enable-libdav1d --enable-libxvid --enable-libzvbi --enable-libzimg
  libavutil      56. 31.100 / 56. 31.100
  libavcodec     58. 54.100 / 58. 54.100
  libavformat    58. 29.100 / 58. 29.100
  libavdevice    58.  8.100 / 58.  8.100
  libavfilter     7. 57.100 /  7. 57.100
  libswscale      5.  5.100 /  5.  5.100
  libswresample   3.  5.100 /  3.  5.100
  libpostproc    55.  5.100 / 55.  5.100
[mov,mp4,m4a,3gp,3g2,mj2 @ 0x604d500] Format mov,mp4,m4a,3gp,3g2,mj2 detected only with low score of 1, misdetection possible!
[mov,mp4,m4a,3gp,3g2,mj2 @ 0x604d500] moov atom not found
../data/bid/video/https:____www.behance.net__videos__c147bd15-2e4a-4205-9bb3-25133826df6a__Shilin-chipping-away-a-painting.mp4: Invalid data found when processing input

----------------------------------------------------------
https://www.behance.net/videos/7e9ff601-cbf5-4fdf-be0f-1685186b5ff3/Frame-by-Frame-Animation-in-Photoshop-with-Klarens-Malluta.mp4
Traceback (most recent call last):
  File "/home/saransh03sharma/.local/lib/python3.10/site-packages/moviepy/video/io/ffmpeg_reader.py", line 285, in ffmpeg_parse_infos
    line = [l for l in lines if keyword in l][index]
IndexError: list index out of range

During handling of the above exception, another exception occurred:

Traceback (most recent call last):
  File "/home/saransh03sharma/Documents/GitHub/VideoIntentDiscovery/scripts/download_videos.py", line 49, in get_slices
    video = VideoFileClip(tmp_name)
  File "/home/saransh03sharma/.local/lib/python3.10/site-packages/moviepy/video/io/VideoFileClip.py", line 88, in __init__
    self.reader = FFMPEG_VideoReader(filename, pix_fmt=pix_fmt,
  File "/home/saransh03sharma/.local/lib/python3.10/site-packages/moviepy/video/io/ffmpeg_reader.py", line 35, in __init__
    infos = ffmpeg_parse_infos(filename, print_infos, check_duration,
  File "/home/saransh03sharma/.local/lib/python3.10/site-packages/moviepy/video/io/ffmpeg_reader.py", line 289, in ffmpeg_parse_infos
    raise IOError(("MoviePy error: failed to read the duration of file %s.\n"
OSError: MoviePy error: failed to read the duration of file ../data/bid/video/https:____www.behance.net__videos__7e9ff601-cbf5-4fdf-be0f-1685186b5ff3__Frame-by-Frame-Animation-in-Photoshop-with-Klarens-Malluta.mp4.
Here are the file infos returned by ffmpeg:

ffmpeg version 4.2.2-static https://johnvansickle.com/ffmpeg/  Copyright (c) 2000-2019 the FFmpeg developers
  built with gcc 8 (Debian 8.3.0-6)
  configuration: --enable-gpl --enable-version3 --enable-static --disable-debug --disable-ffplay --disable-indev=sndio --disable-outdev=sndio --cc=gcc --enable-fontconfig --enable-frei0r --enable-gnutls --enable-gmp --enable-libgme --enable-gray --enable-libaom --enable-libfribidi --enable-libass --enable-libvmaf --enable-libfreetype --enable-libmp3lame --enable-libopencore-amrnb --enable-libopencore-amrwb --enable-libopenjpeg --enable-librubberband --enable-libsoxr --enable-libspeex --enable-libsrt --enable-libvorbis --enable-libopus --enable-libtheora --enable-libvidstab --enable-libvo-amrwbenc --enable-libvpx --enable-libwebp --enable-libx264 --enable-libx265 --enable-libxml2 --enable-libdav1d --enable-libxvid --enable-libzvbi --enable-libzimg
  libavutil      56. 31.100 / 56. 31.100
  libavcodec     58. 54.100 / 58. 54.100
  libavformat    58. 29.100 / 58. 29.100
  libavdevice    58.  8.100 / 58.  8.100
  libavfilter     7. 57.100 /  7. 57.100
  libswscale      5.  5.100 /  5.  5.100
  libswresample   3.  5.100 /  3.  5.100
  libpostproc    55.  5.100 / 55.  5.100
[mov,mp4,m4a,3gp,3g2,mj2 @ 0x5efd500] Format mov,mp4,m4a,3gp,3g2,mj2 detected only with low score of 1, misdetection possible!
[mov,mp4,m4a,3gp,3g2,mj2 @ 0x5efd500] moov atom not found
../data/bid/video/https:____www.behance.net__videos__7e9ff601-cbf5-4fdf-be0f-1685186b5ff3__Frame-by-Frame-Animation-in-Photoshop-with-Klarens-Malluta.mp4: Invalid data found when processing input

----------------------------------------------------------
https://www.behance.net/videos/d91ef6a6-fa91-4dcb-8b86-48efc87a906a/TUTS42-Episode-5-Don-t-Blink.mp4
Traceback (most recent call last):
  File "/home/saransh03sharma/.local/lib/python3.10/site-packages/moviepy/video/io/ffmpeg_reader.py", line 285, in ffmpeg_parse_infos
    line = [l for l in lines if keyword in l][index]
IndexError: list index out of range

During handling of the above exception, another exception occurred:

Traceback (most recent call last):
  File "/home/saransh03sharma/Documents/GitHub/VideoIntentDiscovery/scripts/download_videos.py", line 49, in get_slices
    video = VideoFileClip(tmp_name)
  File "/home/saransh03sharma/.local/lib/python3.10/site-packages/moviepy/video/io/VideoFileClip.py", line 88, in __init__
    self.reader = FFMPEG_VideoReader(filename, pix_fmt=pix_fmt,
  File "/home/saransh03sharma/.local/lib/python3.10/site-packages/moviepy/video/io/ffmpeg_reader.py", line 35, in __init__
    infos = ffmpeg_parse_infos(filename, print_infos, check_duration,
  File "/home/saransh03sharma/.local/lib/python3.10/site-packages/moviepy/video/io/ffmpeg_reader.py", line 289, in ffmpeg_parse_infos
    raise IOError(("MoviePy error: failed to read the duration of file %s.\n"
OSError: MoviePy error: failed to read the duration of file ../data/bid/video/https:____www.behance.net__videos__d91ef6a6-fa91-4dcb-8b86-48efc87a906a__TUTS42-Episode-5-Don-t-Blink.mp4.
Here are the file infos returned by ffmpeg:

ffmpeg version 4.2.2-static https://johnvansickle.com/ffmpeg/  Copyright (c) 2000-2019 the FFmpeg developers
  built with gcc 8 (Debian 8.3.0-6)
  configuration: --enable-gpl --enable-version3 --enable-static --disable-debug --disable-ffplay --disable-indev=sndio --disable-outdev=sndio --cc=gcc --enable-fontconfig --enable-frei0r --enable-gnutls --enable-gmp --enable-libgme --enable-gray --enable-libaom --enable-libfribidi --enable-libass --enable-libvmaf --enable-libfreetype --enable-libmp3lame --enable-libopencore-amrnb --enable-libopencore-amrwb --enable-libopenjpeg --enable-librubberband --enable-libsoxr --enable-libspeex --enable-libsrt --enable-libvorbis --enable-libopus --enable-libtheora --enable-libvidstab --enable-libvo-amrwbenc --enable-libvpx --enable-libwebp --enable-libx264 --enable-libx265 --enable-libxml2 --enable-libdav1d --enable-libxvid --enable-libzvbi --enable-libzimg
  libavutil      56. 31.100 / 56. 31.100
  libavcodec     58. 54.100 / 58. 54.100
  libavformat    58. 29.100 / 58. 29.100
  libavdevice    58.  8.100 / 58.  8.100
  libavfilter     7. 57.100 /  7. 57.100
  libswscale      5.  5.100 /  5.  5.100
  libswresample   3.  5.100 /  3.  5.100
  libpostproc    55.  5.100 / 55.  5.100
[mov,mp4,m4a,3gp,3g2,mj2 @ 0x566c500] Format mov,mp4,m4a,3gp,3g2,mj2 detected only with low score of 1, misdetection possible!
[mov,mp4,m4a,3gp,3g2,mj2 @ 0x566c500] moov atom not found
../data/bid/video/https:____www.behance.net__videos__d91ef6a6-fa91-4dcb-8b86-48efc87a906a__TUTS42-Episode-5-Don-t-Blink.mp4: Invalid data found when processing input

----------------------------------------------------------
https://www.behance.net/videos/cd6ad678-1dd9-4eed-95e9-3fa5abcfea27/Illustrated-Portrait-using-Photoshop-with-Klarens-Malluta.mp4
Traceback (most recent call last):
  File "/home/saransh03sharma/.local/lib/python3.10/site-packages/moviepy/video/io/ffmpeg_reader.py", line 285, in ffmpeg_parse_infos
    line = [l for l in lines if keyword in l][index]
IndexError: list index out of range

During handling of the above exception, another exception occurred:

Traceback (most recent call last):
  File "/home/saransh03sharma/Documents/GitHub/VideoIntentDiscovery/scripts/download_videos.py", line 49, in get_slices
    video = VideoFileClip(tmp_name)
  File "/home/saransh03sharma/.local/lib/python3.10/site-packages/moviepy/video/io/VideoFileClip.py", line 88, in __init__
    self.reader = FFMPEG_VideoReader(filename, pix_fmt=pix_fmt,
  File "/home/saransh03sharma/.local/lib/python3.10/site-packages/moviepy/video/io/ffmpeg_reader.py", line 35, in __init__
    infos = ffmpeg_parse_infos(filename, print_infos, check_duration,
  File "/home/saransh03sharma/.local/lib/python3.10/site-packages/moviepy/video/io/ffmpeg_reader.py", line 289, in ffmpeg_parse_infos
    raise IOError(("MoviePy error: failed to read the duration of file %s.\n"
OSError: MoviePy error: failed to read the duration of file ../data/bid/video/https:____www.behance.net__videos__cd6ad678-1dd9-4eed-95e9-3fa5abcfea27__Illustrated-Portrait-using-Photoshop-with-Klarens-Malluta.mp4.
Here are the file infos returned by ffmpeg:

ffmpeg version 4.2.2-static https://johnvansickle.com/ffmpeg/  Copyright (c) 2000-2019 the FFmpeg developers
  built with gcc 8 (Debian 8.3.0-6)
  configuration: --enable-gpl --enable-version3 --enable-static --disable-debug --disable-ffplay --disable-indev=sndio --disable-outdev=sndio --cc=gcc --enable-fontconfig --enable-frei0r --enable-gnutls --enable-gmp --enable-libgme --enable-gray --enable-libaom --enable-libfribidi --enable-libass --enable-libvmaf --enable-libfreetype --enable-libmp3lame --enable-libopencore-amrnb --enable-libopencore-amrwb --enable-libopenjpeg --enable-librubberband --enable-libsoxr --enable-libspeex --enable-libsrt --enable-libvorbis --enable-libopus --enable-libtheora --enable-libvidstab --enable-libvo-amrwbenc --enable-libvpx --enable-libwebp --enable-libx264 --enable-libx265 --enable-libxml2 --enable-libdav1d --enable-libxvid --enable-libzvbi --enable-libzimg
  libavutil      56. 31.100 / 56. 31.100
  libavcodec     58. 54.100 / 58. 54.100
  libavformat    58. 29.100 / 58. 29.100
  libavdevice    58.  8.100 / 58.  8.100
  libavfilter     7. 57.100 /  7. 57.100
  libswscale      5.  5.100 /  5.  5.100
  libswresample   3.  5.100 /  3.  5.100
  libpostproc    55.  5.100 / 55.  5.100
[mov,mp4,m4a,3gp,3g2,mj2 @ 0x6d84500] Format mov,mp4,m4a,3gp,3g2,mj2 detected only with low score of 1, misdetection possible!
[mov,mp4,m4a,3gp,3g2,mj2 @ 0x6d84500] moov atom not found
../data/bid/video/https:____www.behance.net__videos__cd6ad678-1dd9-4eed-95e9-3fa5abcfea27__Illustrated-Portrait-using-Photoshop-with-Klarens-Malluta.mp4: Invalid data found when processing input

----------------------------------------------------------
https://www.behance.net/videos/632fffaf-f8ae-4c75-bcaf-91ea4f8ddfb6/Daily-Projects-with-Klarens-Malluta.mp4
Traceback (most recent call last):
  File "/home/saransh03sharma/Documents/GitHub/VideoIntentDiscovery/scripts/download_videos.py", line 44, in get_slices
    urllib.request.urlretrieve(url, tmp_name, show_progress)
  File "/usr/lib/python3.10/urllib/request.py", line 267, in urlretrieve
    reporthook(blocknum, bs, size)
  File "/home/saransh03sharma/Documents/GitHub/VideoIntentDiscovery/scripts/download_videos.py", line 28, in show_progress
    pbar.start()
  File "/usr/lib/python3/dist-packages/progressbar/progressbar.py", line 286, in start
    if self.maxval < 0: raise ValueError('Value out of range')
ValueError: Value out of range
----------------------------------------------------------
https://www.behance.net/videos/b7f29dd7-7d9f-435f-8b3c-bcdb8e0202b9/Creature-Character-Concepts-with-2SL.mp4
Traceback (most recent call last):
  File "/home/saransh03sharma/Documents/GitHub/VideoIntentDiscovery/scripts/download_videos.py", line 44, in get_slices
    urllib.request.urlretrieve(url, tmp_name, show_progress)
  File "/usr/lib/python3.10/urllib/request.py", line 267, in urlretrieve
    reporthook(blocknum, bs, size)
  File "/home/saransh03sharma/Documents/GitHub/VideoIntentDiscovery/scripts/download_videos.py", line 34, in show_progress
    pbar.finish()
  File "/usr/lib/python3/dist-packages/progressbar/progressbar.py", line 302, in finish
    self.update(self.maxval)
  File "/usr/lib/python3/dist-packages/progressbar/progressbar.py", line 250, in update
    raise ValueError('Value out of range')
ValueError: Value out of range
----------------------------------------------------------
https://livestream-videos-prod.s3-us-west-2.amazonaws.com/stream-f4d1efd0-1890-4238-9d59-ecd41eb37a51-s3.mp4
Traceback (most recent call last):
  File "/home/saransh03sharma/Documents/GitHub/VideoIntentDiscovery/scripts/download_videos.py", line 44, in get_slices
    urllib.request.urlretrieve(url, tmp_name, show_progress)
  File "/usr/lib/python3.10/urllib/request.py", line 267, in urlretrieve
    reporthook(blocknum, bs, size)
  File "/home/saransh03sharma/Documents/GitHub/VideoIntentDiscovery/scripts/download_videos.py", line 32, in show_progress
    pbar.update(downloaded)
  File "/usr/lib/python3/dist-packages/progressbar/progressbar.py", line 250, in update
    raise ValueError('Value out of range')
ValueError: Value out of range
----------------------------------------------------------
https://www.behance.net/videos/b795c0b0-9820-4806-8365-c86630d45070/Creating-a-black-and-white-duo-portrait-commission-with-Suzanne-Helmigh.mp4
Traceback (most recent call last):
  File "/home/saransh03sharma/Documents/GitHub/VideoIntentDiscovery/scripts/download_videos.py", line 44, in get_slices
    urllib.request.urlretrieve(url, tmp_name, show_progress)
  File "/usr/lib/python3.10/urllib/request.py", line 251, in urlretrieve
    tfp = open(filename, 'wb')
FileNotFoundError: [Errno 2] No such file or directory: '../data/bid/video/https:____www.behance.net__videos__b795c0b0-9820-4806-8365-c86630d45070__Creating-a-black-and-white-duo-portrait-commission-with-Suzanne-Helmigh.mp4'
----------------------------------------------------------
https://www.behance.net/videos/419f9f5f-20d1-459e-954d-18da41d0bf7d/Rejected-Elves-Part-2.mp4
Traceback (most recent call last):
  File "/home/saransh03sharma/Documents/GitHub/VideoIntentDiscovery/scripts/download_videos.py", line 44, in get_slices
    urllib.request.urlretrieve(url, tmp_name, show_progress)
  File "/usr/lib/python3.10/urllib/request.py", line 251, in urlretrieve
    tfp = open(filename, 'wb')
FileNotFoundError: [Errno 2] No such file or directory: '../data/bid/video/https:____www.behance.net__videos__419f9f5f-20d1-459e-954d-18da41d0bf7d__Rejected-Elves-Part-2.mp4'
----------------------------------------------------------
https://www.behance.net/videos/f83ea5f3-dcc8-47c0-ab75-50b489538348/Autumn-Themed-Digital-Painting-Studies-with-Maddy-Bellwoar.mp4
Traceback (most recent call last):
  File "/home/saransh03sharma/Documents/GitHub/VideoIntentDiscovery/scripts/download_videos.py", line 44, in get_slices
    urllib.request.urlretrieve(url, tmp_name, show_progress)
  File "/usr/lib/python3.10/urllib/request.py", line 251, in urlretrieve
    tfp = open(filename, 'wb')
FileNotFoundError: [Errno 2] No such file or directory: '../data/bid/video/https:____www.behance.net__videos__f83ea5f3-dcc8-47c0-ab75-50b489538348__Autumn-Themed-Digital-Painting-Studies-with-Maddy-Bellwoar.mp4'
----------------------------------------------------------
https://www.behance.net/videos/37aec988-de9b-4bf9-941e-947c4b7406e2/Virtual-Plein-Air-Sketch-Studies-with-Maddy-Bellwoar.mp4
Traceback (most recent call last):
  File "/home/saransh03sharma/Documents/GitHub/VideoIntentDiscovery/scripts/download_videos.py", line 44, in get_slices
    urllib.request.urlretrieve(url, tmp_name, show_progress)
  File "/usr/lib/python3.10/urllib/request.py", line 251, in urlretrieve
    tfp = open(filename, 'wb')
FileNotFoundError: [Errno 2] No such file or directory: '../data/bid/video/https:____www.behance.net__videos__37aec988-de9b-4bf9-941e-947c4b7406e2__Virtual-Plein-Air-Sketch-Studies-with-Maddy-Bellwoar.mp4'
----------------------------------------------------------
https://www.behance.net/videos/8e1173b7-9e84-4f44-a849-243f2271bb2c/Thinking-Doodles-with-Rachel-Ashley-from-Fresco.mp4
Traceback (most recent call last):
  File "/home/saransh03sharma/Documents/GitHub/VideoIntentDiscovery/scripts/download_videos.py", line 44, in get_slices
    urllib.request.urlretrieve(url, tmp_name, show_progress)
  File "/usr/lib/python3.10/urllib/request.py", line 251, in urlretrieve
    tfp = open(filename, 'wb')
FileNotFoundError: [Errno 2] No such file or directory: '../data/bid/video/https:____www.behance.net__videos__8e1173b7-9e84-4f44-a849-243f2271bb2c__Thinking-Doodles-with-Rachel-Ashley-from-Fresco.mp4'
----------------------------------------------------------
https://livestream-videos-prod.s3-us-west-2.amazonaws.com/stream-563baf94-84dd-47b2-84f6-4971634cda32-s3.mp4
Traceback (most recent call last):
  File "/home/saransh03sharma/Documents/GitHub/VideoIntentDiscovery/scripts/download_videos.py", line 44, in get_slices
    urllib.request.urlretrieve(url, tmp_name, show_progress)
  File "/usr/lib/python3.10/urllib/request.py", line 251, in urlretrieve
    tfp = open(filename, 'wb')
FileNotFoundError: [Errno 2] No such file or directory: '../data/bid/video/https:____livestream-videos-prod.s3-us-west-2.amazonaws.com__stream-563baf94-84dd-47b2-84f6-4971634cda32-s3.mp4'
----------------------------------------------------------
https://livestream-videos-prod.s3-us-west-2.amazonaws.com/stream-48b982ef-351f-4125-8811-6f26dae0bd3e-s3.mp4
Traceback (most recent call last):
  File "/home/saransh03sharma/Documents/GitHub/VideoIntentDiscovery/scripts/download_videos.py", line 44, in get_slices
    urllib.request.urlretrieve(url, tmp_name, show_progress)
  File "/usr/lib/python3.10/urllib/request.py", line 251, in urlretrieve
    tfp = open(filename, 'wb')
FileNotFoundError: [Errno 2] No such file or directory: '../data/bid/video/https:____livestream-videos-prod.s3-us-west-2.amazonaws.com__stream-48b982ef-351f-4125-8811-6f26dae0bd3e-s3.mp4'
----------------------------------------------------------
https://livestream-videos-prod.s3-us-west-2.amazonaws.com/stream-dcf30094-8aad-468b-9609-4a0235a144b6-s3.mp4
Traceback (most recent call last):
  File "/home/saransh03sharma/Documents/GitHub/VideoIntentDiscovery/scripts/download_videos.py", line 44, in get_slices
    urllib.request.urlretrieve(url, tmp_name, show_progress)
  File "/usr/lib/python3.10/urllib/request.py", line 251, in urlretrieve
    tfp = open(filename, 'wb')
FileNotFoundError: [Errno 2] No such file or directory: '../data/bid/video/https:____livestream-videos-prod.s3-us-west-2.amazonaws.com__stream-dcf30094-8aad-468b-9609-4a0235a144b6-s3.mp4'
----------------------------------------------------------
https://livestream-videos-prod.s3-us-west-2.amazonaws.com/stream-88c271d9-2faa-4dbb-9fd9-e49509682682-s3.mp4
Traceback (most recent call last):
  File "/home/saransh03sharma/Documents/GitHub/VideoIntentDiscovery/scripts/download_videos.py", line 44, in get_slices
    urllib.request.urlretrieve(url, tmp_name, show_progress)
  File "/usr/lib/python3.10/urllib/request.py", line 251, in urlretrieve
    tfp = open(filename, 'wb')
FileNotFoundError: [Errno 2] No such file or directory: '../data/bid/video/https:____livestream-videos-prod.s3-us-west-2.amazonaws.com__stream-88c271d9-2faa-4dbb-9fd9-e49509682682-s3.mp4'
----------------------------------------------------------
https://livestream-videos-prod.s3-us-west-2.amazonaws.com/stream-4e565236-cdf2-4d2f-907d-70ff3cf447ba-s3.mp4
Traceback (most recent call last):
  File "/home/saransh03sharma/Documents/GitHub/VideoIntentDiscovery/scripts/download_videos.py", line 44, in get_slices
    urllib.request.urlretrieve(url, tmp_name, show_progress)
  File "/usr/lib/python3.10/urllib/request.py", line 251, in urlretrieve
    tfp = open(filename, 'wb')
FileNotFoundError: [Errno 2] No such file or directory: '../data/bid/video/https:____livestream-videos-prod.s3-us-west-2.amazonaws.com__stream-4e565236-cdf2-4d2f-907d-70ff3cf447ba-s3.mp4'
----------------------------------------------------------
https://www.behance.net/videos/c147bd15-2e4a-4205-9bb3-25133826df6a/Shilin-chipping-away-a-painting.mp4
Traceback (most recent call last):
  File "/home/saransh03sharma/Documents/GitHub/VideoIntentDiscovery/scripts/download_videos.py", line 44, in get_slices
    urllib.request.urlretrieve(url, tmp_name, show_progress)
  File "/usr/lib/python3.10/urllib/request.py", line 251, in urlretrieve
    tfp = open(filename, 'wb')
FileNotFoundError: [Errno 2] No such file or directory: '../data/bid/video/https:____www.behance.net__videos__c147bd15-2e4a-4205-9bb3-25133826df6a__Shilin-chipping-away-a-painting.mp4'
----------------------------------------------------------
https://www.behance.net/videos/632fffaf-f8ae-4c75-bcaf-91ea4f8ddfb6/Daily-Projects-with-Klarens-Malluta.mp4
Traceback (most recent call last):
  File "/home/saransh03sharma/Documents/GitHub/VideoIntentDiscovery/scripts/download_videos.py", line 44, in get_slices
    urllib.request.urlretrieve(url, tmp_name, show_progress)
  File "/usr/lib/python3.10/urllib/request.py", line 251, in urlretrieve
    tfp = open(filename, 'wb')
FileNotFoundError: [Errno 2] No such file or directory: '../data/bid/video/https:____www.behance.net__videos__632fffaf-f8ae-4c75-bcaf-91ea4f8ddfb6__Daily-Projects-with-Klarens-Malluta.mp4'
----------------------------------------------------------
https://www.behance.net/videos/b7f29dd7-7d9f-435f-8b3c-bcdb8e0202b9/Creature-Character-Concepts-with-2SL.mp4
Traceback (most recent call last):
  File "/home/saransh03sharma/Documents/GitHub/VideoIntentDiscovery/scripts/download_videos.py", line 44, in get_slices
    urllib.request.urlretrieve(url, tmp_name, show_progress)
  File "/usr/lib/python3.10/urllib/request.py", line 251, in urlretrieve
    tfp = open(filename, 'wb')
FileNotFoundError: [Errno 2] No such file or directory: '../data/bid/video/https:____www.behance.net__videos__b7f29dd7-7d9f-435f-8b3c-bcdb8e0202b9__Creature-Character-Concepts-with-2SL.mp4'
----------------------------------------------------------
https://livestream-videos-prod.s3-us-west-2.amazonaws.com/stream-29694c13-e260-49fd-a91f-d349e770ac4d-s3.mp4
Traceback (most recent call last):
  File "/home/saransh03sharma/Documents/GitHub/VideoIntentDiscovery/scripts/download_videos.py", line 44, in get_slices
    urllib.request.urlretrieve(url, tmp_name, show_progress)
  File "/usr/lib/python3.10/urllib/request.py", line 251, in urlretrieve
    tfp = open(filename, 'wb')
FileNotFoundError: [Errno 2] No such file or directory: '../data/bid/video/https:____livestream-videos-prod.s3-us-west-2.amazonaws.com__stream-29694c13-e260-49fd-a91f-d349e770ac4d-s3.mp4'
----------------------------------------------------------
https://livestream-videos-prod.s3-us-west-2.amazonaws.com/stream-7dd6dc31-bbe9-45bc-a215-fc1dbc91af90-s3.mp4
Traceback (most recent call last):
  File "/home/saransh03sharma/Documents/GitHub/VideoIntentDiscovery/scripts/download_videos.py", line 44, in get_slices
    urllib.request.urlretrieve(url, tmp_name, show_progress)
  File "/usr/lib/python3.10/urllib/request.py", line 251, in urlretrieve
    tfp = open(filename, 'wb')
FileNotFoundError: [Errno 2] No such file or directory: '../data/bid/video/https:____livestream-videos-prod.s3-us-west-2.amazonaws.com__stream-7dd6dc31-bbe9-45bc-a215-fc1dbc91af90-s3.mp4'
----------------------------------------------------------
https://livestream-videos-prod.s3-us-west-2.amazonaws.com/stream-205eda67-0a6d-473e-9cc6-74012ac530e4-s3.mp4
Traceback (most recent call last):
  File "/home/saransh03sharma/Documents/GitHub/VideoIntentDiscovery/scripts/download_videos.py", line 44, in get_slices
    urllib.request.urlretrieve(url, tmp_name, show_progress)
  File "/usr/lib/python3.10/urllib/request.py", line 251, in urlretrieve
    tfp = open(filename, 'wb')
FileNotFoundError: [Errno 2] No such file or directory: '../data/bid/video/https:____livestream-videos-prod.s3-us-west-2.amazonaws.com__stream-205eda67-0a6d-473e-9cc6-74012ac530e4-s3.mp4'
----------------------------------------------------------
https://www.behance.net/videos/72c4b6f2-605d-4d3b-abfe-acbffbc0242a/Sketching-Tennis-Players-from-Imagination.mp4
Traceback (most recent call last):
  File "/home/saransh03sharma/Documents/GitHub/VideoIntentDiscovery/scripts/download_videos.py", line 44, in get_slices
    urllib.request.urlretrieve(url, tmp_name, show_progress)
  File "/usr/lib/python3.10/urllib/request.py", line 251, in urlretrieve
    tfp = open(filename, 'wb')
FileNotFoundError: [Errno 2] No such file or directory: '../data/bid/video/https:____www.behance.net__videos__72c4b6f2-605d-4d3b-abfe-acbffbc0242a__Sketching-Tennis-Players-from-Imagination.mp4'
----------------------------------------------------------
https://livestream-videos-prod.s3-us-west-2.amazonaws.com/stream-884d73ac-4c75-44ef-a3be-d500c47f7482-s3.mp4
Traceback (most recent call last):
  File "/home/saransh03sharma/Documents/GitHub/VideoIntentDiscovery/scripts/download_videos.py", line 44, in get_slices
    urllib.request.urlretrieve(url, tmp_name, show_progress)
  File "/usr/lib/python3.10/urllib/request.py", line 251, in urlretrieve
    tfp = open(filename, 'wb')
FileNotFoundError: [Errno 2] No such file or directory: '../data/bid/video/https:____livestream-videos-prod.s3-us-west-2.amazonaws.com__stream-884d73ac-4c75-44ef-a3be-d500c47f7482-s3.mp4'
----------------------------------------------------------
https://livestream-videos-prod.s3-us-west-2.amazonaws.com/stream-d05f8a7c-8192-4b3d-b182-dc697dc8c900-s3.mp4
Traceback (most recent call last):
  File "/home/saransh03sharma/Documents/GitHub/VideoIntentDiscovery/scripts/download_videos.py", line 44, in get_slices
    urllib.request.urlretrieve(url, tmp_name, show_progress)
  File "/usr/lib/python3.10/urllib/request.py", line 251, in urlretrieve
    tfp = open(filename, 'wb')
FileNotFoundError: [Errno 2] No such file or directory: '../data/bid/video/https:____livestream-videos-prod.s3-us-west-2.amazonaws.com__stream-d05f8a7c-8192-4b3d-b182-dc697dc8c900-s3.mp4'
----------------------------------------------------------
https://www.behance.net/videos/cd6ad678-1dd9-4eed-95e9-3fa5abcfea27/Illustrated-Portrait-using-Photoshop-with-Klarens-Malluta.mp4
Traceback (most recent call last):
  File "/home/saransh03sharma/Documents/GitHub/VideoIntentDiscovery/scripts/download_videos.py", line 44, in get_slices
    urllib.request.urlretrieve(url, tmp_name, show_progress)
  File "/usr/lib/python3.10/urllib/request.py", line 251, in urlretrieve
    tfp = open(filename, 'wb')
FileNotFoundError: [Errno 2] No such file or directory: '../data/bid/video/https:____www.behance.net__videos__cd6ad678-1dd9-4eed-95e9-3fa5abcfea27__Illustrated-Portrait-using-Photoshop-with-Klarens-Malluta.mp4'
----------------------------------------------------------
https://livestream-videos-prod.s3-us-west-2.amazonaws.com/stream-3c749cb5-cf8a-4606-9fa5-794f9218654c-s3.mp4
Traceback (most recent call last):
  File "/home/saransh03sharma/Documents/GitHub/VideoIntentDiscovery/scripts/download_videos.py", line 44, in get_slices
    urllib.request.urlretrieve(url, tmp_name, show_progress)
  File "/usr/lib/python3.10/urllib/request.py", line 251, in urlretrieve
    tfp = open(filename, 'wb')
FileNotFoundError: [Errno 2] No such file or directory: '../data/bid/video/https:____livestream-videos-prod.s3-us-west-2.amazonaws.com__stream-3c749cb5-cf8a-4606-9fa5-794f9218654c-s3.mp4'
----------------------------------------------------------
https://livestream-videos-prod.s3-us-west-2.amazonaws.com/stream-a63533e0-6413-4f51-9841-6bee342141b1-s3.mp4
Traceback (most recent call last):
  File "/home/saransh03sharma/Documents/GitHub/VideoIntentDiscovery/scripts/download_videos.py", line 44, in get_slices
    urllib.request.urlretrieve(url, tmp_name, show_progress)
  File "/usr/lib/python3.10/urllib/request.py", line 251, in urlretrieve
    tfp = open(filename, 'wb')
FileNotFoundError: [Errno 2] No such file or directory: '../data/bid/video/https:____livestream-videos-prod.s3-us-west-2.amazonaws.com__stream-a63533e0-6413-4f51-9841-6bee342141b1-s3.mp4'
----------------------------------------------------------
https://livestream-videos-prod.s3-us-west-2.amazonaws.com/stream-f4d1efd0-1890-4238-9d59-ecd41eb37a51-s3.mp4
Traceback (most recent call last):
  File "/home/saransh03sharma/Documents/GitHub/VideoIntentDiscovery/scripts/download_videos.py", line 44, in get_slices
    urllib.request.urlretrieve(url, tmp_name, show_progress)
  File "/usr/lib/python3.10/urllib/request.py", line 251, in urlretrieve
    tfp = open(filename, 'wb')
FileNotFoundError: [Errno 2] No such file or directory: '../data/bid/video/https:____livestream-videos-prod.s3-us-west-2.amazonaws.com__stream-f4d1efd0-1890-4238-9d59-ecd41eb37a51-s3.mp4'
----------------------------------------------------------
https://livestream-videos-prod.s3-us-west-2.amazonaws.com/stream-2ef3cbfe-4ecb-425f-903e-427fb9844dee-s3.mp4
Traceback (most recent call last):
  File "/home/saransh03sharma/Documents/GitHub/VideoIntentDiscovery/scripts/download_videos.py", line 44, in get_slices
    urllib.request.urlretrieve(url, tmp_name, show_progress)
  File "/usr/lib/python3.10/urllib/request.py", line 251, in urlretrieve
    tfp = open(filename, 'wb')
FileNotFoundError: [Errno 2] No such file or directory: '../data/bid/video/https:____livestream-videos-prod.s3-us-west-2.amazonaws.com__stream-2ef3cbfe-4ecb-425f-903e-427fb9844dee-s3.mp4'
----------------------------------------------------------
https://livestream-videos-prod.s3-us-west-2.amazonaws.com/stream-399896c6-5508-4e79-b686-36a839d43cc7-s3.mp4
Traceback (most recent call last):
  File "/home/saransh03sharma/Documents/GitHub/VideoIntentDiscovery/scripts/download_videos.py", line 44, in get_slices
    urllib.request.urlretrieve(url, tmp_name, show_progress)
  File "/usr/lib/python3.10/urllib/request.py", line 251, in urlretrieve
    tfp = open(filename, 'wb')
FileNotFoundError: [Errno 2] No such file or directory: '../data/bid/video/https:____livestream-videos-prod.s3-us-west-2.amazonaws.com__stream-399896c6-5508-4e79-b686-36a839d43cc7-s3.mp4'
----------------------------------------------------------
https://livestream-videos-prod.s3-us-west-2.amazonaws.com/stream-c0902cc5-e96a-4221-9f52-39fc87062c98-s3.mp4
Traceback (most recent call last):
  File "/home/saransh03sharma/Documents/GitHub/VideoIntentDiscovery/scripts/download_videos.py", line 44, in get_slices
    urllib.request.urlretrieve(url, tmp_name, show_progress)
  File "/usr/lib/python3.10/urllib/request.py", line 251, in urlretrieve
    tfp = open(filename, 'wb')
FileNotFoundError: [Errno 2] No such file or directory: '../data/bid/video/https:____livestream-videos-prod.s3-us-west-2.amazonaws.com__stream-c0902cc5-e96a-4221-9f52-39fc87062c98-s3.mp4'
----------------------------------------------------------
https://livestream-videos-prod.s3-us-west-2.amazonaws.com/stream-023bdbeb-9c95-4d03-a38e-c07002579b2a-s3.mp4
Traceback (most recent call last):
  File "/home/saransh03sharma/Documents/GitHub/VideoIntentDiscovery/scripts/download_videos.py", line 44, in get_slices
    urllib.request.urlretrieve(url, tmp_name, show_progress)
  File "/usr/lib/python3.10/urllib/request.py", line 251, in urlretrieve
    tfp = open(filename, 'wb')
FileNotFoundError: [Errno 2] No such file or directory: '../data/bid/video/https:____livestream-videos-prod.s3-us-west-2.amazonaws.com__stream-023bdbeb-9c95-4d03-a38e-c07002579b2a-s3.mp4'
----------------------------------------------------------
https://livestream-videos-prod.s3-us-west-2.amazonaws.com/stream-e191c578-475d-4d7c-8693-a214544f5bba-s3.mp4
Traceback (most recent call last):
  File "/home/saransh03sharma/Documents/GitHub/VideoIntentDiscovery/scripts/download_videos.py", line 44, in get_slices
    urllib.request.urlretrieve(url, tmp_name, show_progress)
  File "/usr/lib/python3.10/urllib/request.py", line 251, in urlretrieve
    tfp = open(filename, 'wb')
FileNotFoundError: [Errno 2] No such file or directory: '../data/bid/video/https:____livestream-videos-prod.s3-us-west-2.amazonaws.com__stream-e191c578-475d-4d7c-8693-a214544f5bba-s3.mp4'
----------------------------------------------------------
https://livestream-videos-prod.s3-us-west-2.amazonaws.com/stream-632d2535-01b2-49a8-bfb8-c9895e8f6124-s3.mp4
Traceback (most recent call last):
  File "/home/saransh03sharma/Documents/GitHub/VideoIntentDiscovery/scripts/download_videos.py", line 44, in get_slices
    urllib.request.urlretrieve(url, tmp_name, show_progress)
  File "/usr/lib/python3.10/urllib/request.py", line 251, in urlretrieve
    tfp = open(filename, 'wb')
FileNotFoundError: [Errno 2] No such file or directory: '../data/bid/video/https:____livestream-videos-prod.s3-us-west-2.amazonaws.com__stream-632d2535-01b2-49a8-bfb8-c9895e8f6124-s3.mp4'
----------------------------------------------------------
https://livestream-videos-prod.s3-us-west-2.amazonaws.com/stream-3d06e524-13a2-45ae-95d8-993113826c77-s3.mp4
Traceback (most recent call last):
  File "/home/saransh03sharma/Documents/GitHub/VideoIntentDiscovery/scripts/download_videos.py", line 44, in get_slices
    urllib.request.urlretrieve(url, tmp_name, show_progress)
  File "/usr/lib/python3.10/urllib/request.py", line 251, in urlretrieve
    tfp = open(filename, 'wb')
FileNotFoundError: [Errno 2] No such file or directory: '../data/bid/video/https:____livestream-videos-prod.s3-us-west-2.amazonaws.com__stream-3d06e524-13a2-45ae-95d8-993113826c77-s3.mp4'
----------------------------------------------------------
https://www.behance.net/videos/7e9ff601-cbf5-4fdf-be0f-1685186b5ff3/Frame-by-Frame-Animation-in-Photoshop-with-Klarens-Malluta.mp4
Traceback (most recent call last):
  File "/home/saransh03sharma/Documents/GitHub/VideoIntentDiscovery/scripts/download_videos.py", line 44, in get_slices
    urllib.request.urlretrieve(url, tmp_name, show_progress)
  File "/usr/lib/python3.10/urllib/request.py", line 251, in urlretrieve
    tfp = open(filename, 'wb')
FileNotFoundError: [Errno 2] No such file or directory: '../data/bid/video/https:____www.behance.net__videos__7e9ff601-cbf5-4fdf-be0f-1685186b5ff3__Frame-by-Frame-Animation-in-Photoshop-with-Klarens-Malluta.mp4'
----------------------------------------------------------
https://www.behance.net/videos/d91ef6a6-fa91-4dcb-8b86-48efc87a906a/TUTS42-Episode-5-Don-t-Blink.mp4
Traceback (most recent call last):
  File "/home/saransh03sharma/Documents/GitHub/VideoIntentDiscovery/scripts/download_videos.py", line 44, in get_slices
    urllib.request.urlretrieve(url, tmp_name, show_progress)
  File "/usr/lib/python3.10/urllib/request.py", line 251, in urlretrieve
    tfp = open(filename, 'wb')
FileNotFoundError: [Errno 2] No such file or directory: '../data/bid/video/https:____www.behance.net__videos__d91ef6a6-fa91-4dcb-8b86-48efc87a906a__TUTS42-Episode-5-Don-t-Blink.mp4'
----------------------------------------------------------
https://livestream-videos-prod.s3-us-west-2.amazonaws.com/stream-14049d9f-b2e0-4a31-9ad2-d140cb843d26-s3.mp4
Traceback (most recent call last):
  File "/home/saransh03sharma/Documents/GitHub/VideoIntentDiscovery/scripts/download_videos.py", line 44, in get_slices
    urllib.request.urlretrieve(url, tmp_name, show_progress)
  File "/usr/lib/python3.10/urllib/request.py", line 251, in urlretrieve
    tfp = open(filename, 'wb')
FileNotFoundError: [Errno 2] No such file or directory: '../data/bid/video/https:____livestream-videos-prod.s3-us-west-2.amazonaws.com__stream-14049d9f-b2e0-4a31-9ad2-d140cb843d26-s3.mp4'
----------------------------------------------------------
https://livestream-videos-prod.s3-us-west-2.amazonaws.com/stream-dd2ba85f-1c83-416d-9188-35c4b197cc66-s3.mp4
Traceback (most recent call last):
  File "/home/saransh03sharma/Documents/GitHub/VideoIntentDiscovery/scripts/download_videos.py", line 44, in get_slices
    urllib.request.urlretrieve(url, tmp_name, show_progress)
  File "/usr/lib/python3.10/urllib/request.py", line 251, in urlretrieve
    tfp = open(filename, 'wb')
FileNotFoundError: [Errno 2] No such file or directory: '../data/bid/video/https:____livestream-videos-prod.s3-us-west-2.amazonaws.com__stream-dd2ba85f-1c83-416d-9188-35c4b197cc66-s3.mp4'
----------------------------------------------------------
https://livestream-videos-prod.s3-us-west-2.amazonaws.com/stream-946940c7-6d6d-4140-a1f6-28a8ed7737dd-s3.mp4
Traceback (most recent call last):
  File "/home/saransh03sharma/Documents/GitHub/VideoIntentDiscovery/scripts/download_videos.py", line 44, in get_slices
    urllib.request.urlretrieve(url, tmp_name, show_progress)
  File "/usr/lib/python3.10/urllib/request.py", line 251, in urlretrieve
    tfp = open(filename, 'wb')
FileNotFoundError: [Errno 2] No such file or directory: '../data/bid/video/https:____livestream-videos-prod.s3-us-west-2.amazonaws.com__stream-946940c7-6d6d-4140-a1f6-28a8ed7737dd-s3.mp4'
----------------------------------------------------------
https://www.behance.net/videos/419f9f5f-20d1-459e-954d-18da41d0bf7d/Rejected-Elves-Part-2.mp4
Traceback (most recent call last):
  File "/home/saransh03sharma/.local/lib/python3.10/site-packages/moviepy/video/io/ffmpeg_reader.py", line 285, in ffmpeg_parse_infos
    line = [l for l in lines if keyword in l][index]
IndexError: list index out of range

During handling of the above exception, another exception occurred:

Traceback (most recent call last):
  File "/home/saransh03sharma/Documents/GitHub/VideoIntentDiscovery/scripts/download_videos.py", line 49, in get_slices
    video = VideoFileClip(tmp_name)
  File "/home/saransh03sharma/.local/lib/python3.10/site-packages/moviepy/video/io/VideoFileClip.py", line 88, in __init__
    self.reader = FFMPEG_VideoReader(filename, pix_fmt=pix_fmt,
  File "/home/saransh03sharma/.local/lib/python3.10/site-packages/moviepy/video/io/ffmpeg_reader.py", line 35, in __init__
    infos = ffmpeg_parse_infos(filename, print_infos, check_duration,
  File "/home/saransh03sharma/.local/lib/python3.10/site-packages/moviepy/video/io/ffmpeg_reader.py", line 289, in ffmpeg_parse_infos
    raise IOError(("MoviePy error: failed to read the duration of file %s.\n"
OSError: MoviePy error: failed to read the duration of file ../data/bid/video/https:____www.behance.net__videos__419f9f5f-20d1-459e-954d-18da41d0bf7d__Rejected-Elves-Part-2.mp4.
Here are the file infos returned by ffmpeg:

ffmpeg version 4.2.2-static https://johnvansickle.com/ffmpeg/  Copyright (c) 2000-2019 the FFmpeg developers
  built with gcc 8 (Debian 8.3.0-6)
  configuration: --enable-gpl --enable-version3 --enable-static --disable-debug --disable-ffplay --disable-indev=sndio --disable-outdev=sndio --cc=gcc --enable-fontconfig --enable-frei0r --enable-gnutls --enable-gmp --enable-libgme --enable-gray --enable-libaom --enable-libfribidi --enable-libass --enable-libvmaf --enable-libfreetype --enable-libmp3lame --enable-libopencore-amrnb --enable-libopencore-amrwb --enable-libopenjpeg --enable-librubberband --enable-libsoxr --enable-libspeex --enable-libsrt --enable-libvorbis --enable-libopus --enable-libtheora --enable-libvidstab --enable-libvo-amrwbenc --enable-libvpx --enable-libwebp --enable-libx264 --enable-libx265 --enable-libxml2 --enable-libdav1d --enable-libxvid --enable-libzvbi --enable-libzimg
  libavutil      56. 31.100 / 56. 31.100
  libavcodec     58. 54.100 / 58. 54.100
  libavformat    58. 29.100 / 58. 29.100
  libavdevice    58.  8.100 / 58.  8.100
  libavfilter     7. 57.100 /  7. 57.100
  libswscale      5.  5.100 /  5.  5.100
  libswresample   3.  5.100 /  3.  5.100
  libpostproc    55.  5.100 / 55.  5.100
[mov,mp4,m4a,3gp,3g2,mj2 @ 0x6872500] Format mov,mp4,m4a,3gp,3g2,mj2 detected only with low score of 1, misdetection possible!
[mov,mp4,m4a,3gp,3g2,mj2 @ 0x6872500] moov atom not found
../data/bid/video/https:____www.behance.net__videos__419f9f5f-20d1-459e-954d-18da41d0bf7d__Rejected-Elves-Part-2.mp4: Invalid data found when processing input

----------------------------------------------------------
https://www.behance.net/videos/f83ea5f3-dcc8-47c0-ab75-50b489538348/Autumn-Themed-Digital-Painting-Studies-with-Maddy-Bellwoar.mp4
Traceback (most recent call last):
  File "/home/saransh03sharma/.local/lib/python3.10/site-packages/moviepy/video/io/ffmpeg_reader.py", line 285, in ffmpeg_parse_infos
    line = [l for l in lines if keyword in l][index]
IndexError: list index out of range

During handling of the above exception, another exception occurred:

Traceback (most recent call last):
  File "/home/saransh03sharma/Documents/GitHub/VideoIntentDiscovery/scripts/download_videos.py", line 49, in get_slices
    video = VideoFileClip(tmp_name)
  File "/home/saransh03sharma/.local/lib/python3.10/site-packages/moviepy/video/io/VideoFileClip.py", line 88, in __init__
    self.reader = FFMPEG_VideoReader(filename, pix_fmt=pix_fmt,
  File "/home/saransh03sharma/.local/lib/python3.10/site-packages/moviepy/video/io/ffmpeg_reader.py", line 35, in __init__
    infos = ffmpeg_parse_infos(filename, print_infos, check_duration,
  File "/home/saransh03sharma/.local/lib/python3.10/site-packages/moviepy/video/io/ffmpeg_reader.py", line 289, in ffmpeg_parse_infos
    raise IOError(("MoviePy error: failed to read the duration of file %s.\n"
OSError: MoviePy error: failed to read the duration of file ../data/bid/video/https:____www.behance.net__videos__f83ea5f3-dcc8-47c0-ab75-50b489538348__Autumn-Themed-Digital-Painting-Studies-with-Maddy-Bellwoar.mp4.
Here are the file infos returned by ffmpeg:

ffmpeg version 4.2.2-static https://johnvansickle.com/ffmpeg/  Copyright (c) 2000-2019 the FFmpeg developers
  built with gcc 8 (Debian 8.3.0-6)
  configuration: --enable-gpl --enable-version3 --enable-static --disable-debug --disable-ffplay --disable-indev=sndio --disable-outdev=sndio --cc=gcc --enable-fontconfig --enable-frei0r --enable-gnutls --enable-gmp --enable-libgme --enable-gray --enable-libaom --enable-libfribidi --enable-libass --enable-libvmaf --enable-libfreetype --enable-libmp3lame --enable-libopencore-amrnb --enable-libopencore-amrwb --enable-libopenjpeg --enable-librubberband --enable-libsoxr --enable-libspeex --enable-libsrt --enable-libvorbis --enable-libopus --enable-libtheora --enable-libvidstab --enable-libvo-amrwbenc --enable-libvpx --enable-libwebp --enable-libx264 --enable-libx265 --enable-libxml2 --enable-libdav1d --enable-libxvid --enable-libzvbi --enable-libzimg
  libavutil      56. 31.100 / 56. 31.100
  libavcodec     58. 54.100 / 58. 54.100
  libavformat    58. 29.100 / 58. 29.100
  libavdevice    58.  8.100 / 58.  8.100
  libavfilter     7. 57.100 /  7. 57.100
  libswscale      5.  5.100 /  5.  5.100
  libswresample   3.  5.100 /  3.  5.100
  libpostproc    55.  5.100 / 55.  5.100
[mov,mp4,m4a,3gp,3g2,mj2 @ 0x5d09500] Format mov,mp4,m4a,3gp,3g2,mj2 detected only with low score of 1, misdetection possible!
[mov,mp4,m4a,3gp,3g2,mj2 @ 0x5d09500] moov atom not found
../data/bid/video/https:____www.behance.net__videos__f83ea5f3-dcc8-47c0-ab75-50b489538348__Autumn-Themed-Digital-Painting-Studies-with-Maddy-Bellwoar.mp4: Invalid data found when processing input

----------------------------------------------------------
https://www.behance.net/videos/b795c0b0-9820-4806-8365-c86630d45070/Creating-a-black-and-white-duo-portrait-commission-with-Suzanne-Helmigh.mp4
Traceback (most recent call last):
  File "/home/saransh03sharma/.local/lib/python3.10/site-packages/moviepy/video/io/ffmpeg_reader.py", line 285, in ffmpeg_parse_infos
    line = [l for l in lines if keyword in l][index]
IndexError: list index out of range

During handling of the above exception, another exception occurred:

Traceback (most recent call last):
  File "/home/saransh03sharma/Documents/GitHub/VideoIntentDiscovery/scripts/download_videos.py", line 49, in get_slices
    video = VideoFileClip(tmp_name)
  File "/home/saransh03sharma/.local/lib/python3.10/site-packages/moviepy/video/io/VideoFileClip.py", line 88, in __init__
    self.reader = FFMPEG_VideoReader(filename, pix_fmt=pix_fmt,
  File "/home/saransh03sharma/.local/lib/python3.10/site-packages/moviepy/video/io/ffmpeg_reader.py", line 35, in __init__
    infos = ffmpeg_parse_infos(filename, print_infos, check_duration,
  File "/home/saransh03sharma/.local/lib/python3.10/site-packages/moviepy/video/io/ffmpeg_reader.py", line 289, in ffmpeg_parse_infos
    raise IOError(("MoviePy error: failed to read the duration of file %s.\n"
OSError: MoviePy error: failed to read the duration of file ../data/bid/video/https:____www.behance.net__videos__b795c0b0-9820-4806-8365-c86630d45070__Creating-a-black-and-white-duo-portrait-commission-with-Suzanne-Helmigh.mp4.
Here are the file infos returned by ffmpeg:

ffmpeg version 4.2.2-static https://johnvansickle.com/ffmpeg/  Copyright (c) 2000-2019 the FFmpeg developers
  built with gcc 8 (Debian 8.3.0-6)
  configuration: --enable-gpl --enable-version3 --enable-static --disable-debug --disable-ffplay --disable-indev=sndio --disable-outdev=sndio --cc=gcc --enable-fontconfig --enable-frei0r --enable-gnutls --enable-gmp --enable-libgme --enable-gray --enable-libaom --enable-libfribidi --enable-libass --enable-libvmaf --enable-libfreetype --enable-libmp3lame --enable-libopencore-amrnb --enable-libopencore-amrwb --enable-libopenjpeg --enable-librubberband --enable-libsoxr --enable-libspeex --enable-libsrt --enable-libvorbis --enable-libopus --enable-libtheora --enable-libvidstab --enable-libvo-amrwbenc --enable-libvpx --enable-libwebp --enable-libx264 --enable-libx265 --enable-libxml2 --enable-libdav1d --enable-libxvid --enable-libzvbi --enable-libzimg
  libavutil      56. 31.100 / 56. 31.100
  libavcodec     58. 54.100 / 58. 54.100
  libavformat    58. 29.100 / 58. 29.100
  libavdevice    58.  8.100 / 58.  8.100
  libavfilter     7. 57.100 /  7. 57.100
  libswscale      5.  5.100 /  5.  5.100
  libswresample   3.  5.100 /  3.  5.100
  libpostproc    55.  5.100 / 55.  5.100
[mov,mp4,m4a,3gp,3g2,mj2 @ 0x6d8b500] Format mov,mp4,m4a,3gp,3g2,mj2 detected only with low score of 1, misdetection possible!
[mov,mp4,m4a,3gp,3g2,mj2 @ 0x6d8b500] moov atom not found
../data/bid/video/https:____www.behance.net__videos__b795c0b0-9820-4806-8365-c86630d45070__Creating-a-black-and-white-duo-portrait-commission-with-Suzanne-Helmigh.mp4: Invalid data found when processing input

----------------------------------------------------------
https://www.behance.net/videos/8e1173b7-9e84-4f44-a849-243f2271bb2c/Thinking-Doodles-with-Rachel-Ashley-from-Fresco.mp4
Traceback (most recent call last):
  File "/home/saransh03sharma/.local/lib/python3.10/site-packages/moviepy/video/io/ffmpeg_reader.py", line 285, in ffmpeg_parse_infos
    line = [l for l in lines if keyword in l][index]
IndexError: list index out of range

During handling of the above exception, another exception occurred:

Traceback (most recent call last):
  File "/home/saransh03sharma/Documents/GitHub/VideoIntentDiscovery/scripts/download_videos.py", line 49, in get_slices
    video = VideoFileClip(tmp_name)
  File "/home/saransh03sharma/.local/lib/python3.10/site-packages/moviepy/video/io/VideoFileClip.py", line 88, in __init__
    self.reader = FFMPEG_VideoReader(filename, pix_fmt=pix_fmt,
  File "/home/saransh03sharma/.local/lib/python3.10/site-packages/moviepy/video/io/ffmpeg_reader.py", line 35, in __init__
    infos = ffmpeg_parse_infos(filename, print_infos, check_duration,
  File "/home/saransh03sharma/.local/lib/python3.10/site-packages/moviepy/video/io/ffmpeg_reader.py", line 289, in ffmpeg_parse_infos
    raise IOError(("MoviePy error: failed to read the duration of file %s.\n"
OSError: MoviePy error: failed to read the duration of file ../data/bid/video/https:____www.behance.net__videos__8e1173b7-9e84-4f44-a849-243f2271bb2c__Thinking-Doodles-with-Rachel-Ashley-from-Fresco.mp4.
Here are the file infos returned by ffmpeg:

ffmpeg version 4.2.2-static https://johnvansickle.com/ffmpeg/  Copyright (c) 2000-2019 the FFmpeg developers
  built with gcc 8 (Debian 8.3.0-6)
  configuration: --enable-gpl --enable-version3 --enable-static --disable-debug --disable-ffplay --disable-indev=sndio --disable-outdev=sndio --cc=gcc --enable-fontconfig --enable-frei0r --enable-gnutls --enable-gmp --enable-libgme --enable-gray --enable-libaom --enable-libfribidi --enable-libass --enable-libvmaf --enable-libfreetype --enable-libmp3lame --enable-libopencore-amrnb --enable-libopencore-amrwb --enable-libopenjpeg --enable-librubberband --enable-libsoxr --enable-libspeex --enable-libsrt --enable-libvorbis --enable-libopus --enable-libtheora --enable-libvidstab --enable-libvo-amrwbenc --enable-libvpx --enable-libwebp --enable-libx264 --enable-libx265 --enable-libxml2 --enable-libdav1d --enable-libxvid --enable-libzvbi --enable-libzimg
  libavutil      56. 31.100 / 56. 31.100
  libavcodec     58. 54.100 / 58. 54.100
  libavformat    58. 29.100 / 58. 29.100
  libavdevice    58.  8.100 / 58.  8.100
  libavfilter     7. 57.100 /  7. 57.100
  libswscale      5.  5.100 /  5.  5.100
  libswresample   3.  5.100 /  3.  5.100
  libpostproc    55.  5.100 / 55.  5.100
[mov,mp4,m4a,3gp,3g2,mj2 @ 0x5914500] Format mov,mp4,m4a,3gp,3g2,mj2 detected only with low score of 1, misdetection possible!
[mov,mp4,m4a,3gp,3g2,mj2 @ 0x5914500] moov atom not found
../data/bid/video/https:____www.behance.net__videos__8e1173b7-9e84-4f44-a849-243f2271bb2c__Thinking-Doodles-with-Rachel-Ashley-from-Fresco.mp4: Invalid data found when processing input

----------------------------------------------------------
https://www.behance.net/videos/37aec988-de9b-4bf9-941e-947c4b7406e2/Virtual-Plein-Air-Sketch-Studies-with-Maddy-Bellwoar.mp4
Traceback (most recent call last):
  File "/home/saransh03sharma/.local/lib/python3.10/site-packages/moviepy/video/io/ffmpeg_reader.py", line 285, in ffmpeg_parse_infos
    line = [l for l in lines if keyword in l][index]
IndexError: list index out of range

During handling of the above exception, another exception occurred:

Traceback (most recent call last):
  File "/home/saransh03sharma/Documents/GitHub/VideoIntentDiscovery/scripts/download_videos.py", line 49, in get_slices
    video = VideoFileClip(tmp_name)
  File "/home/saransh03sharma/.local/lib/python3.10/site-packages/moviepy/video/io/VideoFileClip.py", line 88, in __init__
    self.reader = FFMPEG_VideoReader(filename, pix_fmt=pix_fmt,
  File "/home/saransh03sharma/.local/lib/python3.10/site-packages/moviepy/video/io/ffmpeg_reader.py", line 35, in __init__
    infos = ffmpeg_parse_infos(filename, print_infos, check_duration,
  File "/home/saransh03sharma/.local/lib/python3.10/site-packages/moviepy/video/io/ffmpeg_reader.py", line 289, in ffmpeg_parse_infos
    raise IOError(("MoviePy error: failed to read the duration of file %s.\n"
OSError: MoviePy error: failed to read the duration of file ../data/bid/video/https:____www.behance.net__videos__37aec988-de9b-4bf9-941e-947c4b7406e2__Virtual-Plein-Air-Sketch-Studies-with-Maddy-Bellwoar.mp4.
Here are the file infos returned by ffmpeg:

ffmpeg version 4.2.2-static https://johnvansickle.com/ffmpeg/  Copyright (c) 2000-2019 the FFmpeg developers
  built with gcc 8 (Debian 8.3.0-6)
  configuration: --enable-gpl --enable-version3 --enable-static --disable-debug --disable-ffplay --disable-indev=sndio --disable-outdev=sndio --cc=gcc --enable-fontconfig --enable-frei0r --enable-gnutls --enable-gmp --enable-libgme --enable-gray --enable-libaom --enable-libfribidi --enable-libass --enable-libvmaf --enable-libfreetype --enable-libmp3lame --enable-libopencore-amrnb --enable-libopencore-amrwb --enable-libopenjpeg --enable-librubberband --enable-libsoxr --enable-libspeex --enable-libsrt --enable-libvorbis --enable-libopus --enable-libtheora --enable-libvidstab --enable-libvo-amrwbenc --enable-libvpx --enable-libwebp --enable-libx264 --enable-libx265 --enable-libxml2 --enable-libdav1d --enable-libxvid --enable-libzvbi --enable-libzimg
  libavutil      56. 31.100 / 56. 31.100
  libavcodec     58. 54.100 / 58. 54.100
  libavformat    58. 29.100 / 58. 29.100
  libavdevice    58.  8.100 / 58.  8.100
  libavfilter     7. 57.100 /  7. 57.100
  libswscale      5.  5.100 /  5.  5.100
  libswresample   3.  5.100 /  3.  5.100
  libpostproc    55.  5.100 / 55.  5.100
[mov,mp4,m4a,3gp,3g2,mj2 @ 0x7316500] Format mov,mp4,m4a,3gp,3g2,mj2 detected only with low score of 1, misdetection possible!
[mov,mp4,m4a,3gp,3g2,mj2 @ 0x7316500] moov atom not found
../data/bid/video/https:____www.behance.net__videos__37aec988-de9b-4bf9-941e-947c4b7406e2__Virtual-Plein-Air-Sketch-Studies-with-Maddy-Bellwoar.mp4: Invalid data found when processing input

----------------------------------------------------------
https://www.behance.net/videos/c147bd15-2e4a-4205-9bb3-25133826df6a/Shilin-chipping-away-a-painting.mp4
Traceback (most recent call last):
  File "/home/saransh03sharma/.local/lib/python3.10/site-packages/moviepy/video/io/ffmpeg_reader.py", line 285, in ffmpeg_parse_infos
    line = [l for l in lines if keyword in l][index]
IndexError: list index out of range

During handling of the above exception, another exception occurred:

Traceback (most recent call last):
  File "/home/saransh03sharma/Documents/GitHub/VideoIntentDiscovery/scripts/download_videos.py", line 49, in get_slices
    video = VideoFileClip(tmp_name)
  File "/home/saransh03sharma/.local/lib/python3.10/site-packages/moviepy/video/io/VideoFileClip.py", line 88, in __init__
    self.reader = FFMPEG_VideoReader(filename, pix_fmt=pix_fmt,
  File "/home/saransh03sharma/.local/lib/python3.10/site-packages/moviepy/video/io/ffmpeg_reader.py", line 35, in __init__
    infos = ffmpeg_parse_infos(filename, print_infos, check_duration,
  File "/home/saransh03sharma/.local/lib/python3.10/site-packages/moviepy/video/io/ffmpeg_reader.py", line 289, in ffmpeg_parse_infos
    raise IOError(("MoviePy error: failed to read the duration of file %s.\n"
OSError: MoviePy error: failed to read the duration of file ../data/bid/video/https:____www.behance.net__videos__c147bd15-2e4a-4205-9bb3-25133826df6a__Shilin-chipping-away-a-painting.mp4.
Here are the file infos returned by ffmpeg:

ffmpeg version 4.2.2-static https://johnvansickle.com/ffmpeg/  Copyright (c) 2000-2019 the FFmpeg developers
  built with gcc 8 (Debian 8.3.0-6)
  configuration: --enable-gpl --enable-version3 --enable-static --disable-debug --disable-ffplay --disable-indev=sndio --disable-outdev=sndio --cc=gcc --enable-fontconfig --enable-frei0r --enable-gnutls --enable-gmp --enable-libgme --enable-gray --enable-libaom --enable-libfribidi --enable-libass --enable-libvmaf --enable-libfreetype --enable-libmp3lame --enable-libopencore-amrnb --enable-libopencore-amrwb --enable-libopenjpeg --enable-librubberband --enable-libsoxr --enable-libspeex --enable-libsrt --enable-libvorbis --enable-libopus --enable-libtheora --enable-libvidstab --enable-libvo-amrwbenc --enable-libvpx --enable-libwebp --enable-libx264 --enable-libx265 --enable-libxml2 --enable-libdav1d --enable-libxvid --enable-libzvbi --enable-libzimg
  libavutil      56. 31.100 / 56. 31.100
  libavcodec     58. 54.100 / 58. 54.100
  libavformat    58. 29.100 / 58. 29.100
  libavdevice    58.  8.100 / 58.  8.100
  libavfilter     7. 57.100 /  7. 57.100
  libswscale      5.  5.100 /  5.  5.100
  libswresample   3.  5.100 /  3.  5.100
  libpostproc    55.  5.100 / 55.  5.100
[mov,mp4,m4a,3gp,3g2,mj2 @ 0x556f500] Format mov,mp4,m4a,3gp,3g2,mj2 detected only with low score of 1, misdetection possible!
[mov,mp4,m4a,3gp,3g2,mj2 @ 0x556f500] moov atom not found
../data/bid/video/https:____www.behance.net__videos__c147bd15-2e4a-4205-9bb3-25133826df6a__Shilin-chipping-away-a-painting.mp4: Invalid data found when processing input

----------------------------------------------------------
https://www.behance.net/videos/7e9ff601-cbf5-4fdf-be0f-1685186b5ff3/Frame-by-Frame-Animation-in-Photoshop-with-Klarens-Malluta.mp4
Traceback (most recent call last):
  File "/home/saransh03sharma/.local/lib/python3.10/site-packages/moviepy/video/io/ffmpeg_reader.py", line 285, in ffmpeg_parse_infos
    line = [l for l in lines if keyword in l][index]
IndexError: list index out of range

During handling of the above exception, another exception occurred:

Traceback (most recent call last):
  File "/home/saransh03sharma/Documents/GitHub/VideoIntentDiscovery/scripts/download_videos.py", line 49, in get_slices
    video = VideoFileClip(tmp_name)
  File "/home/saransh03sharma/.local/lib/python3.10/site-packages/moviepy/video/io/VideoFileClip.py", line 88, in __init__
    self.reader = FFMPEG_VideoReader(filename, pix_fmt=pix_fmt,
  File "/home/saransh03sharma/.local/lib/python3.10/site-packages/moviepy/video/io/ffmpeg_reader.py", line 35, in __init__
    infos = ffmpeg_parse_infos(filename, print_infos, check_duration,
  File "/home/saransh03sharma/.local/lib/python3.10/site-packages/moviepy/video/io/ffmpeg_reader.py", line 289, in ffmpeg_parse_infos
    raise IOError(("MoviePy error: failed to read the duration of file %s.\n"
OSError: MoviePy error: failed to read the duration of file ../data/bid/video/https:____www.behance.net__videos__7e9ff601-cbf5-4fdf-be0f-1685186b5ff3__Frame-by-Frame-Animation-in-Photoshop-with-Klarens-Malluta.mp4.
Here are the file infos returned by ffmpeg:

ffmpeg version 4.2.2-static https://johnvansickle.com/ffmpeg/  Copyright (c) 2000-2019 the FFmpeg developers
  built with gcc 8 (Debian 8.3.0-6)
  configuration: --enable-gpl --enable-version3 --enable-static --disable-debug --disable-ffplay --disable-indev=sndio --disable-outdev=sndio --cc=gcc --enable-fontconfig --enable-frei0r --enable-gnutls --enable-gmp --enable-libgme --enable-gray --enable-libaom --enable-libfribidi --enable-libass --enable-libvmaf --enable-libfreetype --enable-libmp3lame --enable-libopencore-amrnb --enable-libopencore-amrwb --enable-libopenjpeg --enable-librubberband --enable-libsoxr --enable-libspeex --enable-libsrt --enable-libvorbis --enable-libopus --enable-libtheora --enable-libvidstab --enable-libvo-amrwbenc --enable-libvpx --enable-libwebp --enable-libx264 --enable-libx265 --enable-libxml2 --enable-libdav1d --enable-libxvid --enable-libzvbi --enable-libzimg
  libavutil      56. 31.100 / 56. 31.100
  libavcodec     58. 54.100 / 58. 54.100
  libavformat    58. 29.100 / 58. 29.100
  libavdevice    58.  8.100 / 58.  8.100
  libavfilter     7. 57.100 /  7. 57.100
  libswscale      5.  5.100 /  5.  5.100
  libswresample   3.  5.100 /  3.  5.100
  libpostproc    55.  5.100 / 55.  5.100
[mov,mp4,m4a,3gp,3g2,mj2 @ 0x60d4500] Format mov,mp4,m4a,3gp,3g2,mj2 detected only with low score of 1, misdetection possible!
[mov,mp4,m4a,3gp,3g2,mj2 @ 0x60d4500] moov atom not found
../data/bid/video/https:____www.behance.net__videos__7e9ff601-cbf5-4fdf-be0f-1685186b5ff3__Frame-by-Frame-Animation-in-Photoshop-with-Klarens-Malluta.mp4: Invalid data found when processing input

----------------------------------------------------------
https://www.behance.net/videos/d91ef6a6-fa91-4dcb-8b86-48efc87a906a/TUTS42-Episode-5-Don-t-Blink.mp4
Traceback (most recent call last):
  File "/home/saransh03sharma/.local/lib/python3.10/site-packages/moviepy/video/io/ffmpeg_reader.py", line 285, in ffmpeg_parse_infos
    line = [l for l in lines if keyword in l][index]
IndexError: list index out of range

During handling of the above exception, another exception occurred:

Traceback (most recent call last):
  File "/home/saransh03sharma/Documents/GitHub/VideoIntentDiscovery/scripts/download_videos.py", line 49, in get_slices
    video = VideoFileClip(tmp_name)
  File "/home/saransh03sharma/.local/lib/python3.10/site-packages/moviepy/video/io/VideoFileClip.py", line 88, in __init__
    self.reader = FFMPEG_VideoReader(filename, pix_fmt=pix_fmt,
  File "/home/saransh03sharma/.local/lib/python3.10/site-packages/moviepy/video/io/ffmpeg_reader.py", line 35, in __init__
    infos = ffmpeg_parse_infos(filename, print_infos, check_duration,
  File "/home/saransh03sharma/.local/lib/python3.10/site-packages/moviepy/video/io/ffmpeg_reader.py", line 289, in ffmpeg_parse_infos
    raise IOError(("MoviePy error: failed to read the duration of file %s.\n"
OSError: MoviePy error: failed to read the duration of file ../data/bid/video/https:____www.behance.net__videos__d91ef6a6-fa91-4dcb-8b86-48efc87a906a__TUTS42-Episode-5-Don-t-Blink.mp4.
Here are the file infos returned by ffmpeg:

ffmpeg version 4.2.2-static https://johnvansickle.com/ffmpeg/  Copyright (c) 2000-2019 the FFmpeg developers
  built with gcc 8 (Debian 8.3.0-6)
  configuration: --enable-gpl --enable-version3 --enable-static --disable-debug --disable-ffplay --disable-indev=sndio --disable-outdev=sndio --cc=gcc --enable-fontconfig --enable-frei0r --enable-gnutls --enable-gmp --enable-libgme --enable-gray --enable-libaom --enable-libfribidi --enable-libass --enable-libvmaf --enable-libfreetype --enable-libmp3lame --enable-libopencore-amrnb --enable-libopencore-amrwb --enable-libopenjpeg --enable-librubberband --enable-libsoxr --enable-libspeex --enable-libsrt --enable-libvorbis --enable-libopus --enable-libtheora --enable-libvidstab --enable-libvo-amrwbenc --enable-libvpx --enable-libwebp --enable-libx264 --enable-libx265 --enable-libxml2 --enable-libdav1d --enable-libxvid --enable-libzvbi --enable-libzimg
  libavutil      56. 31.100 / 56. 31.100
  libavcodec     58. 54.100 / 58. 54.100
  libavformat    58. 29.100 / 58. 29.100
  libavdevice    58.  8.100 / 58.  8.100
  libavfilter     7. 57.100 /  7. 57.100
  libswscale      5.  5.100 /  5.  5.100
  libswresample   3.  5.100 /  3.  5.100
  libpostproc    55.  5.100 / 55.  5.100
[mov,mp4,m4a,3gp,3g2,mj2 @ 0x667b500] Format mov,mp4,m4a,3gp,3g2,mj2 detected only with low score of 1, misdetection possible!
[mov,mp4,m4a,3gp,3g2,mj2 @ 0x667b500] moov atom not found
../data/bid/video/https:____www.behance.net__videos__d91ef6a6-fa91-4dcb-8b86-48efc87a906a__TUTS42-Episode-5-Don-t-Blink.mp4: Invalid data found when processing input

----------------------------------------------------------
https://www.behance.net/videos/72c4b6f2-605d-4d3b-abfe-acbffbc0242a/Sketching-Tennis-Players-from-Imagination.mp4
Traceback (most recent call last):
  File "/home/saransh03sharma/Documents/GitHub/VideoIntentDiscovery/scripts/download_videos.py", line 44, in get_slices
    urllib.request.urlretrieve(url, tmp_name, show_progress)
  File "/usr/lib/python3.10/urllib/request.py", line 267, in urlretrieve
    reporthook(blocknum, bs, size)
  File "/home/saransh03sharma/Documents/GitHub/VideoIntentDiscovery/scripts/download_videos.py", line 28, in show_progress
    pbar.start()
  File "/usr/lib/python3/dist-packages/progressbar/progressbar.py", line 286, in start
    if self.maxval < 0: raise ValueError('Value out of range')
ValueError: Value out of range
----------------------------------------------------------
https://livestream-videos-prod.s3-us-west-2.amazonaws.com/stream-c0902cc5-e96a-4221-9f52-39fc87062c98-s3.mp4
Traceback (most recent call last):
  File "/home/saransh03sharma/Documents/GitHub/VideoIntentDiscovery/scripts/download_videos.py", line 44, in get_slices
    urllib.request.urlretrieve(url, tmp_name, show_progress)
  File "/usr/lib/python3.10/urllib/request.py", line 267, in urlretrieve
    reporthook(blocknum, bs, size)
  File "/home/saransh03sharma/Documents/GitHub/VideoIntentDiscovery/scripts/download_videos.py", line 32, in show_progress
    pbar.update(downloaded)
  File "/usr/lib/python3/dist-packages/progressbar/progressbar.py", line 250, in update
    raise ValueError('Value out of range')
ValueError: Value out of range
----------------------------------------------------------
https://www.behance.net/videos/cd6ad678-1dd9-4eed-95e9-3fa5abcfea27/Illustrated-Portrait-using-Photoshop-with-Klarens-Malluta.mp4
Traceback (most recent call last):
  File "/home/saransh03sharma/Documents/GitHub/VideoIntentDiscovery/scripts/download_videos.py", line 44, in get_slices
    urllib.request.urlretrieve(url, tmp_name, show_progress)
  File "/usr/lib/python3.10/urllib/request.py", line 267, in urlretrieve
    reporthook(blocknum, bs, size)
  File "/home/saransh03sharma/Documents/GitHub/VideoIntentDiscovery/scripts/download_videos.py", line 28, in show_progress
    pbar.start()
  File "/usr/lib/python3/dist-packages/progressbar/progressbar.py", line 286, in start
    if self.maxval < 0: raise ValueError('Value out of range')
ValueError: Value out of range
----------------------------------------------------------
https://livestream-videos-prod.s3-us-west-2.amazonaws.com/stream-3d06e524-13a2-45ae-95d8-993113826c77-s3.mp4
Traceback (most recent call last):
  File "/home/saransh03sharma/Documents/GitHub/VideoIntentDiscovery/scripts/download_videos.py", line 44, in get_slices
    urllib.request.urlretrieve(url, tmp_name, show_progress)
  File "/usr/lib/python3.10/urllib/request.py", line 267, in urlretrieve
    reporthook(blocknum, bs, size)
  File "/home/saransh03sharma/Documents/GitHub/VideoIntentDiscovery/scripts/download_videos.py", line 32, in show_progress
    pbar.update(downloaded)
  File "/usr/lib/python3/dist-packages/progressbar/progressbar.py", line 250, in update
    raise ValueError('Value out of range')
ValueError: Value out of range
----------------------------------------------------------
https://www.behance.net/videos/632fffaf-f8ae-4c75-bcaf-91ea4f8ddfb6/Daily-Projects-with-Klarens-Malluta.mp4
Traceback (most recent call last):
  File "/home/saransh03sharma/Documents/GitHub/VideoIntentDiscovery/scripts/download_videos.py", line 44, in get_slices
    urllib.request.urlretrieve(url, tmp_name, show_progress)
  File "/usr/lib/python3.10/urllib/request.py", line 267, in urlretrieve
    reporthook(blocknum, bs, size)
  File "/home/saransh03sharma/Documents/GitHub/VideoIntentDiscovery/scripts/download_videos.py", line 28, in show_progress
    pbar.start()
  File "/usr/lib/python3/dist-packages/progressbar/progressbar.py", line 286, in start
    if self.maxval < 0: raise ValueError('Value out of range')
ValueError: Value out of range
----------------------------------------------------------
https://www.behance.net/videos/b7f29dd7-7d9f-435f-8b3c-bcdb8e0202b9/Creature-Character-Concepts-with-2SL.mp4
Traceback (most recent call last):
  File "/home/saransh03sharma/Documents/GitHub/VideoIntentDiscovery/scripts/download_videos.py", line 44, in get_slices
    urllib.request.urlretrieve(url, tmp_name, show_progress)
  File "/usr/lib/python3.10/urllib/request.py", line 267, in urlretrieve
    reporthook(blocknum, bs, size)
  File "/home/saransh03sharma/Documents/GitHub/VideoIntentDiscovery/scripts/download_videos.py", line 34, in show_progress
    pbar.finish()
  File "/usr/lib/python3/dist-packages/progressbar/progressbar.py", line 302, in finish
    self.update(self.maxval)
  File "/usr/lib/python3/dist-packages/progressbar/progressbar.py", line 250, in update
    raise ValueError('Value out of range')
ValueError: Value out of range
----------------------------------------------------------
https://livestream-videos-prod.s3-us-west-2.amazonaws.com/stream-f4d1efd0-1890-4238-9d59-ecd41eb37a51-s3.mp4
Traceback (most recent call last):
  File "/home/saransh03sharma/Documents/GitHub/VideoIntentDiscovery/scripts/download_videos.py", line 44, in get_slices
    urllib.request.urlretrieve(url, tmp_name, show_progress)
  File "/usr/lib/python3.10/urllib/request.py", line 267, in urlretrieve
    reporthook(blocknum, bs, size)
  File "/home/saransh03sharma/Documents/GitHub/VideoIntentDiscovery/scripts/download_videos.py", line 32, in show_progress
    pbar.update(downloaded)
  File "/usr/lib/python3/dist-packages/progressbar/progressbar.py", line 250, in update
    raise ValueError('Value out of range')
ValueError: Value out of range
----------------------------------------------------------
https://www.behance.net/videos/f83ea5f3-dcc8-47c0-ab75-50b489538348/Autumn-Themed-Digital-Painting-Studies-with-Maddy-Bellwoar.mp4
Traceback (most recent call last):
  File "/home/saransh03sharma/.local/lib/python3.10/site-packages/moviepy/video/io/ffmpeg_reader.py", line 285, in ffmpeg_parse_infos
    line = [l for l in lines if keyword in l][index]
IndexError: list index out of range

During handling of the above exception, another exception occurred:

Traceback (most recent call last):
  File "/home/saransh03sharma/Documents/GitHub/VideoIntentDiscovery/scripts/download_videos.py", line 49, in get_slices
    video = VideoFileClip(tmp_name)
  File "/home/saransh03sharma/.local/lib/python3.10/site-packages/moviepy/video/io/VideoFileClip.py", line 88, in __init__
    self.reader = FFMPEG_VideoReader(filename, pix_fmt=pix_fmt,
  File "/home/saransh03sharma/.local/lib/python3.10/site-packages/moviepy/video/io/ffmpeg_reader.py", line 35, in __init__
    infos = ffmpeg_parse_infos(filename, print_infos, check_duration,
  File "/home/saransh03sharma/.local/lib/python3.10/site-packages/moviepy/video/io/ffmpeg_reader.py", line 289, in ffmpeg_parse_infos
    raise IOError(("MoviePy error: failed to read the duration of file %s.\n"
OSError: MoviePy error: failed to read the duration of file ../data/bid/video/https:____www.behance.net__videos__f83ea5f3-dcc8-47c0-ab75-50b489538348__Autumn-Themed-Digital-Painting-Studies-with-Maddy-Bellwoar.mp4.
Here are the file infos returned by ffmpeg:

ffmpeg version 4.2.2-static https://johnvansickle.com/ffmpeg/  Copyright (c) 2000-2019 the FFmpeg developers
  built with gcc 8 (Debian 8.3.0-6)
  configuration: --enable-gpl --enable-version3 --enable-static --disable-debug --disable-ffplay --disable-indev=sndio --disable-outdev=sndio --cc=gcc --enable-fontconfig --enable-frei0r --enable-gnutls --enable-gmp --enable-libgme --enable-gray --enable-libaom --enable-libfribidi --enable-libass --enable-libvmaf --enable-libfreetype --enable-libmp3lame --enable-libopencore-amrnb --enable-libopencore-amrwb --enable-libopenjpeg --enable-librubberband --enable-libsoxr --enable-libspeex --enable-libsrt --enable-libvorbis --enable-libopus --enable-libtheora --enable-libvidstab --enable-libvo-amrwbenc --enable-libvpx --enable-libwebp --enable-libx264 --enable-libx265 --enable-libxml2 --enable-libdav1d --enable-libxvid --enable-libzvbi --enable-libzimg
  libavutil      56. 31.100 / 56. 31.100
  libavcodec     58. 54.100 / 58. 54.100
  libavformat    58. 29.100 / 58. 29.100
  libavdevice    58.  8.100 / 58.  8.100
  libavfilter     7. 57.100 /  7. 57.100
  libswscale      5.  5.100 /  5.  5.100
  libswresample   3.  5.100 /  3.  5.100
  libpostproc    55.  5.100 / 55.  5.100
[mov,mp4,m4a,3gp,3g2,mj2 @ 0x55b3500] Format mov,mp4,m4a,3gp,3g2,mj2 detected only with low score of 1, misdetection possible!
[mov,mp4,m4a,3gp,3g2,mj2 @ 0x55b3500] moov atom not found
../data/bid/video/https:____www.behance.net__videos__f83ea5f3-dcc8-47c0-ab75-50b489538348__Autumn-Themed-Digital-Painting-Studies-with-Maddy-Bellwoar.mp4: Invalid data found when processing input

----------------------------------------------------------
https://www.behance.net/videos/37aec988-de9b-4bf9-941e-947c4b7406e2/Virtual-Plein-Air-Sketch-Studies-with-Maddy-Bellwoar.mp4
Traceback (most recent call last):
  File "/home/saransh03sharma/.local/lib/python3.10/site-packages/moviepy/video/io/ffmpeg_reader.py", line 285, in ffmpeg_parse_infos
    line = [l for l in lines if keyword in l][index]
IndexError: list index out of range

During handling of the above exception, another exception occurred:

Traceback (most recent call last):
  File "/home/saransh03sharma/Documents/GitHub/VideoIntentDiscovery/scripts/download_videos.py", line 49, in get_slices
    video = VideoFileClip(tmp_name)
  File "/home/saransh03sharma/.local/lib/python3.10/site-packages/moviepy/video/io/VideoFileClip.py", line 88, in __init__
    self.reader = FFMPEG_VideoReader(filename, pix_fmt=pix_fmt,
  File "/home/saransh03sharma/.local/lib/python3.10/site-packages/moviepy/video/io/ffmpeg_reader.py", line 35, in __init__
    infos = ffmpeg_parse_infos(filename, print_infos, check_duration,
  File "/home/saransh03sharma/.local/lib/python3.10/site-packages/moviepy/video/io/ffmpeg_reader.py", line 289, in ffmpeg_parse_infos
    raise IOError(("MoviePy error: failed to read the duration of file %s.\n"
OSError: MoviePy error: failed to read the duration of file ../data/bid/video/https:____www.behance.net__videos__37aec988-de9b-4bf9-941e-947c4b7406e2__Virtual-Plein-Air-Sketch-Studies-with-Maddy-Bellwoar.mp4.
Here are the file infos returned by ffmpeg:

ffmpeg version 4.2.2-static https://johnvansickle.com/ffmpeg/  Copyright (c) 2000-2019 the FFmpeg developers
  built with gcc 8 (Debian 8.3.0-6)
  configuration: --enable-gpl --enable-version3 --enable-static --disable-debug --disable-ffplay --disable-indev=sndio --disable-outdev=sndio --cc=gcc --enable-fontconfig --enable-frei0r --enable-gnutls --enable-gmp --enable-libgme --enable-gray --enable-libaom --enable-libfribidi --enable-libass --enable-libvmaf --enable-libfreetype --enable-libmp3lame --enable-libopencore-amrnb --enable-libopencore-amrwb --enable-libopenjpeg --enable-librubberband --enable-libsoxr --enable-libspeex --enable-libsrt --enable-libvorbis --enable-libopus --enable-libtheora --enable-libvidstab --enable-libvo-amrwbenc --enable-libvpx --enable-libwebp --enable-libx264 --enable-libx265 --enable-libxml2 --enable-libdav1d --enable-libxvid --enable-libzvbi --enable-libzimg
  libavutil      56. 31.100 / 56. 31.100
  libavcodec     58. 54.100 / 58. 54.100
  libavformat    58. 29.100 / 58. 29.100
  libavdevice    58.  8.100 / 58.  8.100
  libavfilter     7. 57.100 /  7. 57.100
  libswscale      5.  5.100 /  5.  5.100
  libswresample   3.  5.100 /  3.  5.100
  libpostproc    55.  5.100 / 55.  5.100
[mov,mp4,m4a,3gp,3g2,mj2 @ 0x6850500] Format mov,mp4,m4a,3gp,3g2,mj2 detected only with low score of 1, misdetection possible!
[mov,mp4,m4a,3gp,3g2,mj2 @ 0x6850500] moov atom not found
../data/bid/video/https:____www.behance.net__videos__37aec988-de9b-4bf9-941e-947c4b7406e2__Virtual-Plein-Air-Sketch-Studies-with-Maddy-Bellwoar.mp4: Invalid data found when processing input

----------------------------------------------------------
https://www.behance.net/videos/b7f29dd7-7d9f-435f-8b3c-bcdb8e0202b9/Creature-Character-Concepts-with-2SL.mp4
Traceback (most recent call last):
  File "/home/saransh03sharma/.local/lib/python3.10/site-packages/moviepy/video/io/ffmpeg_reader.py", line 285, in ffmpeg_parse_infos
    line = [l for l in lines if keyword in l][index]
IndexError: list index out of range

During handling of the above exception, another exception occurred:

Traceback (most recent call last):
  File "/home/saransh03sharma/Documents/GitHub/VideoIntentDiscovery/scripts/download_videos.py", line 49, in get_slices
    video = VideoFileClip(tmp_name)
  File "/home/saransh03sharma/.local/lib/python3.10/site-packages/moviepy/video/io/VideoFileClip.py", line 88, in __init__
    self.reader = FFMPEG_VideoReader(filename, pix_fmt=pix_fmt,
  File "/home/saransh03sharma/.local/lib/python3.10/site-packages/moviepy/video/io/ffmpeg_reader.py", line 35, in __init__
    infos = ffmpeg_parse_infos(filename, print_infos, check_duration,
  File "/home/saransh03sharma/.local/lib/python3.10/site-packages/moviepy/video/io/ffmpeg_reader.py", line 289, in ffmpeg_parse_infos
    raise IOError(("MoviePy error: failed to read the duration of file %s.\n"
OSError: MoviePy error: failed to read the duration of file ../data/bid/video/https:____www.behance.net__videos__b7f29dd7-7d9f-435f-8b3c-bcdb8e0202b9__Creature-Character-Concepts-with-2SL.mp4.
Here are the file infos returned by ffmpeg:

ffmpeg version 4.2.2-static https://johnvansickle.com/ffmpeg/  Copyright (c) 2000-2019 the FFmpeg developers
  built with gcc 8 (Debian 8.3.0-6)
  configuration: --enable-gpl --enable-version3 --enable-static --disable-debug --disable-ffplay --disable-indev=sndio --disable-outdev=sndio --cc=gcc --enable-fontconfig --enable-frei0r --enable-gnutls --enable-gmp --enable-libgme --enable-gray --enable-libaom --enable-libfribidi --enable-libass --enable-libvmaf --enable-libfreetype --enable-libmp3lame --enable-libopencore-amrnb --enable-libopencore-amrwb --enable-libopenjpeg --enable-librubberband --enable-libsoxr --enable-libspeex --enable-libsrt --enable-libvorbis --enable-libopus --enable-libtheora --enable-libvidstab --enable-libvo-amrwbenc --enable-libvpx --enable-libwebp --enable-libx264 --enable-libx265 --enable-libxml2 --enable-libdav1d --enable-libxvid --enable-libzvbi --enable-libzimg
  libavutil      56. 31.100 / 56. 31.100
  libavcodec     58. 54.100 / 58. 54.100
  libavformat    58. 29.100 / 58. 29.100
  libavdevice    58.  8.100 / 58.  8.100
  libavfilter     7. 57.100 /  7. 57.100
  libswscale      5.  5.100 /  5.  5.100
  libswresample   3.  5.100 /  3.  5.100
  libpostproc    55.  5.100 / 55.  5.100
[mov,mp4,m4a,3gp,3g2,mj2 @ 0x7280500] Format mov,mp4,m4a,3gp,3g2,mj2 detected only with low score of 1, misdetection possible!
[mov,mp4,m4a,3gp,3g2,mj2 @ 0x7280500] moov atom not found
../data/bid/video/https:____www.behance.net__videos__b7f29dd7-7d9f-435f-8b3c-bcdb8e0202b9__Creature-Character-Concepts-with-2SL.mp4: Invalid data found when processing input

----------------------------------------------------------
https://www.behance.net/videos/c147bd15-2e4a-4205-9bb3-25133826df6a/Shilin-chipping-away-a-painting.mp4
Traceback (most recent call last):
  File "/home/saransh03sharma/.local/lib/python3.10/site-packages/moviepy/video/io/ffmpeg_reader.py", line 285, in ffmpeg_parse_infos
    line = [l for l in lines if keyword in l][index]
IndexError: list index out of range

During handling of the above exception, another exception occurred:

Traceback (most recent call last):
  File "/home/saransh03sharma/Documents/GitHub/VideoIntentDiscovery/scripts/download_videos.py", line 49, in get_slices
    video = VideoFileClip(tmp_name)
  File "/home/saransh03sharma/.local/lib/python3.10/site-packages/moviepy/video/io/VideoFileClip.py", line 88, in __init__
    self.reader = FFMPEG_VideoReader(filename, pix_fmt=pix_fmt,
  File "/home/saransh03sharma/.local/lib/python3.10/site-packages/moviepy/video/io/ffmpeg_reader.py", line 35, in __init__
    infos = ffmpeg_parse_infos(filename, print_infos, check_duration,
  File "/home/saransh03sharma/.local/lib/python3.10/site-packages/moviepy/video/io/ffmpeg_reader.py", line 289, in ffmpeg_parse_infos
    raise IOError(("MoviePy error: failed to read the duration of file %s.\n"
OSError: MoviePy error: failed to read the duration of file ../data/bid/video/https:____www.behance.net__videos__c147bd15-2e4a-4205-9bb3-25133826df6a__Shilin-chipping-away-a-painting.mp4.
Here are the file infos returned by ffmpeg:

ffmpeg version 4.2.2-static https://johnvansickle.com/ffmpeg/  Copyright (c) 2000-2019 the FFmpeg developers
  built with gcc 8 (Debian 8.3.0-6)
  configuration: --enable-gpl --enable-version3 --enable-static --disable-debug --disable-ffplay --disable-indev=sndio --disable-outdev=sndio --cc=gcc --enable-fontconfig --enable-frei0r --enable-gnutls --enable-gmp --enable-libgme --enable-gray --enable-libaom --enable-libfribidi --enable-libass --enable-libvmaf --enable-libfreetype --enable-libmp3lame --enable-libopencore-amrnb --enable-libopencore-amrwb --enable-libopenjpeg --enable-librubberband --enable-libsoxr --enable-libspeex --enable-libsrt --enable-libvorbis --enable-libopus --enable-libtheora --enable-libvidstab --enable-libvo-amrwbenc --enable-libvpx --enable-libwebp --enable-libx264 --enable-libx265 --enable-libxml2 --enable-libdav1d --enable-libxvid --enable-libzvbi --enable-libzimg
  libavutil      56. 31.100 / 56. 31.100
  libavcodec     58. 54.100 / 58. 54.100
  libavformat    58. 29.100 / 58. 29.100
  libavdevice    58.  8.100 / 58.  8.100
  libavfilter     7. 57.100 /  7. 57.100
  libswscale      5.  5.100 /  5.  5.100
  libswresample   3.  5.100 /  3.  5.100
  libpostproc    55.  5.100 / 55.  5.100
[mov,mp4,m4a,3gp,3g2,mj2 @ 0x6b37500] Format mov,mp4,m4a,3gp,3g2,mj2 detected only with low score of 1, misdetection possible!
[mov,mp4,m4a,3gp,3g2,mj2 @ 0x6b37500] moov atom not found
../data/bid/video/https:____www.behance.net__videos__c147bd15-2e4a-4205-9bb3-25133826df6a__Shilin-chipping-away-a-painting.mp4: Invalid data found when processing input

----------------------------------------------------------
https://www.behance.net/videos/632fffaf-f8ae-4c75-bcaf-91ea4f8ddfb6/Daily-Projects-with-Klarens-Malluta.mp4
Traceback (most recent call last):
  File "/home/saransh03sharma/.local/lib/python3.10/site-packages/moviepy/video/io/ffmpeg_reader.py", line 285, in ffmpeg_parse_infos
    line = [l for l in lines if keyword in l][index]
IndexError: list index out of range

During handling of the above exception, another exception occurred:

Traceback (most recent call last):
  File "/home/saransh03sharma/Documents/GitHub/VideoIntentDiscovery/scripts/download_videos.py", line 49, in get_slices
    video = VideoFileClip(tmp_name)
  File "/home/saransh03sharma/.local/lib/python3.10/site-packages/moviepy/video/io/VideoFileClip.py", line 88, in __init__
    self.reader = FFMPEG_VideoReader(filename, pix_fmt=pix_fmt,
  File "/home/saransh03sharma/.local/lib/python3.10/site-packages/moviepy/video/io/ffmpeg_reader.py", line 35, in __init__
    infos = ffmpeg_parse_infos(filename, print_infos, check_duration,
  File "/home/saransh03sharma/.local/lib/python3.10/site-packages/moviepy/video/io/ffmpeg_reader.py", line 289, in ffmpeg_parse_infos
    raise IOError(("MoviePy error: failed to read the duration of file %s.\n"
OSError: MoviePy error: failed to read the duration of file ../data/bid/video/https:____www.behance.net__videos__632fffaf-f8ae-4c75-bcaf-91ea4f8ddfb6__Daily-Projects-with-Klarens-Malluta.mp4.
Here are the file infos returned by ffmpeg:

ffmpeg version 4.2.2-static https://johnvansickle.com/ffmpeg/  Copyright (c) 2000-2019 the FFmpeg developers
  built with gcc 8 (Debian 8.3.0-6)
  configuration: --enable-gpl --enable-version3 --enable-static --disable-debug --disable-ffplay --disable-indev=sndio --disable-outdev=sndio --cc=gcc --enable-fontconfig --enable-frei0r --enable-gnutls --enable-gmp --enable-libgme --enable-gray --enable-libaom --enable-libfribidi --enable-libass --enable-libvmaf --enable-libfreetype --enable-libmp3lame --enable-libopencore-amrnb --enable-libopencore-amrwb --enable-libopenjpeg --enable-librubberband --enable-libsoxr --enable-libspeex --enable-libsrt --enable-libvorbis --enable-libopus --enable-libtheora --enable-libvidstab --enable-libvo-amrwbenc --enable-libvpx --enable-libwebp --enable-libx264 --enable-libx265 --enable-libxml2 --enable-libdav1d --enable-libxvid --enable-libzvbi --enable-libzimg
  libavutil      56. 31.100 / 56. 31.100
  libavcodec     58. 54.100 / 58. 54.100
  libavformat    58. 29.100 / 58. 29.100
  libavdevice    58.  8.100 / 58.  8.100
  libavfilter     7. 57.100 /  7. 57.100
  libswscale      5.  5.100 /  5.  5.100
  libswresample   3.  5.100 /  3.  5.100
  libpostproc    55.  5.100 / 55.  5.100
[mov,mp4,m4a,3gp,3g2,mj2 @ 0x68a7500] Format mov,mp4,m4a,3gp,3g2,mj2 detected only with low score of 1, misdetection possible!
[mov,mp4,m4a,3gp,3g2,mj2 @ 0x68a7500] moov atom not found
../data/bid/video/https:____www.behance.net__videos__632fffaf-f8ae-4c75-bcaf-91ea4f8ddfb6__Daily-Projects-with-Klarens-Malluta.mp4: Invalid data found when processing input

----------------------------------------------------------
https://www.behance.net/videos/f83ea5f3-dcc8-47c0-ab75-50b489538348/Autumn-Themed-Digital-Painting-Studies-with-Maddy-Bellwoar.mp4
Traceback (most recent call last):
  File "/home/saransh03sharma/.local/lib/python3.10/site-packages/moviepy/video/io/ffmpeg_reader.py", line 285, in ffmpeg_parse_infos
    line = [l for l in lines if keyword in l][index]
IndexError: list index out of range

During handling of the above exception, another exception occurred:

Traceback (most recent call last):
  File "/home/saransh03sharma/Documents/GitHub/VideoIntentDiscovery/scripts/download_videos.py", line 49, in get_slices
    video = VideoFileClip(tmp_name)
  File "/home/saransh03sharma/.local/lib/python3.10/site-packages/moviepy/video/io/VideoFileClip.py", line 88, in __init__
    self.reader = FFMPEG_VideoReader(filename, pix_fmt=pix_fmt,
  File "/home/saransh03sharma/.local/lib/python3.10/site-packages/moviepy/video/io/ffmpeg_reader.py", line 35, in __init__
    infos = ffmpeg_parse_infos(filename, print_infos, check_duration,
  File "/home/saransh03sharma/.local/lib/python3.10/site-packages/moviepy/video/io/ffmpeg_reader.py", line 289, in ffmpeg_parse_infos
    raise IOError(("MoviePy error: failed to read the duration of file %s.\n"
OSError: MoviePy error: failed to read the duration of file ../data/bid/video/https:____www.behance.net__videos__f83ea5f3-dcc8-47c0-ab75-50b489538348__Autumn-Themed-Digital-Painting-Studies-with-Maddy-Bellwoar.mp4.
Here are the file infos returned by ffmpeg:

ffmpeg version 4.2.2-static https://johnvansickle.com/ffmpeg/  Copyright (c) 2000-2019 the FFmpeg developers
  built with gcc 8 (Debian 8.3.0-6)
  configuration: --enable-gpl --enable-version3 --enable-static --disable-debug --disable-ffplay --disable-indev=sndio --disable-outdev=sndio --cc=gcc --enable-fontconfig --enable-frei0r --enable-gnutls --enable-gmp --enable-libgme --enable-gray --enable-libaom --enable-libfribidi --enable-libass --enable-libvmaf --enable-libfreetype --enable-libmp3lame --enable-libopencore-amrnb --enable-libopencore-amrwb --enable-libopenjpeg --enable-librubberband --enable-libsoxr --enable-libspeex --enable-libsrt --enable-libvorbis --enable-libopus --enable-libtheora --enable-libvidstab --enable-libvo-amrwbenc --enable-libvpx --enable-libwebp --enable-libx264 --enable-libx265 --enable-libxml2 --enable-libdav1d --enable-libxvid --enable-libzvbi --enable-libzimg
  libavutil      56. 31.100 / 56. 31.100
  libavcodec     58. 54.100 / 58. 54.100
  libavformat    58. 29.100 / 58. 29.100
  libavdevice    58.  8.100 / 58.  8.100
  libavfilter     7. 57.100 /  7. 57.100
  libswscale      5.  5.100 /  5.  5.100
  libswresample   3.  5.100 /  3.  5.100
  libpostproc    55.  5.100 / 55.  5.100
[mov,mp4,m4a,3gp,3g2,mj2 @ 0x644d500] Format mov,mp4,m4a,3gp,3g2,mj2 detected only with low score of 1, misdetection possible!
[mov,mp4,m4a,3gp,3g2,mj2 @ 0x644d500] moov atom not found
../data/bid/video/https:____www.behance.net__videos__f83ea5f3-dcc8-47c0-ab75-50b489538348__Autumn-Themed-Digital-Painting-Studies-with-Maddy-Bellwoar.mp4: Invalid data found when processing input

----------------------------------------------------------
https://www.behance.net/videos/632fffaf-f8ae-4c75-bcaf-91ea4f8ddfb6/Daily-Projects-with-Klarens-Malluta.mp4
Traceback (most recent call last):
  File "/home/saransh03sharma/.local/lib/python3.10/site-packages/moviepy/video/io/ffmpeg_reader.py", line 285, in ffmpeg_parse_infos
    line = [l for l in lines if keyword in l][index]
IndexError: list index out of range

During handling of the above exception, another exception occurred:

Traceback (most recent call last):
  File "/home/saransh03sharma/Documents/GitHub/VideoIntentDiscovery/scripts/download_videos.py", line 49, in get_slices
    video = VideoFileClip(tmp_name)
  File "/home/saransh03sharma/.local/lib/python3.10/site-packages/moviepy/video/io/VideoFileClip.py", line 88, in __init__
    self.reader = FFMPEG_VideoReader(filename, pix_fmt=pix_fmt,
  File "/home/saransh03sharma/.local/lib/python3.10/site-packages/moviepy/video/io/ffmpeg_reader.py", line 35, in __init__
    infos = ffmpeg_parse_infos(filename, print_infos, check_duration,
  File "/home/saransh03sharma/.local/lib/python3.10/site-packages/moviepy/video/io/ffmpeg_reader.py", line 289, in ffmpeg_parse_infos
    raise IOError(("MoviePy error: failed to read the duration of file %s.\n"
OSError: MoviePy error: failed to read the duration of file ../data/bid/video/https:____www.behance.net__videos__632fffaf-f8ae-4c75-bcaf-91ea4f8ddfb6__Daily-Projects-with-Klarens-Malluta.mp4.
Here are the file infos returned by ffmpeg:

ffmpeg version 4.2.2-static https://johnvansickle.com/ffmpeg/  Copyright (c) 2000-2019 the FFmpeg developers
  built with gcc 8 (Debian 8.3.0-6)
  configuration: --enable-gpl --enable-version3 --enable-static --disable-debug --disable-ffplay --disable-indev=sndio --disable-outdev=sndio --cc=gcc --enable-fontconfig --enable-frei0r --enable-gnutls --enable-gmp --enable-libgme --enable-gray --enable-libaom --enable-libfribidi --enable-libass --enable-libvmaf --enable-libfreetype --enable-libmp3lame --enable-libopencore-amrnb --enable-libopencore-amrwb --enable-libopenjpeg --enable-librubberband --enable-libsoxr --enable-libspeex --enable-libsrt --enable-libvorbis --enable-libopus --enable-libtheora --enable-libvidstab --enable-libvo-amrwbenc --enable-libvpx --enable-libwebp --enable-libx264 --enable-libx265 --enable-libxml2 --enable-libdav1d --enable-libxvid --enable-libzvbi --enable-libzimg
  libavutil      56. 31.100 / 56. 31.100
  libavcodec     58. 54.100 / 58. 54.100
  libavformat    58. 29.100 / 58. 29.100
  libavdevice    58.  8.100 / 58.  8.100
  libavfilter     7. 57.100 /  7. 57.100
  libswscale      5.  5.100 /  5.  5.100
  libswresample   3.  5.100 /  3.  5.100
  libpostproc    55.  5.100 / 55.  5.100
[mov,mp4,m4a,3gp,3g2,mj2 @ 0x5891500] Format mov,mp4,m4a,3gp,3g2,mj2 detected only with low score of 1, misdetection possible!
[mov,mp4,m4a,3gp,3g2,mj2 @ 0x5891500] moov atom not found
../data/bid/video/https:____www.behance.net__videos__632fffaf-f8ae-4c75-bcaf-91ea4f8ddfb6__Daily-Projects-with-Klarens-Malluta.mp4: Invalid data found when processing input

----------------------------------------------------------
https://www.behance.net/videos/37aec988-de9b-4bf9-941e-947c4b7406e2/Virtual-Plein-Air-Sketch-Studies-with-Maddy-Bellwoar.mp4
Traceback (most recent call last):
  File "/home/saransh03sharma/.local/lib/python3.10/site-packages/moviepy/video/io/ffmpeg_reader.py", line 285, in ffmpeg_parse_infos
    line = [l for l in lines if keyword in l][index]
IndexError: list index out of range

During handling of the above exception, another exception occurred:

Traceback (most recent call last):
  File "/home/saransh03sharma/Documents/GitHub/VideoIntentDiscovery/scripts/download_videos.py", line 49, in get_slices
    video = VideoFileClip(tmp_name)
  File "/home/saransh03sharma/.local/lib/python3.10/site-packages/moviepy/video/io/VideoFileClip.py", line 88, in __init__
    self.reader = FFMPEG_VideoReader(filename, pix_fmt=pix_fmt,
  File "/home/saransh03sharma/.local/lib/python3.10/site-packages/moviepy/video/io/ffmpeg_reader.py", line 35, in __init__
    infos = ffmpeg_parse_infos(filename, print_infos, check_duration,
  File "/home/saransh03sharma/.local/lib/python3.10/site-packages/moviepy/video/io/ffmpeg_reader.py", line 289, in ffmpeg_parse_infos
    raise IOError(("MoviePy error: failed to read the duration of file %s.\n"
OSError: MoviePy error: failed to read the duration of file ../data/bid/video/https:____www.behance.net__videos__37aec988-de9b-4bf9-941e-947c4b7406e2__Virtual-Plein-Air-Sketch-Studies-with-Maddy-Bellwoar.mp4.
Here are the file infos returned by ffmpeg:

ffmpeg version 4.2.2-static https://johnvansickle.com/ffmpeg/  Copyright (c) 2000-2019 the FFmpeg developers
  built with gcc 8 (Debian 8.3.0-6)
  configuration: --enable-gpl --enable-version3 --enable-static --disable-debug --disable-ffplay --disable-indev=sndio --disable-outdev=sndio --cc=gcc --enable-fontconfig --enable-frei0r --enable-gnutls --enable-gmp --enable-libgme --enable-gray --enable-libaom --enable-libfribidi --enable-libass --enable-libvmaf --enable-libfreetype --enable-libmp3lame --enable-libopencore-amrnb --enable-libopencore-amrwb --enable-libopenjpeg --enable-librubberband --enable-libsoxr --enable-libspeex --enable-libsrt --enable-libvorbis --enable-libopus --enable-libtheora --enable-libvidstab --enable-libvo-amrwbenc --enable-libvpx --enable-libwebp --enable-libx264 --enable-libx265 --enable-libxml2 --enable-libdav1d --enable-libxvid --enable-libzvbi --enable-libzimg
  libavutil      56. 31.100 / 56. 31.100
  libavcodec     58. 54.100 / 58. 54.100
  libavformat    58. 29.100 / 58. 29.100
  libavdevice    58.  8.100 / 58.  8.100
  libavfilter     7. 57.100 /  7. 57.100
  libswscale      5.  5.100 /  5.  5.100
  libswresample   3.  5.100 /  3.  5.100
  libpostproc    55.  5.100 / 55.  5.100
[mov,mp4,m4a,3gp,3g2,mj2 @ 0x6618500] Format mov,mp4,m4a,3gp,3g2,mj2 detected only with low score of 1, misdetection possible!
[mov,mp4,m4a,3gp,3g2,mj2 @ 0x6618500] moov atom not found
../data/bid/video/https:____www.behance.net__videos__37aec988-de9b-4bf9-941e-947c4b7406e2__Virtual-Plein-Air-Sketch-Studies-with-Maddy-Bellwoar.mp4: Invalid data found when processing input

----------------------------------------------------------
https://www.behance.net/videos/b7f29dd7-7d9f-435f-8b3c-bcdb8e0202b9/Creature-Character-Concepts-with-2SL.mp4
Traceback (most recent call last):
  File "/home/saransh03sharma/.local/lib/python3.10/site-packages/moviepy/video/io/ffmpeg_reader.py", line 285, in ffmpeg_parse_infos
    line = [l for l in lines if keyword in l][index]
IndexError: list index out of range

During handling of the above exception, another exception occurred:

Traceback (most recent call last):
  File "/home/saransh03sharma/Documents/GitHub/VideoIntentDiscovery/scripts/download_videos.py", line 49, in get_slices
    video = VideoFileClip(tmp_name)
  File "/home/saransh03sharma/.local/lib/python3.10/site-packages/moviepy/video/io/VideoFileClip.py", line 88, in __init__
    self.reader = FFMPEG_VideoReader(filename, pix_fmt=pix_fmt,
  File "/home/saransh03sharma/.local/lib/python3.10/site-packages/moviepy/video/io/ffmpeg_reader.py", line 35, in __init__
    infos = ffmpeg_parse_infos(filename, print_infos, check_duration,
  File "/home/saransh03sharma/.local/lib/python3.10/site-packages/moviepy/video/io/ffmpeg_reader.py", line 289, in ffmpeg_parse_infos
    raise IOError(("MoviePy error: failed to read the duration of file %s.\n"
OSError: MoviePy error: failed to read the duration of file ../data/bid/video/https:____www.behance.net__videos__b7f29dd7-7d9f-435f-8b3c-bcdb8e0202b9__Creature-Character-Concepts-with-2SL.mp4.
Here are the file infos returned by ffmpeg:

ffmpeg version 4.2.2-static https://johnvansickle.com/ffmpeg/  Copyright (c) 2000-2019 the FFmpeg developers
  built with gcc 8 (Debian 8.3.0-6)
  configuration: --enable-gpl --enable-version3 --enable-static --disable-debug --disable-ffplay --disable-indev=sndio --disable-outdev=sndio --cc=gcc --enable-fontconfig --enable-frei0r --enable-gnutls --enable-gmp --enable-libgme --enable-gray --enable-libaom --enable-libfribidi --enable-libass --enable-libvmaf --enable-libfreetype --enable-libmp3lame --enable-libopencore-amrnb --enable-libopencore-amrwb --enable-libopenjpeg --enable-librubberband --enable-libsoxr --enable-libspeex --enable-libsrt --enable-libvorbis --enable-libopus --enable-libtheora --enable-libvidstab --enable-libvo-amrwbenc --enable-libvpx --enable-libwebp --enable-libx264 --enable-libx265 --enable-libxml2 --enable-libdav1d --enable-libxvid --enable-libzvbi --enable-libzimg
  libavutil      56. 31.100 / 56. 31.100
  libavcodec     58. 54.100 / 58. 54.100
  libavformat    58. 29.100 / 58. 29.100
  libavdevice    58.  8.100 / 58.  8.100
  libavfilter     7. 57.100 /  7. 57.100
  libswscale      5.  5.100 /  5.  5.100
  libswresample   3.  5.100 /  3.  5.100
  libpostproc    55.  5.100 / 55.  5.100
[mov,mp4,m4a,3gp,3g2,mj2 @ 0x5a3a500] Format mov,mp4,m4a,3gp,3g2,mj2 detected only with low score of 1, misdetection possible!
[mov,mp4,m4a,3gp,3g2,mj2 @ 0x5a3a500] moov atom not found
../data/bid/video/https:____www.behance.net__videos__b7f29dd7-7d9f-435f-8b3c-bcdb8e0202b9__Creature-Character-Concepts-with-2SL.mp4: Invalid data found when processing input

----------------------------------------------------------
https://www.behance.net/videos/c147bd15-2e4a-4205-9bb3-25133826df6a/Shilin-chipping-away-a-painting.mp4
Traceback (most recent call last):
  File "/home/saransh03sharma/.local/lib/python3.10/site-packages/moviepy/video/io/ffmpeg_reader.py", line 285, in ffmpeg_parse_infos
    line = [l for l in lines if keyword in l][index]
IndexError: list index out of range

During handling of the above exception, another exception occurred:

Traceback (most recent call last):
  File "/home/saransh03sharma/Documents/GitHub/VideoIntentDiscovery/scripts/download_videos.py", line 49, in get_slices
    video = VideoFileClip(tmp_name)
  File "/home/saransh03sharma/.local/lib/python3.10/site-packages/moviepy/video/io/VideoFileClip.py", line 88, in __init__
    self.reader = FFMPEG_VideoReader(filename, pix_fmt=pix_fmt,
  File "/home/saransh03sharma/.local/lib/python3.10/site-packages/moviepy/video/io/ffmpeg_reader.py", line 35, in __init__
    infos = ffmpeg_parse_infos(filename, print_infos, check_duration,
  File "/home/saransh03sharma/.local/lib/python3.10/site-packages/moviepy/video/io/ffmpeg_reader.py", line 289, in ffmpeg_parse_infos
    raise IOError(("MoviePy error: failed to read the duration of file %s.\n"
OSError: MoviePy error: failed to read the duration of file ../data/bid/video/https:____www.behance.net__videos__c147bd15-2e4a-4205-9bb3-25133826df6a__Shilin-chipping-away-a-painting.mp4.
Here are the file infos returned by ffmpeg:

ffmpeg version 4.2.2-static https://johnvansickle.com/ffmpeg/  Copyright (c) 2000-2019 the FFmpeg developers
  built with gcc 8 (Debian 8.3.0-6)
  configuration: --enable-gpl --enable-version3 --enable-static --disable-debug --disable-ffplay --disable-indev=sndio --disable-outdev=sndio --cc=gcc --enable-fontconfig --enable-frei0r --enable-gnutls --enable-gmp --enable-libgme --enable-gray --enable-libaom --enable-libfribidi --enable-libass --enable-libvmaf --enable-libfreetype --enable-libmp3lame --enable-libopencore-amrnb --enable-libopencore-amrwb --enable-libopenjpeg --enable-librubberband --enable-libsoxr --enable-libspeex --enable-libsrt --enable-libvorbis --enable-libopus --enable-libtheora --enable-libvidstab --enable-libvo-amrwbenc --enable-libvpx --enable-libwebp --enable-libx264 --enable-libx265 --enable-libxml2 --enable-libdav1d --enable-libxvid --enable-libzvbi --enable-libzimg
  libavutil      56. 31.100 / 56. 31.100
  libavcodec     58. 54.100 / 58. 54.100
  libavformat    58. 29.100 / 58. 29.100
  libavdevice    58.  8.100 / 58.  8.100
  libavfilter     7. 57.100 /  7. 57.100
  libswscale      5.  5.100 /  5.  5.100
  libswresample   3.  5.100 /  3.  5.100
  libpostproc    55.  5.100 / 55.  5.100
[mov,mp4,m4a,3gp,3g2,mj2 @ 0x5990500] Format mov,mp4,m4a,3gp,3g2,mj2 detected only with low score of 1, misdetection possible!
[mov,mp4,m4a,3gp,3g2,mj2 @ 0x5990500] moov atom not found
../data/bid/video/https:____www.behance.net__videos__c147bd15-2e4a-4205-9bb3-25133826df6a__Shilin-chipping-away-a-painting.mp4: Invalid data found when processing input

----------------------------------------------------------
https://www.behance.net/videos/https://www.behance.net/videos/b7f29dd7-7d9f-435f-8b3c-bcdb8e0202b9/Creature-Character-Concepts-with-2SL.mp4
Traceback (most recent call last):
  File "/home/saransh03sharma/.local/lib/python3.10/site-packages/youtube_dl/YoutubeDL.py", line 815, in wrapper
    return func(self, *args, **kwargs)
  File "/home/saransh03sharma/.local/lib/python3.10/site-packages/youtube_dl/YoutubeDL.py", line 836, in __extract_info
    ie_result = ie.extract(url)
  File "/home/saransh03sharma/.local/lib/python3.10/site-packages/youtube_dl/extractor/common.py", line 534, in extract
    ie_result = self._real_extract(url)
  File "/home/saransh03sharma/.local/lib/python3.10/site-packages/youtube_dl/extractor/generic.py", line 3489, in _real_extract
    raise UnsupportedError(url)
youtube_dl.utils.UnsupportedError: Unsupported URL: https://www.behance.net/videos/https://www.behance.net/videos/b7f29dd7-7d9f-435f-8b3c-bcdb8e0202b9/Creature-Character-Concepts-with-2SL.mp4

During handling of the above exception, another exception occurred:

Traceback (most recent call last):
  File "/home/saransh03sharma/Documents/GitHub/VideoIntentDiscovery/scripts/download_videos.py", line 51, in get_slices
    download_video_with_youtube_dl(url, tmp_name)
  File "/home/saransh03sharma/Documents/GitHub/VideoIntentDiscovery/scripts/download_videos.py", line 43, in download_video_with_youtube_dl
    ydl.download([url])
  File "/home/saransh03sharma/.local/lib/python3.10/site-packages/youtube_dl/YoutubeDL.py", line 2068, in download
    res = self.extract_info(
  File "/home/saransh03sharma/.local/lib/python3.10/site-packages/youtube_dl/YoutubeDL.py", line 808, in extract_info
    return self.__extract_info(url, ie, download, extra_info, process)
  File "/home/saransh03sharma/.local/lib/python3.10/site-packages/youtube_dl/YoutubeDL.py", line 824, in wrapper
    self.report_error(compat_str(e), e.format_traceback())
  File "/home/saransh03sharma/.local/lib/python3.10/site-packages/youtube_dl/YoutubeDL.py", line 628, in report_error
    self.trouble(error_message, tb)
  File "/home/saransh03sharma/.local/lib/python3.10/site-packages/youtube_dl/YoutubeDL.py", line 598, in trouble
    raise DownloadError(message, exc_info)
youtube_dl.utils.DownloadError: [0;31mERROR:[0m Unsupported URL: https://www.behance.net/videos/https://www.behance.net/videos/b7f29dd7-7d9f-435f-8b3c-bcdb8e0202b9/Creature-Character-Concepts-with-2SL.mp4
----------------------------------------------------------
https://www.behance.net/videos/https://livestream-videos-prod.s3-us-west-2.amazonaws.com/stream-a63533e0-6413-4f51-9841-6bee342141b1-s3.mp4.mp4
Traceback (most recent call last):
  File "/home/saransh03sharma/.local/lib/python3.10/site-packages/youtube_dl/YoutubeDL.py", line 815, in wrapper
    return func(self, *args, **kwargs)
  File "/home/saransh03sharma/.local/lib/python3.10/site-packages/youtube_dl/YoutubeDL.py", line 836, in __extract_info
    ie_result = ie.extract(url)
  File "/home/saransh03sharma/.local/lib/python3.10/site-packages/youtube_dl/extractor/common.py", line 534, in extract
    ie_result = self._real_extract(url)
  File "/home/saransh03sharma/.local/lib/python3.10/site-packages/youtube_dl/extractor/generic.py", line 3489, in _real_extract
    raise UnsupportedError(url)
youtube_dl.utils.UnsupportedError: Unsupported URL: https://www.behance.net/videos/https://livestream-videos-prod.s3-us-west-2.amazonaws.com/stream-a63533e0-6413-4f51-9841-6bee342141b1-s3.mp4.mp4

During handling of the above exception, another exception occurred:

Traceback (most recent call last):
  File "/home/saransh03sharma/Documents/GitHub/VideoIntentDiscovery/scripts/download_videos.py", line 51, in get_slices
    download_video_with_youtube_dl(url, tmp_name)
  File "/home/saransh03sharma/Documents/GitHub/VideoIntentDiscovery/scripts/download_videos.py", line 43, in download_video_with_youtube_dl
    ydl.download([url])
  File "/home/saransh03sharma/.local/lib/python3.10/site-packages/youtube_dl/YoutubeDL.py", line 2068, in download
    res = self.extract_info(
  File "/home/saransh03sharma/.local/lib/python3.10/site-packages/youtube_dl/YoutubeDL.py", line 808, in extract_info
    return self.__extract_info(url, ie, download, extra_info, process)
  File "/home/saransh03sharma/.local/lib/python3.10/site-packages/youtube_dl/YoutubeDL.py", line 824, in wrapper
    self.report_error(compat_str(e), e.format_traceback())
  File "/home/saransh03sharma/.local/lib/python3.10/site-packages/youtube_dl/YoutubeDL.py", line 628, in report_error
    self.trouble(error_message, tb)
  File "/home/saransh03sharma/.local/lib/python3.10/site-packages/youtube_dl/YoutubeDL.py", line 598, in trouble
    raise DownloadError(message, exc_info)
youtube_dl.utils.DownloadError: [0;31mERROR:[0m Unsupported URL: https://www.behance.net/videos/https://livestream-videos-prod.s3-us-west-2.amazonaws.com/stream-a63533e0-6413-4f51-9841-6bee342141b1-s3.mp4.mp4
----------------------------------------------------------
https://www.behance.net/videos/https://www.behance.net/videos/37aec988-de9b-4bf9-941e-947c4b7406e2/Virtual-Plein-Air-Sketch-Studies-with-Maddy-Bellwoar.mp4
Traceback (most recent call last):
  File "/home/saransh03sharma/.local/lib/python3.10/site-packages/youtube_dl/YoutubeDL.py", line 815, in wrapper
    return func(self, *args, **kwargs)
  File "/home/saransh03sharma/.local/lib/python3.10/site-packages/youtube_dl/YoutubeDL.py", line 836, in __extract_info
    ie_result = ie.extract(url)
  File "/home/saransh03sharma/.local/lib/python3.10/site-packages/youtube_dl/extractor/common.py", line 534, in extract
    ie_result = self._real_extract(url)
  File "/home/saransh03sharma/.local/lib/python3.10/site-packages/youtube_dl/extractor/generic.py", line 3489, in _real_extract
    raise UnsupportedError(url)
youtube_dl.utils.UnsupportedError: Unsupported URL: https://www.behance.net/videos/https://www.behance.net/videos/37aec988-de9b-4bf9-941e-947c4b7406e2/Virtual-Plein-Air-Sketch-Studies-with-Maddy-Bellwoar.mp4

During handling of the above exception, another exception occurred:

Traceback (most recent call last):
  File "/home/saransh03sharma/Documents/GitHub/VideoIntentDiscovery/scripts/download_videos.py", line 51, in get_slices
    download_video_with_youtube_dl(url, tmp_name)
  File "/home/saransh03sharma/Documents/GitHub/VideoIntentDiscovery/scripts/download_videos.py", line 43, in download_video_with_youtube_dl
    ydl.download([url])
  File "/home/saransh03sharma/.local/lib/python3.10/site-packages/youtube_dl/YoutubeDL.py", line 2068, in download
    res = self.extract_info(
  File "/home/saransh03sharma/.local/lib/python3.10/site-packages/youtube_dl/YoutubeDL.py", line 808, in extract_info
    return self.__extract_info(url, ie, download, extra_info, process)
  File "/home/saransh03sharma/.local/lib/python3.10/site-packages/youtube_dl/YoutubeDL.py", line 824, in wrapper
    self.report_error(compat_str(e), e.format_traceback())
  File "/home/saransh03sharma/.local/lib/python3.10/site-packages/youtube_dl/YoutubeDL.py", line 628, in report_error
    self.trouble(error_message, tb)
  File "/home/saransh03sharma/.local/lib/python3.10/site-packages/youtube_dl/YoutubeDL.py", line 598, in trouble
    raise DownloadError(message, exc_info)
youtube_dl.utils.DownloadError: [0;31mERROR:[0m Unsupported URL: https://www.behance.net/videos/https://www.behance.net/videos/37aec988-de9b-4bf9-941e-947c4b7406e2/Virtual-Plein-Air-Sketch-Studies-with-Maddy-Bellwoar.mp4
----------------------------------------------------------
https://www.behance.net/videos/https://livestream-videos-prod.s3-us-west-2.amazonaws.com/stream-563baf94-84dd-47b2-84f6-4971634cda32-s3.mp4.mp4
Traceback (most recent call last):
  File "/home/saransh03sharma/.local/lib/python3.10/site-packages/youtube_dl/YoutubeDL.py", line 815, in wrapper
    return func(self, *args, **kwargs)
  File "/home/saransh03sharma/.local/lib/python3.10/site-packages/youtube_dl/YoutubeDL.py", line 836, in __extract_info
    ie_result = ie.extract(url)
  File "/home/saransh03sharma/.local/lib/python3.10/site-packages/youtube_dl/extractor/common.py", line 534, in extract
    ie_result = self._real_extract(url)
  File "/home/saransh03sharma/.local/lib/python3.10/site-packages/youtube_dl/extractor/generic.py", line 3489, in _real_extract
    raise UnsupportedError(url)
youtube_dl.utils.UnsupportedError: Unsupported URL: https://www.behance.net/videos/https://livestream-videos-prod.s3-us-west-2.amazonaws.com/stream-563baf94-84dd-47b2-84f6-4971634cda32-s3.mp4.mp4

During handling of the above exception, another exception occurred:

Traceback (most recent call last):
  File "/home/saransh03sharma/Documents/GitHub/VideoIntentDiscovery/scripts/download_videos.py", line 51, in get_slices
    download_video_with_youtube_dl(url, tmp_name)
  File "/home/saransh03sharma/Documents/GitHub/VideoIntentDiscovery/scripts/download_videos.py", line 43, in download_video_with_youtube_dl
    ydl.download([url])
  File "/home/saransh03sharma/.local/lib/python3.10/site-packages/youtube_dl/YoutubeDL.py", line 2068, in download
    res = self.extract_info(
  File "/home/saransh03sharma/.local/lib/python3.10/site-packages/youtube_dl/YoutubeDL.py", line 808, in extract_info
    return self.__extract_info(url, ie, download, extra_info, process)
  File "/home/saransh03sharma/.local/lib/python3.10/site-packages/youtube_dl/YoutubeDL.py", line 824, in wrapper
    self.report_error(compat_str(e), e.format_traceback())
  File "/home/saransh03sharma/.local/lib/python3.10/site-packages/youtube_dl/YoutubeDL.py", line 628, in report_error
    self.trouble(error_message, tb)
  File "/home/saransh03sharma/.local/lib/python3.10/site-packages/youtube_dl/YoutubeDL.py", line 598, in trouble
    raise DownloadError(message, exc_info)
youtube_dl.utils.DownloadError: [0;31mERROR:[0m Unsupported URL: https://www.behance.net/videos/https://livestream-videos-prod.s3-us-west-2.amazonaws.com/stream-563baf94-84dd-47b2-84f6-4971634cda32-s3.mp4.mp4
----------------------------------------------------------
https://www.behance.net/videos/https://www.behance.net/videos/f83ea5f3-dcc8-47c0-ab75-50b489538348/Autumn-Themed-Digital-Painting-Studies-with-Maddy-Bellwoar.mp4
Traceback (most recent call last):
  File "/home/saransh03sharma/.local/lib/python3.10/site-packages/youtube_dl/YoutubeDL.py", line 815, in wrapper
    return func(self, *args, **kwargs)
  File "/home/saransh03sharma/.local/lib/python3.10/site-packages/youtube_dl/YoutubeDL.py", line 836, in __extract_info
    ie_result = ie.extract(url)
  File "/home/saransh03sharma/.local/lib/python3.10/site-packages/youtube_dl/extractor/common.py", line 534, in extract
    ie_result = self._real_extract(url)
  File "/home/saransh03sharma/.local/lib/python3.10/site-packages/youtube_dl/extractor/generic.py", line 3489, in _real_extract
    raise UnsupportedError(url)
youtube_dl.utils.UnsupportedError: Unsupported URL: https://www.behance.net/videos/https://www.behance.net/videos/f83ea5f3-dcc8-47c0-ab75-50b489538348/Autumn-Themed-Digital-Painting-Studies-with-Maddy-Bellwoar.mp4

During handling of the above exception, another exception occurred:

Traceback (most recent call last):
  File "/home/saransh03sharma/Documents/GitHub/VideoIntentDiscovery/scripts/download_videos.py", line 51, in get_slices
    download_video_with_youtube_dl(url, tmp_name)
  File "/home/saransh03sharma/Documents/GitHub/VideoIntentDiscovery/scripts/download_videos.py", line 43, in download_video_with_youtube_dl
    ydl.download([url])
  File "/home/saransh03sharma/.local/lib/python3.10/site-packages/youtube_dl/YoutubeDL.py", line 2068, in download
    res = self.extract_info(
  File "/home/saransh03sharma/.local/lib/python3.10/site-packages/youtube_dl/YoutubeDL.py", line 808, in extract_info
    return self.__extract_info(url, ie, download, extra_info, process)
  File "/home/saransh03sharma/.local/lib/python3.10/site-packages/youtube_dl/YoutubeDL.py", line 824, in wrapper
    self.report_error(compat_str(e), e.format_traceback())
  File "/home/saransh03sharma/.local/lib/python3.10/site-packages/youtube_dl/YoutubeDL.py", line 628, in report_error
    self.trouble(error_message, tb)
  File "/home/saransh03sharma/.local/lib/python3.10/site-packages/youtube_dl/YoutubeDL.py", line 598, in trouble
    raise DownloadError(message, exc_info)
youtube_dl.utils.DownloadError: [0;31mERROR:[0m Unsupported URL: https://www.behance.net/videos/https://www.behance.net/videos/f83ea5f3-dcc8-47c0-ab75-50b489538348/Autumn-Themed-Digital-Painting-Studies-with-Maddy-Bellwoar.mp4
----------------------------------------------------------
https://www.behance.net/videos/https://www.behance.net/videos/c147bd15-2e4a-4205-9bb3-25133826df6a/Shilin-chipping-away-a-painting.mp4
Traceback (most recent call last):
  File "/home/saransh03sharma/.local/lib/python3.10/site-packages/youtube_dl/YoutubeDL.py", line 815, in wrapper
    return func(self, *args, **kwargs)
  File "/home/saransh03sharma/.local/lib/python3.10/site-packages/youtube_dl/YoutubeDL.py", line 836, in __extract_info
    ie_result = ie.extract(url)
  File "/home/saransh03sharma/.local/lib/python3.10/site-packages/youtube_dl/extractor/common.py", line 534, in extract
    ie_result = self._real_extract(url)
  File "/home/saransh03sharma/.local/lib/python3.10/site-packages/youtube_dl/extractor/generic.py", line 3489, in _real_extract
    raise UnsupportedError(url)
youtube_dl.utils.UnsupportedError: Unsupported URL: https://www.behance.net/videos/https://www.behance.net/videos/c147bd15-2e4a-4205-9bb3-25133826df6a/Shilin-chipping-away-a-painting.mp4

During handling of the above exception, another exception occurred:

Traceback (most recent call last):
  File "/home/saransh03sharma/Documents/GitHub/VideoIntentDiscovery/scripts/download_videos.py", line 51, in get_slices
    download_video_with_youtube_dl(url, tmp_name)
  File "/home/saransh03sharma/Documents/GitHub/VideoIntentDiscovery/scripts/download_videos.py", line 43, in download_video_with_youtube_dl
    ydl.download([url])
  File "/home/saransh03sharma/.local/lib/python3.10/site-packages/youtube_dl/YoutubeDL.py", line 2068, in download
    res = self.extract_info(
  File "/home/saransh03sharma/.local/lib/python3.10/site-packages/youtube_dl/YoutubeDL.py", line 808, in extract_info
    return self.__extract_info(url, ie, download, extra_info, process)
  File "/home/saransh03sharma/.local/lib/python3.10/site-packages/youtube_dl/YoutubeDL.py", line 824, in wrapper
    self.report_error(compat_str(e), e.format_traceback())
  File "/home/saransh03sharma/.local/lib/python3.10/site-packages/youtube_dl/YoutubeDL.py", line 628, in report_error
    self.trouble(error_message, tb)
  File "/home/saransh03sharma/.local/lib/python3.10/site-packages/youtube_dl/YoutubeDL.py", line 598, in trouble
    raise DownloadError(message, exc_info)
youtube_dl.utils.DownloadError: [0;31mERROR:[0m Unsupported URL: https://www.behance.net/videos/https://www.behance.net/videos/c147bd15-2e4a-4205-9bb3-25133826df6a/Shilin-chipping-away-a-painting.mp4
----------------------------------------------------------
https://www.behance.net/videos/https://livestream-videos-prod.s3-us-west-2.amazonaws.com/stream-e191c578-475d-4d7c-8693-a214544f5bba-s3.mp4.mp4
Traceback (most recent call last):
  File "/home/saransh03sharma/.local/lib/python3.10/site-packages/youtube_dl/YoutubeDL.py", line 815, in wrapper
    return func(self, *args, **kwargs)
  File "/home/saransh03sharma/.local/lib/python3.10/site-packages/youtube_dl/YoutubeDL.py", line 836, in __extract_info
    ie_result = ie.extract(url)
  File "/home/saransh03sharma/.local/lib/python3.10/site-packages/youtube_dl/extractor/common.py", line 534, in extract
    ie_result = self._real_extract(url)
  File "/home/saransh03sharma/.local/lib/python3.10/site-packages/youtube_dl/extractor/generic.py", line 3489, in _real_extract
    raise UnsupportedError(url)
youtube_dl.utils.UnsupportedError: Unsupported URL: https://www.behance.net/videos/https://livestream-videos-prod.s3-us-west-2.amazonaws.com/stream-e191c578-475d-4d7c-8693-a214544f5bba-s3.mp4.mp4

During handling of the above exception, another exception occurred:

Traceback (most recent call last):
  File "/home/saransh03sharma/Documents/GitHub/VideoIntentDiscovery/scripts/download_videos.py", line 51, in get_slices
    download_video_with_youtube_dl(url, tmp_name)
  File "/home/saransh03sharma/Documents/GitHub/VideoIntentDiscovery/scripts/download_videos.py", line 43, in download_video_with_youtube_dl
    ydl.download([url])
  File "/home/saransh03sharma/.local/lib/python3.10/site-packages/youtube_dl/YoutubeDL.py", line 2068, in download
    res = self.extract_info(
  File "/home/saransh03sharma/.local/lib/python3.10/site-packages/youtube_dl/YoutubeDL.py", line 808, in extract_info
    return self.__extract_info(url, ie, download, extra_info, process)
  File "/home/saransh03sharma/.local/lib/python3.10/site-packages/youtube_dl/YoutubeDL.py", line 824, in wrapper
    self.report_error(compat_str(e), e.format_traceback())
  File "/home/saransh03sharma/.local/lib/python3.10/site-packages/youtube_dl/YoutubeDL.py", line 628, in report_error
    self.trouble(error_message, tb)
  File "/home/saransh03sharma/.local/lib/python3.10/site-packages/youtube_dl/YoutubeDL.py", line 598, in trouble
    raise DownloadError(message, exc_info)
youtube_dl.utils.DownloadError: [0;31mERROR:[0m Unsupported URL: https://www.behance.net/videos/https://livestream-videos-prod.s3-us-west-2.amazonaws.com/stream-e191c578-475d-4d7c-8693-a214544f5bba-s3.mp4.mp4
----------------------------------------------------------
https://www.behance.net/videos/https://www.behance.net/videos/632fffaf-f8ae-4c75-bcaf-91ea4f8ddfb6/Daily-Projects-with-Klarens-Malluta.mp4
Traceback (most recent call last):
  File "/home/saransh03sharma/.local/lib/python3.10/site-packages/youtube_dl/YoutubeDL.py", line 815, in wrapper
    return func(self, *args, **kwargs)
  File "/home/saransh03sharma/.local/lib/python3.10/site-packages/youtube_dl/YoutubeDL.py", line 836, in __extract_info
    ie_result = ie.extract(url)
  File "/home/saransh03sharma/.local/lib/python3.10/site-packages/youtube_dl/extractor/common.py", line 534, in extract
    ie_result = self._real_extract(url)
  File "/home/saransh03sharma/.local/lib/python3.10/site-packages/youtube_dl/extractor/generic.py", line 3489, in _real_extract
    raise UnsupportedError(url)
youtube_dl.utils.UnsupportedError: Unsupported URL: https://www.behance.net/videos/https://www.behance.net/videos/632fffaf-f8ae-4c75-bcaf-91ea4f8ddfb6/Daily-Projects-with-Klarens-Malluta.mp4

During handling of the above exception, another exception occurred:

Traceback (most recent call last):
  File "/home/saransh03sharma/Documents/GitHub/VideoIntentDiscovery/scripts/download_videos.py", line 51, in get_slices
    download_video_with_youtube_dl(url, tmp_name)
  File "/home/saransh03sharma/Documents/GitHub/VideoIntentDiscovery/scripts/download_videos.py", line 43, in download_video_with_youtube_dl
    ydl.download([url])
  File "/home/saransh03sharma/.local/lib/python3.10/site-packages/youtube_dl/YoutubeDL.py", line 2068, in download
    res = self.extract_info(
  File "/home/saransh03sharma/.local/lib/python3.10/site-packages/youtube_dl/YoutubeDL.py", line 808, in extract_info
    return self.__extract_info(url, ie, download, extra_info, process)
  File "/home/saransh03sharma/.local/lib/python3.10/site-packages/youtube_dl/YoutubeDL.py", line 824, in wrapper
    self.report_error(compat_str(e), e.format_traceback())
  File "/home/saransh03sharma/.local/lib/python3.10/site-packages/youtube_dl/YoutubeDL.py", line 628, in report_error
    self.trouble(error_message, tb)
  File "/home/saransh03sharma/.local/lib/python3.10/site-packages/youtube_dl/YoutubeDL.py", line 598, in trouble
    raise DownloadError(message, exc_info)
youtube_dl.utils.DownloadError: [0;31mERROR:[0m Unsupported URL: https://www.behance.net/videos/https://www.behance.net/videos/632fffaf-f8ae-4c75-bcaf-91ea4f8ddfb6/Daily-Projects-with-Klarens-Malluta.mp4
----------------------------------------------------------
https://www.behance.net/videos/https://livestream-videos-prod.s3-us-west-2.amazonaws.com/stream-4e565236-cdf2-4d2f-907d-70ff3cf447ba-s3.mp4.mp4
Traceback (most recent call last):
  File "/home/saransh03sharma/.local/lib/python3.10/site-packages/youtube_dl/YoutubeDL.py", line 815, in wrapper
    return func(self, *args, **kwargs)
  File "/home/saransh03sharma/.local/lib/python3.10/site-packages/youtube_dl/YoutubeDL.py", line 836, in __extract_info
    ie_result = ie.extract(url)
  File "/home/saransh03sharma/.local/lib/python3.10/site-packages/youtube_dl/extractor/common.py", line 534, in extract
    ie_result = self._real_extract(url)
  File "/home/saransh03sharma/.local/lib/python3.10/site-packages/youtube_dl/extractor/generic.py", line 3489, in _real_extract
    raise UnsupportedError(url)
youtube_dl.utils.UnsupportedError: Unsupported URL: https://www.behance.net/videos/https://livestream-videos-prod.s3-us-west-2.amazonaws.com/stream-4e565236-cdf2-4d2f-907d-70ff3cf447ba-s3.mp4.mp4

During handling of the above exception, another exception occurred:

Traceback (most recent call last):
  File "/home/saransh03sharma/Documents/GitHub/VideoIntentDiscovery/scripts/download_videos.py", line 51, in get_slices
    download_video_with_youtube_dl(url, tmp_name)
  File "/home/saransh03sharma/Documents/GitHub/VideoIntentDiscovery/scripts/download_videos.py", line 43, in download_video_with_youtube_dl
    ydl.download([url])
  File "/home/saransh03sharma/.local/lib/python3.10/site-packages/youtube_dl/YoutubeDL.py", line 2068, in download
    res = self.extract_info(
  File "/home/saransh03sharma/.local/lib/python3.10/site-packages/youtube_dl/YoutubeDL.py", line 808, in extract_info
    return self.__extract_info(url, ie, download, extra_info, process)
  File "/home/saransh03sharma/.local/lib/python3.10/site-packages/youtube_dl/YoutubeDL.py", line 824, in wrapper
    self.report_error(compat_str(e), e.format_traceback())
  File "/home/saransh03sharma/.local/lib/python3.10/site-packages/youtube_dl/YoutubeDL.py", line 628, in report_error
    self.trouble(error_message, tb)
  File "/home/saransh03sharma/.local/lib/python3.10/site-packages/youtube_dl/YoutubeDL.py", line 598, in trouble
    raise DownloadError(message, exc_info)
youtube_dl.utils.DownloadError: [0;31mERROR:[0m Unsupported URL: https://www.behance.net/videos/https://livestream-videos-prod.s3-us-west-2.amazonaws.com/stream-4e565236-cdf2-4d2f-907d-70ff3cf447ba-s3.mp4.mp4
----------------------------------------------------------
https://www.behance.net/videos/https://livestream-videos-prod.s3-us-west-2.amazonaws.com/stream-205eda67-0a6d-473e-9cc6-74012ac530e4-s3.mp4.mp4
Traceback (most recent call last):
  File "/home/saransh03sharma/.local/lib/python3.10/site-packages/youtube_dl/YoutubeDL.py", line 815, in wrapper
    return func(self, *args, **kwargs)
  File "/home/saransh03sharma/.local/lib/python3.10/site-packages/youtube_dl/YoutubeDL.py", line 836, in __extract_info
    ie_result = ie.extract(url)
  File "/home/saransh03sharma/.local/lib/python3.10/site-packages/youtube_dl/extractor/common.py", line 534, in extract
    ie_result = self._real_extract(url)
  File "/home/saransh03sharma/.local/lib/python3.10/site-packages/youtube_dl/extractor/generic.py", line 3489, in _real_extract
    raise UnsupportedError(url)
youtube_dl.utils.UnsupportedError: Unsupported URL: https://www.behance.net/videos/https://livestream-videos-prod.s3-us-west-2.amazonaws.com/stream-205eda67-0a6d-473e-9cc6-74012ac530e4-s3.mp4.mp4

During handling of the above exception, another exception occurred:

Traceback (most recent call last):
  File "/home/saransh03sharma/Documents/GitHub/VideoIntentDiscovery/scripts/download_videos.py", line 51, in get_slices
    download_video_with_youtube_dl(url, tmp_name)
  File "/home/saransh03sharma/Documents/GitHub/VideoIntentDiscovery/scripts/download_videos.py", line 43, in download_video_with_youtube_dl
    ydl.download([url])
  File "/home/saransh03sharma/.local/lib/python3.10/site-packages/youtube_dl/YoutubeDL.py", line 2068, in download
    res = self.extract_info(
  File "/home/saransh03sharma/.local/lib/python3.10/site-packages/youtube_dl/YoutubeDL.py", line 808, in extract_info
    return self.__extract_info(url, ie, download, extra_info, process)
  File "/home/saransh03sharma/.local/lib/python3.10/site-packages/youtube_dl/YoutubeDL.py", line 824, in wrapper
    self.report_error(compat_str(e), e.format_traceback())
  File "/home/saransh03sharma/.local/lib/python3.10/site-packages/youtube_dl/YoutubeDL.py", line 628, in report_error
    self.trouble(error_message, tb)
  File "/home/saransh03sharma/.local/lib/python3.10/site-packages/youtube_dl/YoutubeDL.py", line 598, in trouble
    raise DownloadError(message, exc_info)
youtube_dl.utils.DownloadError: [0;31mERROR:[0m Unsupported URL: https://www.behance.net/videos/https://livestream-videos-prod.s3-us-west-2.amazonaws.com/stream-205eda67-0a6d-473e-9cc6-74012ac530e4-s3.mp4.mp4
----------------------------------------------------------
https://www.behance.net/videos/https://livestream-videos-prod.s3-us-west-2.amazonaws.com/stream-a63533e0-6413-4f51-9841-6bee342141b1-s3.mp4
Traceback (most recent call last):
  File "/home/saransh03sharma/.local/lib/python3.10/site-packages/youtube_dl/YoutubeDL.py", line 815, in wrapper
    return func(self, *args, **kwargs)
  File "/home/saransh03sharma/.local/lib/python3.10/site-packages/youtube_dl/YoutubeDL.py", line 836, in __extract_info
    ie_result = ie.extract(url)
  File "/home/saransh03sharma/.local/lib/python3.10/site-packages/youtube_dl/extractor/common.py", line 534, in extract
    ie_result = self._real_extract(url)
  File "/home/saransh03sharma/.local/lib/python3.10/site-packages/youtube_dl/extractor/generic.py", line 3489, in _real_extract
    raise UnsupportedError(url)
youtube_dl.utils.UnsupportedError: Unsupported URL: https://www.behance.net/videos/https://livestream-videos-prod.s3-us-west-2.amazonaws.com/stream-a63533e0-6413-4f51-9841-6bee342141b1-s3.mp4

During handling of the above exception, another exception occurred:

Traceback (most recent call last):
  File "/home/saransh03sharma/Documents/GitHub/VideoIntentDiscovery/scripts/download_videos.py", line 51, in get_slices
    download_video_with_youtube_dl(url, tmp_name)
  File "/home/saransh03sharma/Documents/GitHub/VideoIntentDiscovery/scripts/download_videos.py", line 43, in download_video_with_youtube_dl
    ydl.download([url])
  File "/home/saransh03sharma/.local/lib/python3.10/site-packages/youtube_dl/YoutubeDL.py", line 2068, in download
    res = self.extract_info(
  File "/home/saransh03sharma/.local/lib/python3.10/site-packages/youtube_dl/YoutubeDL.py", line 808, in extract_info
    return self.__extract_info(url, ie, download, extra_info, process)
  File "/home/saransh03sharma/.local/lib/python3.10/site-packages/youtube_dl/YoutubeDL.py", line 824, in wrapper
    self.report_error(compat_str(e), e.format_traceback())
  File "/home/saransh03sharma/.local/lib/python3.10/site-packages/youtube_dl/YoutubeDL.py", line 628, in report_error
    self.trouble(error_message, tb)
  File "/home/saransh03sharma/.local/lib/python3.10/site-packages/youtube_dl/YoutubeDL.py", line 598, in trouble
    raise DownloadError(message, exc_info)
youtube_dl.utils.DownloadError: [0;31mERROR:[0m Unsupported URL: https://www.behance.net/videos/https://livestream-videos-prod.s3-us-west-2.amazonaws.com/stream-a63533e0-6413-4f51-9841-6bee342141b1-s3.mp4
----------------------------------------------------------
https://www.behance.net/videos/https://www.behance.net/videos/37aec988-de9b-4bf9-941e-947c4b7406e2/Virtual-Plein-Air-Sketch-Studies-with-Maddy-Bellwoar
Traceback (most recent call last):
  File "/home/saransh03sharma/.local/lib/python3.10/site-packages/youtube_dl/YoutubeDL.py", line 815, in wrapper
    return func(self, *args, **kwargs)
  File "/home/saransh03sharma/.local/lib/python3.10/site-packages/youtube_dl/YoutubeDL.py", line 836, in __extract_info
    ie_result = ie.extract(url)
  File "/home/saransh03sharma/.local/lib/python3.10/site-packages/youtube_dl/extractor/common.py", line 534, in extract
    ie_result = self._real_extract(url)
  File "/home/saransh03sharma/.local/lib/python3.10/site-packages/youtube_dl/extractor/generic.py", line 3489, in _real_extract
    raise UnsupportedError(url)
youtube_dl.utils.UnsupportedError: Unsupported URL: https://www.behance.net/videos/https://www.behance.net/videos/37aec988-de9b-4bf9-941e-947c4b7406e2/Virtual-Plein-Air-Sketch-Studies-with-Maddy-Bellwoar

During handling of the above exception, another exception occurred:

Traceback (most recent call last):
  File "/home/saransh03sharma/Documents/GitHub/VideoIntentDiscovery/scripts/download_videos.py", line 51, in get_slices
    download_video_with_youtube_dl(url, tmp_name)
  File "/home/saransh03sharma/Documents/GitHub/VideoIntentDiscovery/scripts/download_videos.py", line 43, in download_video_with_youtube_dl
    ydl.download([url])
  File "/home/saransh03sharma/.local/lib/python3.10/site-packages/youtube_dl/YoutubeDL.py", line 2068, in download
    res = self.extract_info(
  File "/home/saransh03sharma/.local/lib/python3.10/site-packages/youtube_dl/YoutubeDL.py", line 808, in extract_info
    return self.__extract_info(url, ie, download, extra_info, process)
  File "/home/saransh03sharma/.local/lib/python3.10/site-packages/youtube_dl/YoutubeDL.py", line 824, in wrapper
    self.report_error(compat_str(e), e.format_traceback())
  File "/home/saransh03sharma/.local/lib/python3.10/site-packages/youtube_dl/YoutubeDL.py", line 628, in report_error
    self.trouble(error_message, tb)
  File "/home/saransh03sharma/.local/lib/python3.10/site-packages/youtube_dl/YoutubeDL.py", line 598, in trouble
    raise DownloadError(message, exc_info)
youtube_dl.utils.DownloadError: [0;31mERROR:[0m Unsupported URL: https://www.behance.net/videos/https://www.behance.net/videos/37aec988-de9b-4bf9-941e-947c4b7406e2/Virtual-Plein-Air-Sketch-Studies-with-Maddy-Bellwoar
----------------------------------------------------------
https://www.behance.net/videos/https://www.behance.net/videos/632fffaf-f8ae-4c75-bcaf-91ea4f8ddfb6/Daily-Projects-with-Klarens-Malluta
Traceback (most recent call last):
  File "/home/saransh03sharma/.local/lib/python3.10/site-packages/youtube_dl/YoutubeDL.py", line 815, in wrapper
    return func(self, *args, **kwargs)
  File "/home/saransh03sharma/.local/lib/python3.10/site-packages/youtube_dl/YoutubeDL.py", line 836, in __extract_info
    ie_result = ie.extract(url)
  File "/home/saransh03sharma/.local/lib/python3.10/site-packages/youtube_dl/extractor/common.py", line 534, in extract
    ie_result = self._real_extract(url)
  File "/home/saransh03sharma/.local/lib/python3.10/site-packages/youtube_dl/extractor/generic.py", line 3489, in _real_extract
    raise UnsupportedError(url)
youtube_dl.utils.UnsupportedError: Unsupported URL: https://www.behance.net/videos/https://www.behance.net/videos/632fffaf-f8ae-4c75-bcaf-91ea4f8ddfb6/Daily-Projects-with-Klarens-Malluta

During handling of the above exception, another exception occurred:

Traceback (most recent call last):
  File "/home/saransh03sharma/Documents/GitHub/VideoIntentDiscovery/scripts/download_videos.py", line 51, in get_slices
    download_video_with_youtube_dl(url, tmp_name)
  File "/home/saransh03sharma/Documents/GitHub/VideoIntentDiscovery/scripts/download_videos.py", line 43, in download_video_with_youtube_dl
    ydl.download([url])
  File "/home/saransh03sharma/.local/lib/python3.10/site-packages/youtube_dl/YoutubeDL.py", line 2068, in download
    res = self.extract_info(
  File "/home/saransh03sharma/.local/lib/python3.10/site-packages/youtube_dl/YoutubeDL.py", line 808, in extract_info
    return self.__extract_info(url, ie, download, extra_info, process)
  File "/home/saransh03sharma/.local/lib/python3.10/site-packages/youtube_dl/YoutubeDL.py", line 824, in wrapper
    self.report_error(compat_str(e), e.format_traceback())
  File "/home/saransh03sharma/.local/lib/python3.10/site-packages/youtube_dl/YoutubeDL.py", line 628, in report_error
    self.trouble(error_message, tb)
  File "/home/saransh03sharma/.local/lib/python3.10/site-packages/youtube_dl/YoutubeDL.py", line 598, in trouble
    raise DownloadError(message, exc_info)
youtube_dl.utils.DownloadError: [0;31mERROR:[0m Unsupported URL: https://www.behance.net/videos/https://www.behance.net/videos/632fffaf-f8ae-4c75-bcaf-91ea4f8ddfb6/Daily-Projects-with-Klarens-Malluta
----------------------------------------------------------
https://www.behance.net/videos/https://livestream-videos-prod.s3-us-west-2.amazonaws.com/stream-563baf94-84dd-47b2-84f6-4971634cda32-s3.mp4
Traceback (most recent call last):
  File "/home/saransh03sharma/.local/lib/python3.10/site-packages/youtube_dl/YoutubeDL.py", line 815, in wrapper
    return func(self, *args, **kwargs)
  File "/home/saransh03sharma/.local/lib/python3.10/site-packages/youtube_dl/YoutubeDL.py", line 836, in __extract_info
    ie_result = ie.extract(url)
  File "/home/saransh03sharma/.local/lib/python3.10/site-packages/youtube_dl/extractor/common.py", line 534, in extract
    ie_result = self._real_extract(url)
  File "/home/saransh03sharma/.local/lib/python3.10/site-packages/youtube_dl/extractor/generic.py", line 3489, in _real_extract
    raise UnsupportedError(url)
youtube_dl.utils.UnsupportedError: Unsupported URL: https://www.behance.net/videos/https://livestream-videos-prod.s3-us-west-2.amazonaws.com/stream-563baf94-84dd-47b2-84f6-4971634cda32-s3.mp4

During handling of the above exception, another exception occurred:

Traceback (most recent call last):
  File "/home/saransh03sharma/Documents/GitHub/VideoIntentDiscovery/scripts/download_videos.py", line 51, in get_slices
    download_video_with_youtube_dl(url, tmp_name)
  File "/home/saransh03sharma/Documents/GitHub/VideoIntentDiscovery/scripts/download_videos.py", line 43, in download_video_with_youtube_dl
    ydl.download([url])
  File "/home/saransh03sharma/.local/lib/python3.10/site-packages/youtube_dl/YoutubeDL.py", line 2068, in download
    res = self.extract_info(
  File "/home/saransh03sharma/.local/lib/python3.10/site-packages/youtube_dl/YoutubeDL.py", line 808, in extract_info
    return self.__extract_info(url, ie, download, extra_info, process)
  File "/home/saransh03sharma/.local/lib/python3.10/site-packages/youtube_dl/YoutubeDL.py", line 824, in wrapper
    self.report_error(compat_str(e), e.format_traceback())
  File "/home/saransh03sharma/.local/lib/python3.10/site-packages/youtube_dl/YoutubeDL.py", line 628, in report_error
    self.trouble(error_message, tb)
  File "/home/saransh03sharma/.local/lib/python3.10/site-packages/youtube_dl/YoutubeDL.py", line 598, in trouble
    raise DownloadError(message, exc_info)
youtube_dl.utils.DownloadError: [0;31mERROR:[0m Unsupported URL: https://www.behance.net/videos/https://livestream-videos-prod.s3-us-west-2.amazonaws.com/stream-563baf94-84dd-47b2-84f6-4971634cda32-s3.mp4
----------------------------------------------------------
https://www.behance.net/videos/https://livestream-videos-prod.s3-us-west-2.amazonaws.com/stream-e191c578-475d-4d7c-8693-a214544f5bba-s3.mp4
Traceback (most recent call last):
  File "/home/saransh03sharma/.local/lib/python3.10/site-packages/youtube_dl/YoutubeDL.py", line 815, in wrapper
    return func(self, *args, **kwargs)
  File "/home/saransh03sharma/.local/lib/python3.10/site-packages/youtube_dl/YoutubeDL.py", line 836, in __extract_info
    ie_result = ie.extract(url)
  File "/home/saransh03sharma/.local/lib/python3.10/site-packages/youtube_dl/extractor/common.py", line 534, in extract
    ie_result = self._real_extract(url)
  File "/home/saransh03sharma/.local/lib/python3.10/site-packages/youtube_dl/extractor/generic.py", line 3489, in _real_extract
    raise UnsupportedError(url)
youtube_dl.utils.UnsupportedError: Unsupported URL: https://www.behance.net/videos/https://livestream-videos-prod.s3-us-west-2.amazonaws.com/stream-e191c578-475d-4d7c-8693-a214544f5bba-s3.mp4

During handling of the above exception, another exception occurred:

Traceback (most recent call last):
  File "/home/saransh03sharma/Documents/GitHub/VideoIntentDiscovery/scripts/download_videos.py", line 51, in get_slices
    download_video_with_youtube_dl(url, tmp_name)
  File "/home/saransh03sharma/Documents/GitHub/VideoIntentDiscovery/scripts/download_videos.py", line 43, in download_video_with_youtube_dl
    ydl.download([url])
  File "/home/saransh03sharma/.local/lib/python3.10/site-packages/youtube_dl/YoutubeDL.py", line 2068, in download
    res = self.extract_info(
  File "/home/saransh03sharma/.local/lib/python3.10/site-packages/youtube_dl/YoutubeDL.py", line 808, in extract_info
    return self.__extract_info(url, ie, download, extra_info, process)
  File "/home/saransh03sharma/.local/lib/python3.10/site-packages/youtube_dl/YoutubeDL.py", line 824, in wrapper
    self.report_error(compat_str(e), e.format_traceback())
  File "/home/saransh03sharma/.local/lib/python3.10/site-packages/youtube_dl/YoutubeDL.py", line 628, in report_error
    self.trouble(error_message, tb)
  File "/home/saransh03sharma/.local/lib/python3.10/site-packages/youtube_dl/YoutubeDL.py", line 598, in trouble
    raise DownloadError(message, exc_info)
youtube_dl.utils.DownloadError: [0;31mERROR:[0m Unsupported URL: https://www.behance.net/videos/https://livestream-videos-prod.s3-us-west-2.amazonaws.com/stream-e191c578-475d-4d7c-8693-a214544f5bba-s3.mp4
----------------------------------------------------------
https://www.behance.net/videos/https://livestream-videos-prod.s3-us-west-2.amazonaws.com/stream-205eda67-0a6d-473e-9cc6-74012ac530e4-s3.mp4
Traceback (most recent call last):
  File "/home/saransh03sharma/.local/lib/python3.10/site-packages/youtube_dl/YoutubeDL.py", line 815, in wrapper
    return func(self, *args, **kwargs)
  File "/home/saransh03sharma/.local/lib/python3.10/site-packages/youtube_dl/YoutubeDL.py", line 836, in __extract_info
    ie_result = ie.extract(url)
  File "/home/saransh03sharma/.local/lib/python3.10/site-packages/youtube_dl/extractor/common.py", line 534, in extract
    ie_result = self._real_extract(url)
  File "/home/saransh03sharma/.local/lib/python3.10/site-packages/youtube_dl/extractor/generic.py", line 3489, in _real_extract
    raise UnsupportedError(url)
youtube_dl.utils.UnsupportedError: Unsupported URL: https://www.behance.net/videos/https://livestream-videos-prod.s3-us-west-2.amazonaws.com/stream-205eda67-0a6d-473e-9cc6-74012ac530e4-s3.mp4

During handling of the above exception, another exception occurred:

Traceback (most recent call last):
  File "/home/saransh03sharma/Documents/GitHub/VideoIntentDiscovery/scripts/download_videos.py", line 51, in get_slices
    download_video_with_youtube_dl(url, tmp_name)
  File "/home/saransh03sharma/Documents/GitHub/VideoIntentDiscovery/scripts/download_videos.py", line 43, in download_video_with_youtube_dl
    ydl.download([url])
  File "/home/saransh03sharma/.local/lib/python3.10/site-packages/youtube_dl/YoutubeDL.py", line 2068, in download
    res = self.extract_info(
  File "/home/saransh03sharma/.local/lib/python3.10/site-packages/youtube_dl/YoutubeDL.py", line 808, in extract_info
    return self.__extract_info(url, ie, download, extra_info, process)
  File "/home/saransh03sharma/.local/lib/python3.10/site-packages/youtube_dl/YoutubeDL.py", line 824, in wrapper
    self.report_error(compat_str(e), e.format_traceback())
  File "/home/saransh03sharma/.local/lib/python3.10/site-packages/youtube_dl/YoutubeDL.py", line 628, in report_error
    self.trouble(error_message, tb)
  File "/home/saransh03sharma/.local/lib/python3.10/site-packages/youtube_dl/YoutubeDL.py", line 598, in trouble
    raise DownloadError(message, exc_info)
youtube_dl.utils.DownloadError: [0;31mERROR:[0m Unsupported URL: https://www.behance.net/videos/https://livestream-videos-prod.s3-us-west-2.amazonaws.com/stream-205eda67-0a6d-473e-9cc6-74012ac530e4-s3.mp4
----------------------------------------------------------
https://www.behance.net/videos/https://www.behance.net/videos/c147bd15-2e4a-4205-9bb3-25133826df6a/Shilin-chipping-away-a-painting
Traceback (most recent call last):
  File "/home/saransh03sharma/.local/lib/python3.10/site-packages/youtube_dl/YoutubeDL.py", line 815, in wrapper
    return func(self, *args, **kwargs)
  File "/home/saransh03sharma/.local/lib/python3.10/site-packages/youtube_dl/YoutubeDL.py", line 836, in __extract_info
    ie_result = ie.extract(url)
  File "/home/saransh03sharma/.local/lib/python3.10/site-packages/youtube_dl/extractor/common.py", line 534, in extract
    ie_result = self._real_extract(url)
  File "/home/saransh03sharma/.local/lib/python3.10/site-packages/youtube_dl/extractor/generic.py", line 3489, in _real_extract
    raise UnsupportedError(url)
youtube_dl.utils.UnsupportedError: Unsupported URL: https://www.behance.net/videos/https://www.behance.net/videos/c147bd15-2e4a-4205-9bb3-25133826df6a/Shilin-chipping-away-a-painting

During handling of the above exception, another exception occurred:

Traceback (most recent call last):
  File "/home/saransh03sharma/Documents/GitHub/VideoIntentDiscovery/scripts/download_videos.py", line 51, in get_slices
    download_video_with_youtube_dl(url, tmp_name)
  File "/home/saransh03sharma/Documents/GitHub/VideoIntentDiscovery/scripts/download_videos.py", line 43, in download_video_with_youtube_dl
    ydl.download([url])
  File "/home/saransh03sharma/.local/lib/python3.10/site-packages/youtube_dl/YoutubeDL.py", line 2068, in download
    res = self.extract_info(
  File "/home/saransh03sharma/.local/lib/python3.10/site-packages/youtube_dl/YoutubeDL.py", line 808, in extract_info
    return self.__extract_info(url, ie, download, extra_info, process)
  File "/home/saransh03sharma/.local/lib/python3.10/site-packages/youtube_dl/YoutubeDL.py", line 824, in wrapper
    self.report_error(compat_str(e), e.format_traceback())
  File "/home/saransh03sharma/.local/lib/python3.10/site-packages/youtube_dl/YoutubeDL.py", line 628, in report_error
    self.trouble(error_message, tb)
  File "/home/saransh03sharma/.local/lib/python3.10/site-packages/youtube_dl/YoutubeDL.py", line 598, in trouble
    raise DownloadError(message, exc_info)
youtube_dl.utils.DownloadError: [0;31mERROR:[0m Unsupported URL: https://www.behance.net/videos/https://www.behance.net/videos/c147bd15-2e4a-4205-9bb3-25133826df6a/Shilin-chipping-away-a-painting
----------------------------------------------------------
https://www.behance.net/videos/https://www.behance.net/videos/b7f29dd7-7d9f-435f-8b3c-bcdb8e0202b9/Creature-Character-Concepts-with-2SL
Traceback (most recent call last):
  File "/home/saransh03sharma/.local/lib/python3.10/site-packages/youtube_dl/YoutubeDL.py", line 815, in wrapper
    return func(self, *args, **kwargs)
  File "/home/saransh03sharma/.local/lib/python3.10/site-packages/youtube_dl/YoutubeDL.py", line 836, in __extract_info
    ie_result = ie.extract(url)
  File "/home/saransh03sharma/.local/lib/python3.10/site-packages/youtube_dl/extractor/common.py", line 534, in extract
    ie_result = self._real_extract(url)
  File "/home/saransh03sharma/.local/lib/python3.10/site-packages/youtube_dl/extractor/generic.py", line 3489, in _real_extract
    raise UnsupportedError(url)
youtube_dl.utils.UnsupportedError: Unsupported URL: https://www.behance.net/videos/https://www.behance.net/videos/b7f29dd7-7d9f-435f-8b3c-bcdb8e0202b9/Creature-Character-Concepts-with-2SL

During handling of the above exception, another exception occurred:

Traceback (most recent call last):
  File "/home/saransh03sharma/Documents/GitHub/VideoIntentDiscovery/scripts/download_videos.py", line 51, in get_slices
    download_video_with_youtube_dl(url, tmp_name)
  File "/home/saransh03sharma/Documents/GitHub/VideoIntentDiscovery/scripts/download_videos.py", line 43, in download_video_with_youtube_dl
    ydl.download([url])
  File "/home/saransh03sharma/.local/lib/python3.10/site-packages/youtube_dl/YoutubeDL.py", line 2068, in download
    res = self.extract_info(
  File "/home/saransh03sharma/.local/lib/python3.10/site-packages/youtube_dl/YoutubeDL.py", line 808, in extract_info
    return self.__extract_info(url, ie, download, extra_info, process)
  File "/home/saransh03sharma/.local/lib/python3.10/site-packages/youtube_dl/YoutubeDL.py", line 824, in wrapper
    self.report_error(compat_str(e), e.format_traceback())
  File "/home/saransh03sharma/.local/lib/python3.10/site-packages/youtube_dl/YoutubeDL.py", line 628, in report_error
    self.trouble(error_message, tb)
  File "/home/saransh03sharma/.local/lib/python3.10/site-packages/youtube_dl/YoutubeDL.py", line 598, in trouble
    raise DownloadError(message, exc_info)
youtube_dl.utils.DownloadError: [0;31mERROR:[0m Unsupported URL: https://www.behance.net/videos/https://www.behance.net/videos/b7f29dd7-7d9f-435f-8b3c-bcdb8e0202b9/Creature-Character-Concepts-with-2SL
----------------------------------------------------------
https://www.behance.net/videos/https://livestream-videos-prod.s3-us-west-2.amazonaws.com/stream-4e565236-cdf2-4d2f-907d-70ff3cf447ba-s3.mp4
Traceback (most recent call last):
  File "/home/saransh03sharma/.local/lib/python3.10/site-packages/youtube_dl/YoutubeDL.py", line 815, in wrapper
    return func(self, *args, **kwargs)
  File "/home/saransh03sharma/.local/lib/python3.10/site-packages/youtube_dl/YoutubeDL.py", line 836, in __extract_info
    ie_result = ie.extract(url)
  File "/home/saransh03sharma/.local/lib/python3.10/site-packages/youtube_dl/extractor/common.py", line 534, in extract
    ie_result = self._real_extract(url)
  File "/home/saransh03sharma/.local/lib/python3.10/site-packages/youtube_dl/extractor/generic.py", line 3489, in _real_extract
    raise UnsupportedError(url)
youtube_dl.utils.UnsupportedError: Unsupported URL: https://www.behance.net/videos/https://livestream-videos-prod.s3-us-west-2.amazonaws.com/stream-4e565236-cdf2-4d2f-907d-70ff3cf447ba-s3.mp4

During handling of the above exception, another exception occurred:

Traceback (most recent call last):
  File "/home/saransh03sharma/Documents/GitHub/VideoIntentDiscovery/scripts/download_videos.py", line 51, in get_slices
    download_video_with_youtube_dl(url, tmp_name)
  File "/home/saransh03sharma/Documents/GitHub/VideoIntentDiscovery/scripts/download_videos.py", line 43, in download_video_with_youtube_dl
    ydl.download([url])
  File "/home/saransh03sharma/.local/lib/python3.10/site-packages/youtube_dl/YoutubeDL.py", line 2068, in download
    res = self.extract_info(
  File "/home/saransh03sharma/.local/lib/python3.10/site-packages/youtube_dl/YoutubeDL.py", line 808, in extract_info
    return self.__extract_info(url, ie, download, extra_info, process)
  File "/home/saransh03sharma/.local/lib/python3.10/site-packages/youtube_dl/YoutubeDL.py", line 824, in wrapper
    self.report_error(compat_str(e), e.format_traceback())
  File "/home/saransh03sharma/.local/lib/python3.10/site-packages/youtube_dl/YoutubeDL.py", line 628, in report_error
    self.trouble(error_message, tb)
  File "/home/saransh03sharma/.local/lib/python3.10/site-packages/youtube_dl/YoutubeDL.py", line 598, in trouble
    raise DownloadError(message, exc_info)
youtube_dl.utils.DownloadError: [0;31mERROR:[0m Unsupported URL: https://www.behance.net/videos/https://livestream-videos-prod.s3-us-west-2.amazonaws.com/stream-4e565236-cdf2-4d2f-907d-70ff3cf447ba-s3.mp4
----------------------------------------------------------
https://www.behance.net/videos/https://www.behance.net/videos/f83ea5f3-dcc8-47c0-ab75-50b489538348/Autumn-Themed-Digital-Painting-Studies-with-Maddy-Bellwoar
Traceback (most recent call last):
  File "/home/saransh03sharma/.local/lib/python3.10/site-packages/youtube_dl/YoutubeDL.py", line 815, in wrapper
    return func(self, *args, **kwargs)
  File "/home/saransh03sharma/.local/lib/python3.10/site-packages/youtube_dl/YoutubeDL.py", line 836, in __extract_info
    ie_result = ie.extract(url)
  File "/home/saransh03sharma/.local/lib/python3.10/site-packages/youtube_dl/extractor/common.py", line 534, in extract
    ie_result = self._real_extract(url)
  File "/home/saransh03sharma/.local/lib/python3.10/site-packages/youtube_dl/extractor/generic.py", line 3489, in _real_extract
    raise UnsupportedError(url)
youtube_dl.utils.UnsupportedError: Unsupported URL: https://www.behance.net/videos/https://www.behance.net/videos/f83ea5f3-dcc8-47c0-ab75-50b489538348/Autumn-Themed-Digital-Painting-Studies-with-Maddy-Bellwoar

During handling of the above exception, another exception occurred:

Traceback (most recent call last):
  File "/home/saransh03sharma/Documents/GitHub/VideoIntentDiscovery/scripts/download_videos.py", line 51, in get_slices
    download_video_with_youtube_dl(url, tmp_name)
  File "/home/saransh03sharma/Documents/GitHub/VideoIntentDiscovery/scripts/download_videos.py", line 43, in download_video_with_youtube_dl
    ydl.download([url])
  File "/home/saransh03sharma/.local/lib/python3.10/site-packages/youtube_dl/YoutubeDL.py", line 2068, in download
    res = self.extract_info(
  File "/home/saransh03sharma/.local/lib/python3.10/site-packages/youtube_dl/YoutubeDL.py", line 808, in extract_info
    return self.__extract_info(url, ie, download, extra_info, process)
  File "/home/saransh03sharma/.local/lib/python3.10/site-packages/youtube_dl/YoutubeDL.py", line 824, in wrapper
    self.report_error(compat_str(e), e.format_traceback())
  File "/home/saransh03sharma/.local/lib/python3.10/site-packages/youtube_dl/YoutubeDL.py", line 628, in report_error
    self.trouble(error_message, tb)
  File "/home/saransh03sharma/.local/lib/python3.10/site-packages/youtube_dl/YoutubeDL.py", line 598, in trouble
    raise DownloadError(message, exc_info)
youtube_dl.utils.DownloadError: [0;31mERROR:[0m Unsupported URL: https://www.behance.net/videos/https://www.behance.net/videos/f83ea5f3-dcc8-47c0-ab75-50b489538348/Autumn-Themed-Digital-Painting-Studies-with-Maddy-Bellwoar
----------------------------------------------------------
https://www.behance.net/videos/37aec988-de9b-4bf9-941e-947c4b7406e2/Virtual-Plein-Air-Sketch-Studies-with-Maddy-Bellwoar
Traceback (most recent call last):
  File "/home/saransh03sharma/.local/lib/python3.10/site-packages/youtube_dl/YoutubeDL.py", line 815, in wrapper
    return func(self, *args, **kwargs)
  File "/home/saransh03sharma/.local/lib/python3.10/site-packages/youtube_dl/YoutubeDL.py", line 836, in __extract_info
    ie_result = ie.extract(url)
  File "/home/saransh03sharma/.local/lib/python3.10/site-packages/youtube_dl/extractor/common.py", line 534, in extract
    ie_result = self._real_extract(url)
  File "/home/saransh03sharma/.local/lib/python3.10/site-packages/youtube_dl/extractor/generic.py", line 3489, in _real_extract
    raise UnsupportedError(url)
youtube_dl.utils.UnsupportedError: Unsupported URL: https://www.behance.net/videos/37aec988-de9b-4bf9-941e-947c4b7406e2/Virtual-Plein-Air-Sketch-Studies-with-Maddy-Bellwoar

During handling of the above exception, another exception occurred:

Traceback (most recent call last):
  File "/home/saransh03sharma/Documents/GitHub/VideoIntentDiscovery/scripts/download_videos.py", line 51, in get_slices
    download_video_with_youtube_dl(url, tmp_name)
  File "/home/saransh03sharma/Documents/GitHub/VideoIntentDiscovery/scripts/download_videos.py", line 43, in download_video_with_youtube_dl
    ydl.download([url])
  File "/home/saransh03sharma/.local/lib/python3.10/site-packages/youtube_dl/YoutubeDL.py", line 2068, in download
    res = self.extract_info(
  File "/home/saransh03sharma/.local/lib/python3.10/site-packages/youtube_dl/YoutubeDL.py", line 808, in extract_info
    return self.__extract_info(url, ie, download, extra_info, process)
  File "/home/saransh03sharma/.local/lib/python3.10/site-packages/youtube_dl/YoutubeDL.py", line 824, in wrapper
    self.report_error(compat_str(e), e.format_traceback())
  File "/home/saransh03sharma/.local/lib/python3.10/site-packages/youtube_dl/YoutubeDL.py", line 628, in report_error
    self.trouble(error_message, tb)
  File "/home/saransh03sharma/.local/lib/python3.10/site-packages/youtube_dl/YoutubeDL.py", line 598, in trouble
    raise DownloadError(message, exc_info)
youtube_dl.utils.DownloadError: [0;31mERROR:[0m Unsupported URL: https://www.behance.net/videos/37aec988-de9b-4bf9-941e-947c4b7406e2/Virtual-Plein-Air-Sketch-Studies-with-Maddy-Bellwoar
----------------------------------------------------------
https://www.behance.net/videos/c147bd15-2e4a-4205-9bb3-25133826df6a/Shilin-chipping-away-a-painting
Traceback (most recent call last):
  File "/home/saransh03sharma/.local/lib/python3.10/site-packages/youtube_dl/YoutubeDL.py", line 815, in wrapper
    return func(self, *args, **kwargs)
  File "/home/saransh03sharma/.local/lib/python3.10/site-packages/youtube_dl/YoutubeDL.py", line 836, in __extract_info
    ie_result = ie.extract(url)
  File "/home/saransh03sharma/.local/lib/python3.10/site-packages/youtube_dl/extractor/common.py", line 534, in extract
    ie_result = self._real_extract(url)
  File "/home/saransh03sharma/.local/lib/python3.10/site-packages/youtube_dl/extractor/generic.py", line 3489, in _real_extract
    raise UnsupportedError(url)
youtube_dl.utils.UnsupportedError: Unsupported URL: https://www.behance.net/videos/c147bd15-2e4a-4205-9bb3-25133826df6a/Shilin-chipping-away-a-painting

During handling of the above exception, another exception occurred:

Traceback (most recent call last):
  File "/home/saransh03sharma/Documents/GitHub/VideoIntentDiscovery/scripts/download_videos.py", line 51, in get_slices
    download_video_with_youtube_dl(url, tmp_name)
  File "/home/saransh03sharma/Documents/GitHub/VideoIntentDiscovery/scripts/download_videos.py", line 43, in download_video_with_youtube_dl
    ydl.download([url])
  File "/home/saransh03sharma/.local/lib/python3.10/site-packages/youtube_dl/YoutubeDL.py", line 2068, in download
    res = self.extract_info(
  File "/home/saransh03sharma/.local/lib/python3.10/site-packages/youtube_dl/YoutubeDL.py", line 808, in extract_info
    return self.__extract_info(url, ie, download, extra_info, process)
  File "/home/saransh03sharma/.local/lib/python3.10/site-packages/youtube_dl/YoutubeDL.py", line 824, in wrapper
    self.report_error(compat_str(e), e.format_traceback())
  File "/home/saransh03sharma/.local/lib/python3.10/site-packages/youtube_dl/YoutubeDL.py", line 628, in report_error
    self.trouble(error_message, tb)
  File "/home/saransh03sharma/.local/lib/python3.10/site-packages/youtube_dl/YoutubeDL.py", line 598, in trouble
    raise DownloadError(message, exc_info)
youtube_dl.utils.DownloadError: [0;31mERROR:[0m Unsupported URL: https://www.behance.net/videos/c147bd15-2e4a-4205-9bb3-25133826df6a/Shilin-chipping-away-a-painting
----------------------------------------------------------
https://www.behance.net/videos/632fffaf-f8ae-4c75-bcaf-91ea4f8ddfb6/Daily-Projects-with-Klarens-Malluta
Traceback (most recent call last):
  File "/home/saransh03sharma/.local/lib/python3.10/site-packages/youtube_dl/YoutubeDL.py", line 815, in wrapper
    return func(self, *args, **kwargs)
  File "/home/saransh03sharma/.local/lib/python3.10/site-packages/youtube_dl/YoutubeDL.py", line 836, in __extract_info
    ie_result = ie.extract(url)
  File "/home/saransh03sharma/.local/lib/python3.10/site-packages/youtube_dl/extractor/common.py", line 534, in extract
    ie_result = self._real_extract(url)
  File "/home/saransh03sharma/.local/lib/python3.10/site-packages/youtube_dl/extractor/generic.py", line 3489, in _real_extract
    raise UnsupportedError(url)
youtube_dl.utils.UnsupportedError: Unsupported URL: https://www.behance.net/videos/632fffaf-f8ae-4c75-bcaf-91ea4f8ddfb6/Daily-Projects-with-Klarens-Malluta

During handling of the above exception, another exception occurred:

Traceback (most recent call last):
  File "/home/saransh03sharma/Documents/GitHub/VideoIntentDiscovery/scripts/download_videos.py", line 51, in get_slices
    download_video_with_youtube_dl(url, tmp_name)
  File "/home/saransh03sharma/Documents/GitHub/VideoIntentDiscovery/scripts/download_videos.py", line 43, in download_video_with_youtube_dl
    ydl.download([url])
  File "/home/saransh03sharma/.local/lib/python3.10/site-packages/youtube_dl/YoutubeDL.py", line 2068, in download
    res = self.extract_info(
  File "/home/saransh03sharma/.local/lib/python3.10/site-packages/youtube_dl/YoutubeDL.py", line 808, in extract_info
    return self.__extract_info(url, ie, download, extra_info, process)
  File "/home/saransh03sharma/.local/lib/python3.10/site-packages/youtube_dl/YoutubeDL.py", line 824, in wrapper
    self.report_error(compat_str(e), e.format_traceback())
  File "/home/saransh03sharma/.local/lib/python3.10/site-packages/youtube_dl/YoutubeDL.py", line 628, in report_error
    self.trouble(error_message, tb)
  File "/home/saransh03sharma/.local/lib/python3.10/site-packages/youtube_dl/YoutubeDL.py", line 598, in trouble
    raise DownloadError(message, exc_info)
youtube_dl.utils.DownloadError: [0;31mERROR:[0m Unsupported URL: https://www.behance.net/videos/632fffaf-f8ae-4c75-bcaf-91ea4f8ddfb6/Daily-Projects-with-Klarens-Malluta
----------------------------------------------------------
https://www.behance.net/videos/b7f29dd7-7d9f-435f-8b3c-bcdb8e0202b9/Creature-Character-Concepts-with-2SL
Traceback (most recent call last):
  File "/home/saransh03sharma/.local/lib/python3.10/site-packages/youtube_dl/YoutubeDL.py", line 815, in wrapper
    return func(self, *args, **kwargs)
  File "/home/saransh03sharma/.local/lib/python3.10/site-packages/youtube_dl/YoutubeDL.py", line 836, in __extract_info
    ie_result = ie.extract(url)
  File "/home/saransh03sharma/.local/lib/python3.10/site-packages/youtube_dl/extractor/common.py", line 534, in extract
    ie_result = self._real_extract(url)
  File "/home/saransh03sharma/.local/lib/python3.10/site-packages/youtube_dl/extractor/generic.py", line 3489, in _real_extract
    raise UnsupportedError(url)
youtube_dl.utils.UnsupportedError: Unsupported URL: https://www.behance.net/videos/b7f29dd7-7d9f-435f-8b3c-bcdb8e0202b9/Creature-Character-Concepts-with-2SL

During handling of the above exception, another exception occurred:

Traceback (most recent call last):
  File "/home/saransh03sharma/Documents/GitHub/VideoIntentDiscovery/scripts/download_videos.py", line 51, in get_slices
    download_video_with_youtube_dl(url, tmp_name)
  File "/home/saransh03sharma/Documents/GitHub/VideoIntentDiscovery/scripts/download_videos.py", line 43, in download_video_with_youtube_dl
    ydl.download([url])
  File "/home/saransh03sharma/.local/lib/python3.10/site-packages/youtube_dl/YoutubeDL.py", line 2068, in download
    res = self.extract_info(
  File "/home/saransh03sharma/.local/lib/python3.10/site-packages/youtube_dl/YoutubeDL.py", line 808, in extract_info
    return self.__extract_info(url, ie, download, extra_info, process)
  File "/home/saransh03sharma/.local/lib/python3.10/site-packages/youtube_dl/YoutubeDL.py", line 824, in wrapper
    self.report_error(compat_str(e), e.format_traceback())
  File "/home/saransh03sharma/.local/lib/python3.10/site-packages/youtube_dl/YoutubeDL.py", line 628, in report_error
    self.trouble(error_message, tb)
  File "/home/saransh03sharma/.local/lib/python3.10/site-packages/youtube_dl/YoutubeDL.py", line 598, in trouble
    raise DownloadError(message, exc_info)
youtube_dl.utils.DownloadError: [0;31mERROR:[0m Unsupported URL: https://www.behance.net/videos/b7f29dd7-7d9f-435f-8b3c-bcdb8e0202b9/Creature-Character-Concepts-with-2SL
----------------------------------------------------------
https://www.behance.net/videos/f83ea5f3-dcc8-47c0-ab75-50b489538348/Autumn-Themed-Digital-Painting-Studies-with-Maddy-Bellwoar
Traceback (most recent call last):
  File "/home/saransh03sharma/.local/lib/python3.10/site-packages/youtube_dl/YoutubeDL.py", line 815, in wrapper
    return func(self, *args, **kwargs)
  File "/home/saransh03sharma/.local/lib/python3.10/site-packages/youtube_dl/YoutubeDL.py", line 836, in __extract_info
    ie_result = ie.extract(url)
  File "/home/saransh03sharma/.local/lib/python3.10/site-packages/youtube_dl/extractor/common.py", line 534, in extract
    ie_result = self._real_extract(url)
  File "/home/saransh03sharma/.local/lib/python3.10/site-packages/youtube_dl/extractor/generic.py", line 3489, in _real_extract
    raise UnsupportedError(url)
youtube_dl.utils.UnsupportedError: Unsupported URL: https://www.behance.net/videos/f83ea5f3-dcc8-47c0-ab75-50b489538348/Autumn-Themed-Digital-Painting-Studies-with-Maddy-Bellwoar

During handling of the above exception, another exception occurred:

Traceback (most recent call last):
  File "/home/saransh03sharma/Documents/GitHub/VideoIntentDiscovery/scripts/download_videos.py", line 51, in get_slices
    download_video_with_youtube_dl(url, tmp_name)
  File "/home/saransh03sharma/Documents/GitHub/VideoIntentDiscovery/scripts/download_videos.py", line 43, in download_video_with_youtube_dl
    ydl.download([url])
  File "/home/saransh03sharma/.local/lib/python3.10/site-packages/youtube_dl/YoutubeDL.py", line 2068, in download
    res = self.extract_info(
  File "/home/saransh03sharma/.local/lib/python3.10/site-packages/youtube_dl/YoutubeDL.py", line 808, in extract_info
    return self.__extract_info(url, ie, download, extra_info, process)
  File "/home/saransh03sharma/.local/lib/python3.10/site-packages/youtube_dl/YoutubeDL.py", line 824, in wrapper
    self.report_error(compat_str(e), e.format_traceback())
  File "/home/saransh03sharma/.local/lib/python3.10/site-packages/youtube_dl/YoutubeDL.py", line 628, in report_error
    self.trouble(error_message, tb)
  File "/home/saransh03sharma/.local/lib/python3.10/site-packages/youtube_dl/YoutubeDL.py", line 598, in trouble
    raise DownloadError(message, exc_info)
youtube_dl.utils.DownloadError: [0;31mERROR:[0m Unsupported URL: https://www.behance.net/videos/f83ea5f3-dcc8-47c0-ab75-50b489538348/Autumn-Themed-Digital-Painting-Studies-with-Maddy-Bellwoar
----------------------------------------------------------
